Workbook

Sheet Summary
A1: 📊 DASHBOARD - UAT EXECUTION SUMMARY
A3: TỔNG QUAN
A4: Tổng số TC | B4: 781 | C4: Số test case đã viết
A5: Đã thực thi | B5: =COUNTIF('Test Cases'!Q4:Q784,"Đạt")+COUNTIF('Test Cases'!Q4:Q784,"Không đạt")+COUNTIF('Test Cases'!Q4:Q784,"Bị chặn") | C5: TC đã có Status
A6: Đạt | B6: =COUNTIF('Test Cases'!Q4:Q784,"Đạt") | C6: TC pass
A7: Không đạt | B7: =COUNTIF('Test Cases'!Q4:Q784,"Không đạt") | C7: TC fail - có bug
A8: Bị chặn | B8: =COUNTIF('Test Cases'!Q4:Q784,"Bị chặn") | C8: Không chạy được
A9: Chưa chạy | B9: =COUNTBLANK('Test Cases'!Q4:Q784)+COUNTIF('Test Cases'!Q4:Q784,"Chưa chạy") | C9: Còn lại
A11: Tỷ lệ đạt | B11: =IFERROR(COUNTIF('Test Cases'!Q4:Q784,"Đạt")/(COUNTIF('Test Cases'!Q4:Q784,"Đạt")+COUNTIF('Test Cases'!Q4:Q784,"Không đạt")),0) | C11: Đạt / (Đạt + Không đạt)
A12: Tỷ lệ hoàn thành | B12: =IFERROR((COUNTIF('Test Cases'!Q4:Q784,"Đạt")+COUNTIF('Test Cases'!Q4:Q784,"Không đạt")+COUNTIF('Test Cases'!Q4:Q784,"Bị chặn"))/781,0) | C12: Đã chạy / Tổng
A14: ĐỘ PHỦ THEO LOẠI
A15: Loại | B15: Số TC | C15: Tỷ lệ | D15: Pass | E15: Fail | F15: Pass rate
A16: GREEN | B16: =COUNTIF('Test Cases'!B4:B784,"GREEN") | C16: =IFERROR(B16/781,0) | D16: =COUNTIFS('Test Cases'!B4:B784,"GREEN",'Test Cases'!Q4:Q784,"Đạt") | E16: =COUNTIFS('Test Cases'!B4:B784,"GREEN",'Test Cases'!Q4:Q784,"Không đạt") | F16: =IFERROR(D16/(D16+E16),0)
A17: RED | B17: =COUNTIF('Test Cases'!B4:B784,"RED") | C17: =IFERROR(B17/781,0) | D17: =COUNTIFS('Test Cases'!B4:B784,"RED",'Test Cases'!Q4:Q784,"Đạt") | E17: =COUNTIFS('Test Cases'!B4:B784,"RED",'Test Cases'!Q4:Q784,"Không đạt") | F17: =IFERROR(D17/(D17+E17),0)
A18: EDGE | B18: =COUNTIF('Test Cases'!B4:B784,"EDGE") | C18: =IFERROR(B18/781,0) | D18: =COUNTIFS('Test Cases'!B4:B784,"EDGE",'Test Cases'!Q4:Q784,"Đạt") | E18: =COUNTIFS('Test Cases'!B4:B784,"EDGE",'Test Cases'!Q4:Q784,"Không đạt") | F18: =IFERROR(D18/(D18+E18),0)
A19: BOUNDARY | B19: =COUNTIF('Test Cases'!B4:B784,"BOUNDARY") | C19: =IFERROR(B19/781,0) | D19: =COUNTIFS('Test Cases'!B4:B784,"BOUNDARY",'Test Cases'!Q4:Q784,"Đạt") | E19: =COUNTIFS('Test Cases'!B4:B784,"BOUNDARY",'Test Cases'!Q4:Q784,"Không đạt") | F19: =IFERROR(D19/(D19+E19),0)
A20: EP | B20: =COUNTIF('Test Cases'!B4:B784,"EP") | C20: =IFERROR(B20/781,0) | D20: =COUNTIFS('Test Cases'!B4:B784,"EP",'Test Cases'!Q4:Q784,"Đạt") | E20: =COUNTIFS('Test Cases'!B4:B784,"EP",'Test Cases'!Q4:Q784,"Không đạt") | F20: =IFERROR(D20/(D20+E20),0)
A21: STATE | B21: =COUNTIF('Test Cases'!B4:B784,"STATE") | C21: =IFERROR(B21/781,0) | D21: =COUNTIFS('Test Cases'!B4:B784,"STATE",'Test Cases'!Q4:Q784,"Đạt") | E21: =COUNTIFS('Test Cases'!B4:B784,"STATE",'Test Cases'!Q4:Q784,"Không đạt") | F21: =IFERROR(D21/(D21+E21),0)
A22: DECISION | B22: =COUNTIF('Test Cases'!B4:B784,"DECISION") | C22: =IFERROR(B22/781,0) | D22: =COUNTIFS('Test Cases'!B4:B784,"DECISION",'Test Cases'!Q4:Q784,"Đạt") | E22: =COUNTIFS('Test Cases'!B4:B784,"DECISION",'Test Cases'!Q4:Q784,"Không đạt") | F22: =IFERROR(D22/(D22+E22),0)
A23: SECURITY | B23: =COUNTIF('Test Cases'!B4:B784,"SECURITY") | C23: =IFERROR(B23/781,0) | D23: =COUNTIFS('Test Cases'!B4:B784,"SECURITY",'Test Cases'!Q4:Q784,"Đạt") | E23: =COUNTIFS('Test Cases'!B4:B784,"SECURITY",'Test Cases'!Q4:Q784,"Không đạt") | F23: =IFERROR(D23/(D23+E23),0)
A24: DATA | B24: =COUNTIF('Test Cases'!B4:B784,"DATA") | C24: =IFERROR(B24/781,0) | D24: =COUNTIFS('Test Cases'!B4:B784,"DATA",'Test Cases'!Q4:Q784,"Đạt") | E24: =COUNTIFS('Test Cases'!B4:B784,"DATA",'Test Cases'!Q4:Q784,"Không đạt") | F24: =IFERROR(D24/(D24+E24),0)
A25: PERFORMANCE | B25: =COUNTIF('Test Cases'!B4:B784,"PERFORMANCE") | C25: =IFERROR(B25/781,0) | D25: =COUNTIFS('Test Cases'!B4:B784,"PERFORMANCE",'Test Cases'!Q4:Q784,"Đạt") | E25: =COUNTIFS('Test Cases'!B4:B784,"PERFORMANCE",'Test Cases'!Q4:Q784,"Không đạt") | F25: =IFERROR(D25/(D25+E25),0)
A26: A11Y | B26: =COUNTIF('Test Cases'!B4:B784,"A11Y") | C26: =IFERROR(B26/781,0) | D26: =COUNTIFS('Test Cases'!B4:B784,"A11Y",'Test Cases'!Q4:Q784,"Đạt") | E26: =COUNTIFS('Test Cases'!B4:B784,"A11Y",'Test Cases'!Q4:Q784,"Không đạt") | F26: =IFERROR(D26/(D26+E26),0)
A27: COMPAT | B27: =COUNTIF('Test Cases'!B4:B784,"COMPAT") | C27: =IFERROR(B27/781,0) | D27: =COUNTIFS('Test Cases'!B4:B784,"COMPAT",'Test Cases'!Q4:Q784,"Đạt") | E27: =COUNTIFS('Test Cases'!B4:B784,"COMPAT",'Test Cases'!Q4:Q784,"Không đạt") | F27: =IFERROR(D27/(D27+E27),0)
A28: INTEGRATION | B28: =COUNTIF('Test Cases'!B4:B784,"INTEGRATION") | C28: =IFERROR(B28/781,0) | D28: =COUNTIFS('Test Cases'!B4:B784,"INTEGRATION",'Test Cases'!Q4:Q784,"Đạt") | E28: =COUNTIFS('Test Cases'!B4:B784,"INTEGRATION",'Test Cases'!Q4:Q784,"Không đạt") | F28: =IFERROR(D28/(D28+E28),0)
A29: REGRESSION | B29: =COUNTIF('Test Cases'!B4:B784,"REGRESSION") | C29: =IFERROR(B29/781,0) | D29: =COUNTIFS('Test Cases'!B4:B784,"REGRESSION",'Test Cases'!Q4:Q784,"Đạt") | E29: =COUNTIFS('Test Cases'!B4:B784,"REGRESSION",'Test Cases'!Q4:Q784,"Không đạt") | F29: =IFERROR(D29/(D29+E29),0)
A30: RECOVERY | B30: =COUNTIF('Test Cases'!B4:B784,"RECOVERY") | C30: =IFERROR(B30/781,0) | D30: =COUNTIFS('Test Cases'!B4:B784,"RECOVERY",'Test Cases'!Q4:Q784,"Đạt") | E30: =COUNTIFS('Test Cases'!B4:B784,"RECOVERY",'Test Cases'!Q4:Q784,"Không đạt") | F30: =IFERROR(D30/(D30+E30),0)
A31: AUDIT | B31: =COUNTIF('Test Cases'!B4:B784,"AUDIT") | C31: =IFERROR(B31/781,0) | D31: =COUNTIFS('Test Cases'!B4:B784,"AUDIT",'Test Cases'!Q4:Q784,"Đạt") | E31: =COUNTIFS('Test Cases'!B4:B784,"AUDIT",'Test Cases'!Q4:Q784,"Không đạt") | F31: =IFERROR(D31/(D31+E31),0)
A32: USABILITY | B32: =COUNTIF('Test Cases'!B4:B784,"USABILITY") | C32: =IFERROR(B32/781,0) | D32: =COUNTIFS('Test Cases'!B4:B784,"USABILITY",'Test Cases'!Q4:Q784,"Đạt") | E32: =COUNTIFS('Test Cases'!B4:B784,"USABILITY",'Test Cases'!Q4:Q784,"Không đạt") | F32: =IFERROR(D32/(D32+E32),0)
A34: THEO ĐỘ ƯU TIÊN
A35: Priority | B35: Số TC | C35: Tỷ lệ | D35: Pass | E35: Fail | F35: Pass rate
A36: P0 | B36: =COUNTIF('Test Cases'!C4:C784,"P0") | C36: =IFERROR(B36/781,0) | D36: =COUNTIFS('Test Cases'!C4:C784,"P0",'Test Cases'!Q4:Q784,"Đạt") | E36: =COUNTIFS('Test Cases'!C4:C784,"P0",'Test Cases'!Q4:Q784,"Không đạt") | F36: =IFERROR(D36/(D36+E36),0)
A37: P1 | B37: =COUNTIF('Test Cases'!C4:C784,"P1") | C37: =IFERROR(B37/781,0) | D37: =COUNTIFS('Test Cases'!C4:C784,"P1",'Test Cases'!Q4:Q784,"Đạt") | E37: =COUNTIFS('Test Cases'!C4:C784,"P1",'Test Cases'!Q4:Q784,"Không đạt") | F37: =IFERROR(D37/(D37+E37),0)
A38: P2 | B38: =COUNTIF('Test Cases'!C4:C784,"P2") | C38: =IFERROR(B38/781,0) | D38: =COUNTIFS('Test Cases'!C4:C784,"P2",'Test Cases'!Q4:Q784,"Đạt") | E38: =COUNTIFS('Test Cases'!C4:C784,"P2",'Test Cases'!Q4:Q784,"Không đạt") | F38: =IFERROR(D38/(D38+E38),0)
A39: P3 | B39: =COUNTIF('Test Cases'!C4:C784,"P3") | C39: =IFERROR(B39/781,0) | D39: =COUNTIFS('Test Cases'!C4:C784,"P3",'Test Cases'!Q4:Q784,"Đạt") | E39: =COUNTIFS('Test Cases'!C4:C784,"P3",'Test Cases'!Q4:Q784,"Không đạt") | F39: =IFERROR(D39/(D39+E39),0)
A41: EXIT CRITERIA
A42: Tiêu chí | B42: Yêu cầu | C42: Thực tế | D42: Trạng thái
A43: P0 pass rate | B43: ≥ 100% | C43: =IFERROR(COUNTIFS('Test Cases'!C4:C784,"P0",'Test Cases'!Q4:Q784,"Đạt")/COUNTIF('Test Cases'!C4:C784,"P0"),0) | D43: =IF(C43>=1,"✅ Đạt","❌ Chưa đạt")
A44: P1 pass rate | B44: ≥ 95% | C44: =IFERROR(COUNTIFS('Test Cases'!C4:C784,"P1",'Test Cases'!Q4:Q784,"Đạt")/COUNTIF('Test Cases'!C4:C784,"P1"),0) | D44: =IF(C44>=0.95,"✅ Đạt","❌ Chưa đạt")
A45: P2 pass rate | B45: ≥ 85% | C45: =IFERROR(COUNTIFS('Test Cases'!C4:C784,"P2",'Test Cases'!Q4:Q784,"Đạt")/MAX(COUNTIF('Test Cases'!C4:C784,"P2"),1),1) | D45: =IF(C45>=0.85,"✅ Đạt","❌ Chưa đạt")
...

Sheet Test Cases
A1: BỘ TEST CASE UAT: Quản lý vụ việc / vụ án (Case Management) — toàn bộ chức năng
A2: Tổng số TC: 781 | Ngày tạo: 23/05/2026 | Generated by uat-test-writer skill
A3: TC-ID | B3: Loại | C3: Độ ưu tiên | D3: Module | E3: Tiêu đề | F3: Yêu cầu | G3: Kỹ thuật test | H3: Mức độ rủi ro | I3: Điều kiện tiên quyết | J3: Các bước kiểm thử | K3: Dữ liệu kiểm thử | L3: Kết quả mong đợi - UI | M3: Kết quả mong đợi - API | N3: Kết quả mong đợi - Side effects | O3: Severity nếu fail | P3: Kết quả thực tế | Q3: Trạng thái | R3: Bug ID | S3: Lần chạy cuối | T3: Lịch sử chạy | U3: Cờ regression | V3: Ghi chú
A4: TC-001 | B4: GREEN | C4: P0 | D4: Create | E4: Tạo Case DIRECT_DISCOVERY thành công với input đầy đủ | F4: REQ-CASE-CREATE-001 | G4: Use case testing | H4: Cao | I4: 1. Login dieuTra1@pc02.local (role INVESTIGATOR) 2. User thuộc Team-Q1 3. JWT valid | J4: 1. Navigate /cases/new 2. Nhập name = 'Vụ trộm cắp xe máy tại Q1 ngày 12/05/2026' 3. Chọn caseProvenance = DIRECT_DISCOVERY 4. Nhập crime = 'Trộm cắp tài sản — Đ.173 BLHS' 5. Chọn capDoToiPham = NGHIEM_TRONG 6. Nhập subjectsCount = 2 7. Nhập ngayKhoiTo = '2026-05-12' 8. Click 'Lưu' | K4: name='Vụ trộm cắp xe máy tại Q1 ngày 12/05/2026', caseProvenance='DIRECT_DISCOVERY', crime='Trộm cắp tài sản — Đ.173 BLHS', capDoToiPham='NGHIEM_TRONG', subjectsCount=2, ngayKhoiTo='2026-05-12' | L4: 1. Toast 'Tạo vụ án thành công' 2. Redirect /cases/<id> 3. Trang detail hiển thị đủ field 4. Badge status = 'Tiếp nhận' | M4: 1. POST /api/v1/cases trả 201 2. Body: success=true, data.id, data.status='TIEP_NHAN', data.caseProvenance='DIRECT_DISCOVERY', data.createdById=<userId> 3. data.assignedTeamId auto-set từ dataScope | N4: 1. Row trong table cases, deletedAt=NULL 2. Audit log CASE_CREATED có ipAddress, userAgent 3. assignedTeamId auto từ ward officer scope (v0.33) | O4: Critical | P4: Thời gian: 125ms | Q4: Không đạt | R4: BUG-078 | S4: 23/05/2026 19:06 | T4: R1:Không đạt
A5: TC-002 | B5: GREEN | C5: P0 | D5: Create | E5: Tạo Case FROM_PETITION link Petition đang status TIEP_NHAN + expectedPetitionUpdatedAt khớp | F5: REQ-CASE-CREATE-002 | G5: Use case testing | H5: Cao | I5: 1. Login INVESTIGATOR 2. Có Petition PET-001 status=TIEP_NHAN, updatedAt='2026-05-20T10:00:00.000Z', linkedCaseId=NULL | J5: 1. Vào /petitions/PET-001 2. Click 'Khởi tố vụ án' 3. Form mở với caseProvenance=FROM_PETITION, linkedPetitionId=PET-001 pre-filled 4. Nhập name = 'Vụ án từ đơn thư PET-001' 5. Submit | K5: linkedPetitionId='PET-001', expectedPetitionUpdatedAt='2026-05-20T10:00:00.000Z', caseProvenance='FROM_PETITION' | L5: 1. Toast 'Tạo vụ án thành công' 2. Redirect /cases/<newId> 3. Tab 'Nguồn tin' hiển thị link sang Petition PET-001 | M5: 1. POST /cases trả 201 2. data.linkedPetitionId='PET-001' 3. Atomic update Petition.status=DA_CHUYEN_VU_AN | N5: 1. cases row có linkedPetitionId 2. petitions PET-001: linkedCaseId=newId, status=DA_CHUYEN_VU_AN 3. Audit CASE_CREATED metadata.linkedPetitionId='PET-001' | O5: Critical | P5: Thời gian: 123ms | Q5: Không đạt | R5: BUG-079 | S5: 23/05/2026 19:06 | T5: R1:Không đạt
A6: TC-003 | B6: GREEN | C6: P0 | D6: Create | E6: Tạo Case FROM_INCIDENT link Incident chưa khởi tố + expectedIncidentUpdatedAt khớp | F6: REQ-CASE-CREATE-003 | G6: Use case testing | H6: Cao | I6: 1. Login INVESTIGATOR 2. Có Incident INC-001 deletedAt=NULL, linkedCaseId=NULL, updatedAt='2026-05-20T11:00:00.000Z' | J6: 1. Vào /incidents/INC-001 2. Click 'Khởi tố vụ án' 3. Form pre-fill caseProvenance=FROM_INCIDENT, linkedIncidentId=INC-001 4. Nhập name='Vụ án khởi tố từ INC-001' 5. Submit | K6: linkedIncidentId='INC-001', expectedIncidentUpdatedAt='2026-05-20T11:00:00.000Z', caseProvenance='FROM_INCIDENT' | L6: 1. Toast success 2. Redirect /cases/<newId> 3. Detail page có badge 'Khởi tố từ vụ việc INC-001' | M6: 1. POST /cases trả 201 2. data.linkedIncidentId='INC-001' 3. Incident INC-001 update linkedCaseId=newId | N6: 1. cases.linkedIncidentId, incidents.linkedCaseId updated atomic 2. Audit CASE_CREATED metadata.linkedIncidentId | O6: Critical | P6: Thời gian: 116ms | Q6: Không đạt | R6: BUG-080 | S6: 23/05/2026 19:06 | T6: R1:Không đạt
A7: TC-004 | B7: GREEN | C7: P0 | D7: Create | E7: Tạo Case TRANSFERRED với sourceDocumentNote | F7: REQ-CASE-CREATE-004 | G7: Use case testing | H7: Cao | I7: 1. Login INVESTIGATOR | J7: 1. Mở form tạo vụ án 2. Chọn caseProvenance=TRANSFERRED 3. Nhập sourceDocumentNote='Công văn chuyển từ Cơ quan ANĐT Thành phố số 1234/CV ngày 10/05/2026' 4. Nhập name + submit | K7: caseProvenance='TRANSFERRED', sourceDocumentNote='Công văn chuyển từ Cơ quan ANĐT Thành phố số 1234/CV ngày 10/05/2026', name='Vụ chuyển CQĐT khác' | L7: Toast 'Tạo vụ án thành công', detail hiện sourceDocumentNote | M7: POST /cases 201, data.caseProvenance='TRANSFERRED', data.sourceDocumentNote set | N7: cases row có sourceDocumentNote saved | O7: High | P7: Thời gian: 118ms | Q7: Không đạt | R7: BUG-081 | S7: 23/05/2026 19:06 | T7: R1:Không đạt
A8: TC-005 | B8: GREEN | C8: P0 | D8: Create | E8: Tạo Case OTHER_LEGAL_SOURCE | F8: REQ-CASE-CREATE-005 | G8: Use case testing | H8: Cao | I8: 1. User đã login 2. Token JWT hợp lệ | J8: 1. Form tạo 2. Chọn provenance=OTHER_LEGAL_SOURCE 3. Nhập name='Vụ phát hiện qua tin báo nặc danh', sourceDocumentNote='Tin báo Hotline 113' 4. Submit | K8: caseProvenance='OTHER_LEGAL_SOURCE', name='Vụ phát hiện qua tin báo nặc danh', sourceDocumentNote='Tin báo Hotline 113' | L8: Toast success | M8: 201 with caseProvenance=OTHER_LEGAL_SOURCE | N8: Row saved | O8: High | P8: Thời gian: 123ms | Q8: Không đạt | R8: BUG-082 | S8: 23/05/2026 19:06 | T8: R1:Không đạt
A9: TC-006 | B9: GREEN | C9: P0 | D9: Create | E9: Tạo Case với capDoToiPham=DAC_BIET_NGHIEM_TRONG để KPI-4 tính | F9: REQ-CASE-CREATE-006 | G9: Use case testing | H9: Cao | I9: 1. User đã login 2. Token JWT hợp lệ | J9: 1. Tạo Case mới 2. Chọn capDoToiPham=DAC_BIET_NGHIEM_TRONG 3. crime='Giết người — Đ.123 BLHS' 4. Submit | K9: capDoToiPham='DAC_BIET_NGHIEM_TRONG', crime='Giết người — Đ.123 BLHS' | L9: Detail hiện badge mức độ 'Đặc biệt nghiêm trọng' màu đỏ | M9: data.capDoToiPham='DAC_BIET_NGHIEM_TRONG' | N9: KPI-4 dashboard cập nhật count án ĐBNT +1 | O9: High | P9: Thời gian: 172ms | Q9: Không đạt | R9: BUG-083 | S9: 23/05/2026 19:06 | T9: R1:Không đạt
A10: TC-007 | B10: GREEN | C10: P0 | D10: Create | E10: Auto-deadline tính theo SystemSetting THOI_HAN_GIAI_QUYET | F10: REQ-CASE-CREATE-007 | G10: Use case testing | H10: Cao | I10: SystemSetting THOI_HAN_GIAI_QUYET = 120 (ngày) | J10: 1. Tạo Case mới ngày 2026-05-23 2. KHÔNG nhập deadline 3. Submit | K10: name='Test auto deadline', caseProvenance='DIRECT_DISCOVERY' | L10: Detail hiển thị deadline = 2026-09-20 (120 ngày sau) | M10: data.deadline = createdAt + 120 days (UTC) | N10: Deadline auto-set từ SystemSetting, không phải từ user input | O10: High | P10: Thời gian: 132ms | Q10: Không đạt | R10: BUG-084 | S10: 23/05/2026 19:06 | T10: R1:Không đạt
A11: TC-008 | B11: GREEN | C11: P0 | D11: Create | E11: Tạo Case manual deadline override auto-deadline | F11: REQ-CASE-CREATE-008 | G11: Use case testing | H11: Cao | I11: 1. User đã login 2. Token JWT hợp lệ | J11: 1. Form tạo 2. Nhập deadline='2026-08-15' (60 ngày sau) 3. Submit | K11: deadline='2026-08-15' | L11: Detail show deadline=15/08/2026 | M11: data.deadline=2026-08-15T00:00:00.000Z | N11: cases.deadline = user input (không bị auto-calc override) | O11: High | P11: Thời gian: 195ms | Q11: Không đạt | R11: BUG-085 | S11: 23/05/2026 19:06 | T11: R1:Không đạt
A12: TC-009 | B12: GREEN | C12: P0 | D12: Create | E12: Tạo Case với metadata custom (người báo tin) | F12: REQ-CASE-CREATE-009 | G12: Use case testing | H12: Cao | I12: 1. User đã login 2. Token JWT hợp lệ | J12: 1. Tạo Case 2. Nhập metadata.nguoiBaoTin='Nguyễn Văn A', metadata.diaChi='12 Lê Lợi Q1' 3. Submit | K12: metadata={nguoiBaoTin:'Nguyễn Văn A', diaChi:'12 Lê Lợi Q1', soDienThoai:'0901234567'} | L12: Detail tab 'Thông tin báo tin' show nguoiBaoTin, diaChi | M12: data.metadata.nguoiBaoTin='Nguyễn Văn A' | N12: JSONB metadata saved | O12: High | P12: Thời gian: 171ms | Q12: Không đạt | R12: BUG-086 | S12: 23/05/2026 19:06 | T12: R1:Không đạt
A13: TC-010 | B13: GREEN | C13: P0 | D13: Create | E13: Ward officer auto-set assignedTeamId theo wardTeamId (silent override) | F13: REQ-CASE-CREATE-010 | G13: Use case testing | H13: Cao | I13: Login wardOfficer1@pc02.local thuộc Team-WARD-01 | J13: 1. Form tạo 2. CỐ NHẬP assignedTeamId='Team-DIFFERENT-99' (team khác) 3. Submit | K13: dto.assignedTeamId='Team-DIFFERENT-99' | L13: Toast success (KHÔNG báo lỗi) | M13: POST 201, data.assignedTeamId='Team-WARD-01' (auto override) | N13: Server silent override theo dataScope.wardTeamId — UX safer per D-eng-fix M3 | O13: High | P13: Thời gian: 131ms | Q13: Không đạt | R13: BUG-087 | S13: 23/05/2026 19:06 | T13: R1:Không đạt
A14: TC-011 | B14: GREEN | C14: P1 | D14: Create | E14: Tạo Case bỏ trống các field optional | F14: REQ-CASE-CREATE-011 | G14: Use case testing | H14: TB | I14: 1. User đã login 2. Token JWT hợp lệ | J14: 1. Form tạo 2. CHỈ nhập name + caseProvenance 3. Submit | K14: name='Vụ tối thiểu', caseProvenance='DIRECT_DISCOVERY' | L14: Toast success, detail hiện các field optional là '-' | M14: 201, crime=NULL, investigatorId=NULL, capDoToiPham=NULL, subjectsCount=0 (default) | N14: DB row với null optional fields | O14: Medium | P14: Đạt như expected. Thời gian: 826ms | Q14: Đạt | S14: 23/05/2026 19:06 | T14: R1:Đạt
A15: TC-012 | B15: GREEN | C15: P1 | D15: Create | E15: Tạo Case với investigatorId là user khác đang active | F15: REQ-CASE-CREATE-012 | G15: Use case testing | H15: TB | I15: Có user dieuTra2@pc02.local đang active | J15: 1. Tạo Case 2. Chọn investigator='Nguyễn ĐTV2' từ FK dropdown 3. Submit | K15: investigatorId='<dieuTra2.id>' | L15: Detail show investigator name = 'Nguyễn ĐTV2' | M15: data.investigatorId=<dieuTra2.id> | N15: cases.investigatorId set | O15: Medium | P15: Đạt như expected. Thời gian: 62ms | Q15: Đạt | S15: 23/05/2026 19:06 | T15: R1:Đạt
A16: TC-013 | B16: GREEN | C16: P1 | D16: Create | E16: Tạo Case với ngayKhoiTo lùi vài ngày trước hôm nay (đã khởi tố trước khi vào hệ thống) | F16: REQ-CASE-CREATE-013 | G16: Use case testing | H16: TB | I16: 1. User đã login 2. Token JWT hợp lệ | J16: 1. Tạo Case 2. ngayKhoiTo='2026-05-15' (8 ngày trước) 3. Submit | K16: ngayKhoiTo='2026-05-15' | L16: Detail show ngày khởi tố 15/05/2026 | M16: data.ngayKhoiTo='2026-05-15T00:00:00.000Z' | N16: Saved without 'future date' validation | O16: Medium | P16: Đạt như expected. Thời gian: 66ms | Q16: Đạt | S16: 23/05/2026 19:06 | T16: R1:Đạt
A17: TC-014 | B17: GREEN | C17: P1 | D17: Create | E17: Dispatcher tạo Case có thể chọn assignedTeamId bất kỳ | F17: REQ-CASE-CREATE-014 | G17: Use case testing | H17: TB | I17: Login dispatcher@pc02.local (canDispatch=true) | J17: 1. Tạo Case 2. assignedTeamId='Team-OTHER-WARD-05' (team khác phường) 3. Submit | K17: assignedTeamId='Team-OTHER-WARD-05' | L17: Toast success, detail show team đã chọn | M17: data.assignedTeamId='Team-OTHER-WARD-05' (KHÔNG bị override) | N17: Dispatcher bypass ward auto-override | O17: High | P17: Thời gian: 706ms | Q17: Không đạt | R17: BUG-088 | S17: 23/05/2026 19:06 | T17: R1:Không đạt
A18: TC-015 | B18: GREEN | C18: P1 | D18: Create | E18: Tạo Case ADMIN với toàn bộ field bao gồm field hiếm dùng | F18: REQ-CASE-CREATE-015 | G18: Use case testing | H18: TB | I18: Login admin@pc02.local | J18: Tạo Case với laCongNgheCao=false, soLanGiaHan=0, daRaSoat=false (default), submit | K18: laCongNgheCao=false, soLanGiaHan=0 | L18: Detail hiển thị 'Không phải án CNC' | M18: 201, các field default applied | N18: Default values saved | O18: Medium | P18: Đạt như expected. Thời gian: 736ms | Q18: Đạt | S18: 23/05/2026 19:06 | T18: R1:Đạt
A19: TC-016 | B19: GREEN | C19: P1 | D19: Create | E19: POST trả response message tiếng Việt 'Tạo vụ án thành công' | F19: REQ-CASE-CREATE-016 | G19: Use case testing | H19: TB | I19: 1. User đã login 2. Token JWT hợp lệ | J19: 1. POST /cases với DTO hợp lệ | K19: dto đầy đủ | L19: - | M19: Response: {success:true, data:{...}, message:'Tạo vụ án thành công'} | N19: - | O19: Low | P19: Đạt như expected. Thời gian: 59ms | Q19: Đạt | S19: 23/05/2026 19:06 | T19: R1:Đạt | V19: Verify response shape khớp với contract message field
A20: TC-017 | B20: RED | C20: P0 | D20: Create-name | E20: Thiếu trường name (required) trả 400 | F20: REQ-CASE-CREATE-NAME-017 | G20: Use case testing | H20: Cao | I20: 1. User đã login 2. Token JWT hợp lệ | J20: 1. POST /cases với dto thiếu key name | K20: {caseProvenance:'DIRECT_DISCOVERY'} | L20: Form: hiện inline error 'Tên vụ án bắt buộc' | M20: 400 BadRequest, error message includes 'name' | N20: Không tạo row | O20: Critical | P20: Đạt như expected. Thời gian: 32ms | Q20: Đạt | S20: 23/05/2026 19:06 | T20: R1:Đạt
A21: TC-018 | B21: RED | C21: P0 | D21: Create-name | E21: name là chuỗi rỗng '' trả 400 'Tên vụ án bắt buộc' | F21: REQ-CASE-CREATE-NAME-018 | G21: Use case testing | H21: Cao | I21: 1. User đã login 2. Token JWT hợp lệ | J21: POST /cases với name='' | K21: name='' | L21: Error 'Tên vụ án bắt buộc' | M21: 400 message ='Tên vụ án bắt buộc' (sau Transform trim) | N21: - | O21: Critical | P21: Đạt như expected. Thời gian: 40ms | Q21: Đạt | S21: 23/05/2026 19:06 | T21: R1:Đạt
A22: TC-019 | B22: RED | C22: P0 | D22: Create-name | E22: name chỉ whitespace ' ' bị trim thành '' → 400 | F22: REQ-CASE-CREATE-NAME-019 | G22: Use case testing | H22: Cao | I22: 1. User đã login 2. Token JWT hợp lệ | J22: POST với name=' ' | K22: name=' ' (5 spaces) | L22: Error 'Tên vụ án bắt buộc' | M22: 400 (Transform trim chạy trước IsNotEmpty) | N22: - | O22: Critical | P22: Đạt như expected. Thời gian: 38ms | Q22: Đạt | S22: 23/05/2026 19:06 | T22: R1:Đạt | V22: UAT 2026-05-23 BUG-001 đã fix
A23: TC-020 | B23: RED | C23: P0 | D23: Create-name | E23: name là null → 400 | F23: REQ-CASE-CREATE-NAME-020 | G23: Use case testing | H23: Cao | I23: 1. User đã login 2. Token JWT hợp lệ | J23: POST với name=null | K23: name=null | L23: Error | M23: 400 | N23: - | O23: Critical | P23: Đạt như expected. Thời gian: 38ms | Q23: Đạt | S23: 23/05/2026 19:06 | T23: R1:Đạt
A24: TC-021 | B24: RED | C24: P0 | D24: Create-name | E24: name là số 12345 không phải string → 400 IsString | F24: REQ-CASE-CREATE-NAME-021 | G24: Use case testing | H24: Cao | I24: 1. User đã login 2. Token JWT hợp lệ | J24: POST name=12345 (number) | K24: name=12345 | L24: - | M24: 400 IsString failed | N24: - | O24: High | P24: Đạt như expected. Thời gian: 46ms | Q24: Đạt | S24: 23/05/2026 19:06 | T24: R1:Đạt
A25: TC-022 | B25: RED | C25: P0 | D25: Create-name | E25: name vượt 500 ký tự (501 chars) → 400 MaxLength | F25: REQ-CASE-CREATE-NAME-022 | G25: Use case testing | H25: Cao | I25: 1. User đã login 2. Token JWT hợp lệ | J25: POST với name='A' lặp 501 lần | K25: name='A'.repeat(501) | L25: Error 'Tên không quá 500 ký tự' | M25: 400 MaxLength(500) | N25: - | O25: High | P25: Đạt như expected. Thời gian: 36ms | Q25: Đạt | S25: 23/05/2026 19:06 | T25: R1:Đạt
A26: TC-023 | B26: RED | C26: P1 | D26: Create-name | E26: name là object JSON → 400 IsString | F26: REQ-CASE-CREATE-NAME-023 | G26: Use case testing | H26: TB | I26: 1. User đã login 2. Token JWT hợp lệ | J26: POST name={text:'abc'} | K26: name={text:'abc'} | L26: - | M26: 400 | N26: - | O26: Medium | P26: Đạt như expected. Thời gian: 45ms | Q26: Đạt | S26: 23/05/2026 19:06 | T26: R1:Đạt
A27: TC-024 | B27: RED | C27: P1 | D27: Create-name | E27: name là array → 400 IsString | F27: REQ-CASE-CREATE-NAME-024 | G27: Use case testing | H27: TB | I27: 1. User đã login 2. Token JWT hợp lệ | J27: POST name=['abc'] | K27: name=['abc'] | L27: - | M27: 400 | N27: - | O27: Medium | P27: Đạt như expected. Thời gian: 46ms | Q27: Đạt | S27: 23/05/2026 19:06 | T27: R1:Đạt
A28: TC-025 | B28: RED | C28: P0 | D28: Create-prov | E28: Thiếu caseProvenance → 400 | F28: REQ-CASE-CREATE-PROV-025 | G28: Use case testing | H28: Cao | I28: 1. User đã login 2. Token JWT hợp lệ | J28: POST không có caseProvenance | K28: {name:'X'} | L28: Inline error 'caseProvenance bắt buộc' | M28: 400 IsEnum message includes 'BLTTHS Đ.143' | N28: - | O28: Critical | P28: Đạt như expected. Thời gian: 61ms | Q28: Đạt | S28: 23/05/2026 19:06 | T28: R1:Đạt
A29: TC-026 | B29: RED | C29: P0 | D29: Create-prov | E29: caseProvenance không phải enum value → 400 | F29: REQ-CASE-CREATE-PROV-026 | G29: Use case testing | H29: Cao | I29: 1. User đã login 2. Token JWT hợp lệ | J29: POST caseProvenance='INVALID_VALUE' | K29: caseProvenance='INVALID_VALUE' | L29: - | M29: 400 IsEnum violation | N29: - | O29: Critical | P29: Đạt như expected. Thời gian: 46ms | Q29: Đạt | S29: 23/05/2026 19:06 | T29: R1:Đạt
A30: TC-027 | B30: RED | C30: P0 | D30: Create-prov | E30: caseProvenance là tiếng Việt (legacy payload) → 400 | F30: REQ-CASE-CREATE-PROV-027 | G30: Use case testing | H30: Cao | I30: 1. User đã login 2. Token JWT hợp lệ | J30: POST caseProvenance='Phát hiện trực tiếp' | K30: caseProvenance='Phát hiện trực tiếp' | L30: - | M30: 400 — v0.37.2.4 BLTTHS Đ.143 — phải dùng enum value tiếng Anh | N30: - | O30: Critical | P30: Đạt như expected. Thời gian: 56ms | Q30: Đạt | S30: 23/05/2026 19:06 | T30: R1:Đạt | V30: Root cause v0.37.2.4 P0 hot-fix
A31: TC-028 | B31: RED | C31: P0 | D31: Create-prov | E31: FROM_PETITION nhưng thiếu linkedPetitionId → 400 | F31: REQ-CASE-CREATE-PROV-028 | G31: Use case testing | H31: Cao | I31: 1. User đã login 2. Token JWT hợp lệ | J31: POST caseProvenance=FROM_PETITION, không có linkedPetitionId | K31: caseProvenance='FROM_PETITION' | L31: Error 'linkedPetitionId required when caseProvenance is FROM_PETITION' | M31: 400 ValidateIf failed | N31: - | O31: Critical | P31: Đạt như expected. Thời gian: 61ms | Q31: Đạt | S31: 23/05/2026 19:06 | T31: R1:Đạt
A32: TC-029 | B32: RED | C32: P0 | D32: Create-prov | E32: FROM_INCIDENT thiếu linkedIncidentId → 400 | F32: REQ-CASE-CREATE-PROV-029 | G32: Use case testing | H32: Cao | I32: 1. User đã login 2. Token JWT hợp lệ | J32: POST caseProvenance=FROM_INCIDENT, không linkedIncidentId | K32: caseProvenance='FROM_INCIDENT' | L32: Error | M32: 400 | N32: - | O32: Critical | P32: Đạt như expected. Thời gian: 44ms | Q32: Đạt | S32: 23/05/2026 19:06 | T32: R1:Đạt
A33: TC-030 | B33: RED | C33: P0 | D33: Create-prov | E33: FROM_PETITION thiếu expectedPetitionUpdatedAt → 400 IsISO8601 | F33: REQ-CASE-CREATE-PROV-030 | G33: Use case testing | H33: Cao | I33: 1. User đã login 2. Token JWT hợp lệ | J33: POST có linkedPetitionId nhưng không expectedPetitionUpdatedAt | K33: caseProvenance=FROM_PETITION, linkedPetitionId='PET-001' | L33: - | M33: 400 | N33: - | O33: Critical | P33: Đạt như expected. Thời gian: 46ms | Q33: Đạt | S33: 23/05/2026 19:06 | T33: R1:Đạt
A34: TC-031 | B34: RED | C34: P0 | D34: Create-prov | E34: FROM_PETITION với expectedPetitionUpdatedAt cũ hơn current → 409 Conflict | F34: REQ-CASE-CREATE-PROV-031 | G34: Use case testing | H34: Cao | I34: Petition PET-001 updatedAt='2026-05-22T15:00:00.000Z' (đã được update bởi user khác) | J34: POST với expectedPetitionUpdatedAt='2026-05-20T10:00:00.000Z' | K34: expectedPetitionUpdatedAt='2026-05-20T10:00:00.000Z' | L34: Toast 'Đơn thư đã được chỉnh sửa hoặc link bởi người dùng khác' | M34: 409 ConflictException | N34: Case KHÔNG tạo, Petition KHÔNG update | O34: High | P34: Thời gian: 99ms | Q34: Không đạt | R34: BUG-057 | S34: 23/05/2026 19:06 | T34: R1:Không đạt
A35: TC-032 | B35: RED | C35: P0 | D35: Create-prov | E35: FROM_PETITION với linkedPetitionId KHÔNG tồn tại → 404 | F35: REQ-CASE-CREATE-PROV-032 | G35: Use case testing | H35: Cao | I35: 1. User đã login 2. Token JWT hợp lệ | J35: POST linkedPetitionId='PET-NOT-EXIST-999' | K35: linkedPetitionId='PET-NOT-EXIST-999', expectedPetitionUpdatedAt='2026-05-20T10:00:00.000Z' | L35: Toast 'Đơn thư không tồn tại hoặc không nằm trong phạm vi của bạn' | M35: 404 NotFoundException — no enumeration leak | N35: - | O35: High | P35: Thời gian: 133ms | Q35: Không đạt | R35: BUG-058 | S35: 23/05/2026 19:06 | T35: R1:Không đạt | V35: IDOR-safe: not-found vs out-of-scope cùng response
A36: TC-033 | B36: RED | C36: P0 | D36: Create-prov | E36: FROM_PETITION với Petition của user KHÁC scope → 404 (không lộ tồn tại) | F36: REQ-CASE-CREATE-PROV-033 | G36: Use case testing | H36: Cao | I36: Login wardOfficer-Q1, Petition PET-A99 thuộc Team-Q3 | J36: POST FROM_PETITION linkedPetitionId='PET-A99' | K36: linkedPetitionId='PET-A99' | L36: Toast 'Đơn thư không tồn tại hoặc không nằm trong phạm vi của bạn' | M36: 404 (không 403) | N36: IDOR-safe enumeration prevention | O36: Critical | P36: Thời gian: 113ms | Q36: Không đạt | R36: BUG-059 | S36: 23/05/2026 19:06 | T36: R1:Không đạt
A37: TC-034 | B37: RED | C37: P0 | D37: Create-prov | E37: FROM_PETITION với Petition đã có linkedCaseId (đã khởi tố trước) → 404 | F37: REQ-CASE-CREATE-PROV-034 | G37: Use case testing | H37: Cao | I37: PET-002 đã có linkedCaseId='CASE-OLD' | J37: POST FROM_PETITION với linkedPetitionId='PET-002' | K37: linkedPetitionId='PET-002' | L37: Toast 'Đơn thư đã được khởi tố rồi' | M37: 404 (filter linkedCaseId:null trong findFirst) | N37: Không double-create | O37: Critical | P37: Thời gian: 130ms | Q37: Không đạt | R37: BUG-060 | S37: 23/05/2026 19:06 | T37: R1:Không đạt
A38: TC-035 | B38: RED | C38: P0 | D38: Create-prov | E38: FROM_PETITION với deletedAt != null → 404 | F38: REQ-CASE-CREATE-PROV-035 | G38: Use case testing | H38: Cao | I38: PET-003 đã soft-deleted | J38: POST FROM_PETITION linkedPetitionId='PET-003' | K38: linkedPetitionId='PET-003' | L38: - | M38: 404 | N38: - | O38: High | P38: Thời gian: 118ms | Q38: Không đạt | R38: BUG-061 | S38: 23/05/2026 19:06 | T38: R1:Không đạt
A39: TC-036 | B39: RED | C39: P1 | D39: Create-prov | E39: expectedPetitionUpdatedAt sai format (không ISO 8601) → 400 | F39: REQ-CASE-CREATE-PROV-036 | G39: Use case testing | H39: TB | I39: 1. User đã login 2. Token JWT hợp lệ | J39: POST expectedPetitionUpdatedAt='20/05/2026' | K39: expectedPetitionUpdatedAt='20/05/2026' | L39: - | M39: 400 IsISO8601 failed | N39: - | O39: Medium | P39: Thời gian: 126ms | Q39: Không đạt | R39: BUG-062 | S39: 23/05/2026 19:06 | T39: R1:Không đạt
A40: TC-037 | B40: RED | C40: P0 | D40: Create-inv | E40: investigatorId không tồn tại trong users table → 400 | F40: REQ-CASE-CREATE-INV-037 | G40: Use case testing | H40: Cao | I40: 1. User đã login 2. Token JWT hợp lệ | J40: POST investigatorId='NON_EXIST_USER_XXX' | K40: investigatorId='NON_EXIST_USER_XXX' | L40: Toast 'Điều tra viên không tồn tại' | M40: 400 BadRequestException msg=Điều tra viên không tồn tại | N40: - | O40: High | P40: Đạt như expected. Thời gian: 51ms | Q40: Đạt | S40: 23/05/2026 19:06 | T40: R1:Đạt
...

Sheet Test Data
A1: 1. TÀI KHOẢN KIỂM THỬ
A2: ID | B2: Email | C2: Mật khẩu | D2: Vai trò | E2: Trạng thái | F2: Mục đích | G2: Ghi chú
A3: U001 | B3: admin@pc02.local | C3: Admin@2026! | D3: ADMIN | E3: Active | F3: Test ADMIN-only restore + listDeleted + bypass scope | G3: Quyền cao nhất
A4: U002 | B4: dispatcher@pc02.local | C4: Disp@2026! | D4: DISPATCHER | E4: Active | F4: Test PATCH /assign + canDispatch bypass | G4: canDispatch=true
A5: U003 | B5: dieuTra1@pc02.local | C5: DTV@2026! | D5: INVESTIGATOR | E5: Active | F5: Owner + same-team test, creator delete | G5: Thuộc Team-Q1
A6: U004 | B6: dieuTra2@pc02.local | C6: DTV@2026! | D6: INVESTIGATOR | E6: Active | F6: Same-team với U003 (Team-Q1)
A7: U005 | B7: dieuTra3-Q3@pc02.local | C7: DTV@2026! | D7: INVESTIGATOR | E7: Active | F7: Different team (Team-Q3) — test scope reject
A8: U006 | B8: wardOfficer1@pc02.local | C8: WO@2026! | D8: WARD_OFFICER | E8: Active | F8: Test isWardOfficer auto-set assignedTeamId override | G8: Thuộc Team-WARD-01
A9: U007 | B9: viewer@pc02.local | C9: View@2026! | D9: VIEWER | E9: Active | F9: Test 403 cho write/delete/restore | G9: Chỉ read
A10: U008 | B10: locked@pc02.local | C10: - | D10: INVESTIGATOR | E10: Locked | F10: Test JWT của user locked
A13: 2. BOUNDARY VALUES (BVA)
A14: Field | B14: Giá trị | C14: Loại | D14: Kỳ vọng | E14: Ghi chú
A15: name | B15: A | C15: min | D15: PASS | E15: 1 ký tự min
A16: name | B16: X×500 | C16: max | D16: PASS | E16: 500 ký tự max
A17: name | B17: X×501 | C17: max+1 | D17: FAIL | E17: vượt MaxLength(500)
A18: name | C18: empty | D18: FAIL | E18: IsNotEmpty
A19: name | C19: whitespace | D19: FAIL | E19: Transform trim → ''
A20: crime | B20: X×255 | C20: max | D20: PASS
A21: crime | B21: X×256 | C21: max+1 | D21: FAIL
A22: unit | B22: X×255 | C22: max | D22: PASS
A23: unit | B23: X×256 | C23: max+1 | D23: FAIL
A24: subjectsCount | B24: 0 | C24: min | D24: PASS
A25: subjectsCount | B25: -1 | C25: min-1 | D25: FAIL | E25: @Min(0)
A26: delete-reason | B26: X×10 | C26: min | D26: PASS | E26: MinLength(10)
A27: delete-reason | B27: X×9 | C27: min-1 | D27: FAIL
A28: delete-reason | B28: X×500 | C28: max | D28: PASS
A29: delete-reason | B29: X×501 | C29: max+1 | D29: FAIL
A30: sourceDocumentNote | B30: X×1000 | C30: max | D30: PASS
A31: sourceDocumentNote | B31: X×1001 | C31: max+1 | D31: FAIL
A32: limit | B32: 1 | C32: min | D32: PASS
A33: limit | B33: 100 | C33: max | D33: PASS
A34: limit | B34: 101 | C34: max+1 | D34: FAIL | E34: @Max(100)
A35: limit | B35: 0 | C35: min-1 | D35: FAIL | E35: @Min(1)
A36: offset | B36: 0 | C36: min | D36: PASS
A37: offset | B37: -1 | C37: min-1 | D37: FAIL
A40: 3. SECURITY PAYLOADS (OWASP)
A41: Field/Endpoint | B41: Payload | C41: Loại tấn công | D41: Kỳ vọng | E41: OWASP Reference
A42: search | B42: ' OR 1=1-- | C42: SQL Injection | D42: 200 data=[] (Prisma parameterized) | E42: A03:2021
A43: sortBy | B43: name; DROP TABLE cases-- | C43: SQL Injection via orderBy | D43: 200 fallback createdAt (whitelist) | E43: A03:2021
A44: name | B44: <script>alert(1)</script> | C44: XSS reflected | D44: 201 lưu raw, React escape ở render | E44: A03:2021
...

Sheet Bug Tracker
A1: 🐛 BUG TRACKER
A2: Workflow: Open → Fixing → Fixed → Verified → Closed. Mỗi lần TC fail tự động tạo bug record.
A3: Bug ID | B3: TC ID liên kết | C3: Mô tả bug | D3: Severity | E3: Status | F3: Ngày phát hiện | G3: Lần fix gần nhất | H3: Re-test kết quả | I3: Ghi chú
A4: BUG-001 | B4: TC-169 | C4: Test fail: TC-169: Dispatcher phân công Case sang Team-Q2 + investigator của team @P0 @GREEN @Critical | D4: Critical | E4: Open | F4: 23/05/2026
A5: BUG-002 | B5: TC-171 | C5: Test fail: TC-171: Case ngoài scope của dispatcher (nếu dispatcher có scope giới hạn) → ? @P0 @RED @High | D5: High | E5: Open | F5: 23/05/2026
A6: BUG-003 | B6: TC-172 | C6: Test fail: TC-172: assignedTeamId team đã isActive=false → 400 'Tổ điều tra không tồn tại hoặc đã ngừng hoạt động' @P0 @RED @High | D6: High | E6: Open | F6: 23/05/2026
A7: BUG-004 | B7: TC-173 | C7: Test fail: TC-173: investigatorId không thuộc team được chỉ định → 400 'Điều tra viên không thuộc tổ' @P0 @RED @High | D7: High | E7: Open | F7: 23/05/2026
A8: BUG-005 | B8: TC-174 | C8: Test fail: TC-174: investigatorId=null khi assign (chỉ chuyển team, chưa giao cho ĐTV cụ thể) @P1 @GREEN @High | D8: High | E8: Open | F8: 23/05/2026
A9: BUG-006 | B9: TC-175 | C9: Test fail: TC-175: Case không tồn tại → 404 @P0 @RED @High | D9: High | E9: Open | F9: 23/05/2026
A10: BUG-007 | B10: TC-176 | C10: Test fail: TC-176: Case đã soft-deleted → 404 @P0 @RED @High | D10: High | E10: Open | F10: 23/05/2026
A11: BUG-008 | B11: TC-177 | C11: Test fail: TC-177: expectedUpdatedAt mismatch → 409 @P0 @RED @High | D11: High | E11: Open | F11: 23/05/2026
A12: BUG-009 | B12: TC-178 | C12: Test fail: TC-178: Escalation: ward team → non-ward team → emit CASE_ESCALATED_FROM_WARD audit @P0 @GREEN @High | D12: High | E12: Open | F12: 23/05/2026
A13: BUG-010 | B13: TC-179 | C13: Test fail: TC-179: Re-assign cùng team (no-op assignedTeamId không đổi) → audit không emit escalation @P1 @GREEN @Medium | D13: Medium | E13: Open | F13: 23/05/2026
A14: BUG-011 | B14: TC-180 | C14: Test fail: TC-180: Non-ward team → ward team (de-escalation) — audit không emit (chỉ from-ward) @P1 @GREEN @Medium | D14: Medium | E14: Open | F14: 23/05/2026
A15: BUG-012 | B15: TC-181 | C15: Test fail: TC-181: assignedTeamId rỗng '' → 400 @P1 @RED @Medium | D15: Medium | E15: Open | F15: 23/05/2026
... A521: BUG-518 | B521: TC-124 | C521: Test fail: TC-124: DTO whitelist reject field lạ trong UpdateCaseDto (forbidNonWhitelisted) @P0 @GREEN @Medium | D521: Medium | E521: Open | F521: 23/05/2026

Sheet Regression Log
A1: ⚠️ REGRESSION LOG — Theo dõi lỗi level down (TC từng Đạt nay Không đạt)
A2: Auto-generated bởi runner khi phát hiện TC từng Đạt giờ Không đạt sau khi fix bug khác. Severity tự động ESCALATE +1 level (High→Critical, Medium→High...). BẤT KỲ regression nào còn open đều BLOCK release.
A3: Reg ID | B3: TC ID | C3: Module | D3: Lần phát hiện | E3: Bug gốc gây regression | F3: Status trước retest | G3: Status sau retest | H3: Severity gốc | I3: Severity regression | J3: Mô tả regression | K3: Đã fix? | L3: Ngày verify lại | M3: Ghi chú
