Workbook

Sheet UAT Result
A1: TỔNG KẾT UAT — Document Numbers
A2: Cập nhật lúc: 26/05/2026 02:10
A3: Modules: A11Y — Color Contrast, A11Y — Color Independent, A11Y — Destructive Action, A11Y — DocNumberPreviewField, A11Y — DocNumberPreviewField OVERRIDE, A11Y — Error Messages, A11Y — Focus Visible, A11Y — Full Keyboard Nav, A11Y — Keyboard Drag, A11Y — Live Region, A11Y — Modal Announce, A11Y — Sort, A11Y — Table, A11Y — TemplateFormModal, Atomic Transaction RED, Audit Log, Audit Log — Fields, Audit Log — Filter, Audit Log — Filter Date, Auth RED, Auth Role Tamper RED, Auth — Forbidden, Auth — RED, Auth — Suspended User RED, Auth — Token Expired, Auth — Unauthorized, Boundary INT Max RED, Boundary — Pagination, Boundary — Pagination Negative, Boundary — Template Name Length, Boundary — maxValue Minimum, COMPAT — Android, COMPAT — Brave, COMPAT — Browser, COMPAT — Drag Drop Chrome, COMPAT — Edge Accessibility, COMPAT — Firefox, COMPAT — High Contrast, COMPAT — Mobile, COMPAT — NVDA, COMPAT — Safari, COMPAT — Tablet, COMPAT — Text Zoom, COMPAT — Windows 10, COMPAT — iOS, Commit Number, Commit Number — Incident Integration, Commit Number — Petition Integration, Commit Number — RED, Commit RED, Commit Validation, Commit Validation RED, Commit — Max Retry RED, Commit — No Template RED, Commit — RED, Commit — draftPreview RED, Concurrency Stress P0, Concurrency — Basic, Concurrency — Exhaust RED, Concurrency — Reset RED, Concurrency — Reset+Commit RED, Concurrency — Row Lock, Concurrency — Stress, Content Negotiation — RED, Counter Cold Start, Counter Cold Start RED, Counter Config Change RED, Counter Exhausted WEEKLY, Counter Exhausted — MONTHLY, Counter Exhausted — NEVER, Counter Padding, Counter — Cold Start, Data — Empty Separator, Data — Special Chars, Data — XSS Stored, Data — i18n, Deploy — RED, Draft Log Accumulation RED, Draft Number, Draft Number — RED, Draft — Concurrent RED, Draft — Inactive Template RED, Draft — No Template, Draft — RED, EP — documentType, EP — inputMode, EP — resetPeriod, Filter — Date Format RED, Filter — RED, Formula Engine, Formula Engine — Context, Formula Engine — Segments, HTTP Method — RED, IDOR — Log Update RED, Infrastructure RED, Infrastructure — RED, Integration — Case List, Integration — Case atomic commit, Integration — Case from Petition with Incident, Integration — Delegation atomic commit, Integration — Incident, Integration — Incident atomic commit, Integration — Petition, Integration — Petition atomic commit, Integration — Proposal atomic commit, Log Filter — RED, Log Immutability RED, Log Update, Log Update — Immutable RED, Log Update — RED, No-Counter Template Commit RED, Pagination — RED, Performance — Commit, Performance — Draft, Performance — Draft Concurrency, Performance — UI, Period Key, Period Key — Year Boundary, Recovery — Backend Restart, Recovery — DB Rollback, Regression — Case List caseCode, Regression — Incident Create, Regression — Incident List, Regression — Petition Create, Regression — Sidebar, Regression — Uniqueness, Reset Counter, Reset Counter RED, Role × Endpoint Matrix, Security Account Delete P0, Security Authorization P0, Security Enumeration P0, Security Forced Browse P0, Security Header — RED, Security Input — RED, Security JWT Alg None P0, Security Mass Delete P0, Security Path Traversal — RED, Security Replay P0, Security SQL Injection P0, Security XSS Stored — RED, Security — Auth, Security — CORS, Security — CSRF, Security — Content Type, Security — Data Exposure, Security — Data Isolation, Security — Error Handling, Security — IDOR, Security — Info Leak, Security — Input, Security — Long Payload, Security — Mass Assignment, Security — Null Byte, Security — Privilege Escalation, Security — Prototype Pollution, Security — Rate Limit, Security — Replay, Security — Stats IDOR, Security — Timing, Security — Token Revocation, Security — Token Role, Security — XSS, Settings Page, Settings Page — Create, Settings Page — Edit, Stats After Reset RED, Stats Freshness RED, Template CRUD, Template CRUD — RED, Template Config Change RED, Template Constraint — RED, Template Default RED, Template Delete Constraint RED, Template Delete — RED, Template Minimal Segments RED, Template Preview, Template Preview — RED, Template State, Template State — Active Constraint, Template State — Commit RED, Template State — Counter Reset, Template State — Delete, Template Stats, Template Stats — RED, Template Uniqueness Constraint RED, Template Update Consistency RED, Template Update — RED, Template Validation, Template Validation RED, Template Validation — Case Sensitive RED, Template Validation — Duplicate COUNTER RED, Template Validation — Edge, Template Validation — NaN RED, Template Validation — RED, Template Validation — Segments Limit RED, Template Validation — Separator RED, Template Validation — documentType enum RED, Transaction Isolation RED, UI — DocNumberPreviewField, UI — SegmentBuilder, UI — SegmentBuilder — Preview, UI — Settings Page, UI — Settings Page — Role, UI — TemplateFormModal, Usability — Changed Toast, Usability — Live Preview, Usability — Loading State, Usability — Reset Confirm
A5: Chỉ tiêu | B5: Giá trị | C5: Ghi chú
A6: Tổng số TC | B6: 315
A7: ✅ Đạt (cả 2 layer) | B7: 22 | C7: 7.0%
A9: Layer 1 — API smoke
A10: API Pass | B10: 179 | C10: 56.8%
A11: API Fail | B11: 100
A12: API Skip/Blocked | B12: 4
A14: Layer 2 — UI E2E
A15: E2E Pass | B15: 28 | C15: 8.9%
A16: E2E Fail | B16: 9
A17: E2E Skip (API gate) | B17: 0
A19: Bug phát hiện
A20: P0/Critical fail | B20: 35 | C20: 🚨 BLOCKER
A21: P1/High fail | B21: 52 | C21: ⚠️ High priority
A23: Exit Criteria
A24: P0 100% pass | B24: ❌ FAIL
A25: P1 >= 95% pass | B25: ❌ FAIL
A26: Overall >= 80% | B26: ❌ FAIL | C26: 7.0%

Sheet Summary
A1: 📊 DASHBOARD - UAT EXECUTION SUMMARY
A3: TỔNG QUAN
A4: Tổng số TC | B4: 315 | C4: Số test case đã viết
A5: ✅ Đạt (cả 2 layer) | B5: =SUMPRODUCT(('Test Cases'!R4:R318="Đạt")*('Test Cases'!S4:S318="Đạt")) | C5: TC pass cả API VÀ E2E
A6: ❌ Không đạt | B6: =SUMPRODUCT((('Test Cases'!R4:R318="Không đạt")+('Test Cases'!S4:S318="Không đạt"))>0)*1 | C6: TC fail ít nhất 1 layer
A7: API Đạt | B7: =COUNTIF('Test Cases'!R4:R318,"Đạt") | C7: Layer 1 — API smoke
A8: API Không đạt | B8: =COUNTIF('Test Cases'!R4:R318,"Không đạt") | C8: API fail
A9: E2E Đạt | B9: =COUNTIF('Test Cases'!S4:S318,"Đạt") | C9: Layer 2 — UI E2E
A10: E2E Không đạt | B10: =COUNTIF('Test Cases'!S4:S318,"Không đạt") | C10: E2E fail
A11: E2E Bỏ qua | B11: =COUNTIF('Test Cases'!S4:S318,"Bỏ qua") | C11: Skip do API smoke fail
A12: Chưa chạy | B12: =COUNTBLANK('Test Cases'!R4:R318)+COUNTIF('Test Cases'!R4:R318,"Chưa chạy") | C12: Còn lại
A14: Tỷ lệ đạt (cả 2 layer) | B14: =IFERROR(SUMPRODUCT(('Test Cases'!R4:R318="Đạt")*('Test Cases'!S4:S318="Đạt"))/(SUMPRODUCT(('Test Cases'!R4:R318="Đạt")*('Test Cases'!S4:S318="Đạt"))+SUMPRODUCT((('Test Cases'!R4:R318="Không đạt")+('Test Cases'!S4:S318="Không đạt"))>0)),0) | C14: API+E2E đều Đạt / Tổng đã chạy
A15: API pass rate | B15: =IFERROR(COUNTIF('Test Cases'!R4:R318,"Đạt")/(COUNTIF('Test Cases'!R4:R318,"Đạt")+COUNTIF('Test Cases'!R4:R318,"Không đạt")),0) | C15: Layer 1
A16: E2E pass rate | B16: =IFERROR(COUNTIF('Test Cases'!S4:S318,"Đạt")/(COUNTIF('Test Cases'!S4:S318,"Đạt")+COUNTIF('Test Cases'!S4:S318,"Không đạt")),0) | C16: Layer 2 (UI Chromium)
A17: Tỷ lệ hoàn thành | B17: =IFERROR((COUNTIF('Test Cases'!R4:R318,"Đạt")+COUNTIF('Test Cases'!R4:R318,"Không đạt")+COUNTIF('Test Cases'!R4:R318,"Bị chặn"))/315,0) | C17: API đã chạy / Tổng
A19: ĐỘ PHỦ THEO LOẠI
A20: Loại | B20: Số TC | C20: Tỷ lệ | D20: Pass | E20: Fail | F20: Pass rate
A21: GREEN | B21: =COUNTIF('Test Cases'!B4:B318,"GREEN") | C21: =IFERROR(B21/315,0) | D21: =COUNTIFS('Test Cases'!B4:B318,"GREEN",'Test Cases'!S4:S318,"Đạt") | E21: =COUNTIFS('Test Cases'!B4:B318,"GREEN",'Test Cases'!S4:S318,"Không đạt") | F21: =IFERROR(D21/(D21+E21),0)
A22: RED | B22: =COUNTIF('Test Cases'!B4:B318,"RED") | C22: =IFERROR(B22/315,0) | D22: =COUNTIFS('Test Cases'!B4:B318,"RED",'Test Cases'!S4:S318,"Đạt") | E22: =COUNTIFS('Test Cases'!B4:B318,"RED",'Test Cases'!S4:S318,"Không đạt") | F22: =IFERROR(D22/(D22+E22),0)
A23: EDGE | B23: =COUNTIF('Test Cases'!B4:B318,"EDGE") | C23: =IFERROR(B23/315,0) | D23: =COUNTIFS('Test Cases'!B4:B318,"EDGE",'Test Cases'!S4:S318,"Đạt") | E23: =COUNTIFS('Test Cases'!B4:B318,"EDGE",'Test Cases'!S4:S318,"Không đạt") | F23: =IFERROR(D23/(D23+E23),0)
A24: BOUNDARY | B24: =COUNTIF('Test Cases'!B4:B318,"BOUNDARY") | C24: =IFERROR(B24/315,0) | D24: =COUNTIFS('Test Cases'!B4:B318,"BOUNDARY",'Test Cases'!S4:S318,"Đạt") | E24: =COUNTIFS('Test Cases'!B4:B318,"BOUNDARY",'Test Cases'!S4:S318,"Không đạt") | F24: =IFERROR(D24/(D24+E24),0)
A25: EP | B25: =COUNTIF('Test Cases'!B4:B318,"EP") | C25: =IFERROR(B25/315,0) | D25: =COUNTIFS('Test Cases'!B4:B318,"EP",'Test Cases'!S4:S318,"Đạt") | E25: =COUNTIFS('Test Cases'!B4:B318,"EP",'Test Cases'!S4:S318,"Không đạt") | F25: =IFERROR(D25/(D25+E25),0)
A26: STATE | B26: =COUNTIF('Test Cases'!B4:B318,"STATE") | C26: =IFERROR(B26/315,0) | D26: =COUNTIFS('Test Cases'!B4:B318,"STATE",'Test Cases'!S4:S318,"Đạt") | E26: =COUNTIFS('Test Cases'!B4:B318,"STATE",'Test Cases'!S4:S318,"Không đạt") | F26: =IFERROR(D26/(D26+E26),0)
A27: DECISION | B27: =COUNTIF('Test Cases'!B4:B318,"DECISION") | C27: =IFERROR(B27/315,0) | D27: =COUNTIFS('Test Cases'!B4:B318,"DECISION",'Test Cases'!S4:S318,"Đạt") | E27: =COUNTIFS('Test Cases'!B4:B318,"DECISION",'Test Cases'!S4:S318,"Không đạt") | F27: =IFERROR(D27/(D27+E27),0)
A28: SECURITY | B28: =COUNTIF('Test Cases'!B4:B318,"SECURITY") | C28: =IFERROR(B28/315,0) | D28: =COUNTIFS('Test Cases'!B4:B318,"SECURITY",'Test Cases'!S4:S318,"Đạt") | E28: =COUNTIFS('Test Cases'!B4:B318,"SECURITY",'Test Cases'!S4:S318,"Không đạt") | F28: =IFERROR(D28/(D28+E28),0)
A29: DATA | B29: =COUNTIF('Test Cases'!B4:B318,"DATA") | C29: =IFERROR(B29/315,0) | D29: =COUNTIFS('Test Cases'!B4:B318,"DATA",'Test Cases'!S4:S318,"Đạt") | E29: =COUNTIFS('Test Cases'!B4:B318,"DATA",'Test Cases'!S4:S318,"Không đạt") | F29: =IFERROR(D29/(D29+E29),0)
A30: PERFORMANCE | B30: =COUNTIF('Test Cases'!B4:B318,"PERFORMANCE") | C30: =IFERROR(B30/315,0) | D30: =COUNTIFS('Test Cases'!B4:B318,"PERFORMANCE",'Test Cases'!S4:S318,"Đạt") | E30: =COUNTIFS('Test Cases'!B4:B318,"PERFORMANCE",'Test Cases'!S4:S318,"Không đạt") | F30: =IFERROR(D30/(D30+E30),0)
A31: A11Y | B31: =COUNTIF('Test Cases'!B4:B318,"A11Y") | C31: =IFERROR(B31/315,0) | D31: =COUNTIFS('Test Cases'!B4:B318,"A11Y",'Test Cases'!S4:S318,"Đạt") | E31: =COUNTIFS('Test Cases'!B4:B318,"A11Y",'Test Cases'!S4:S318,"Không đạt") | F31: =IFERROR(D31/(D31+E31),0)
A32: COMPAT | B32: =COUNTIF('Test Cases'!B4:B318,"COMPAT") | C32: =IFERROR(B32/315,0) | D32: =COUNTIFS('Test Cases'!B4:B318,"COMPAT",'Test Cases'!S4:S318,"Đạt") | E32: =COUNTIFS('Test Cases'!B4:B318,"COMPAT",'Test Cases'!S4:S318,"Không đạt") | F32: =IFERROR(D32/(D32+E32),0)
A33: INTEGRATION | B33: =COUNTIF('Test Cases'!B4:B318,"INTEGRATION") | C33: =IFERROR(B33/315,0) | D33: =COUNTIFS('Test Cases'!B4:B318,"INTEGRATION",'Test Cases'!S4:S318,"Đạt") | E33: =COUNTIFS('Test Cases'!B4:B318,"INTEGRATION",'Test Cases'!S4:S318,"Không đạt") | F33: =IFERROR(D33/(D33+E33),0)
A34: REGRESSION | B34: =COUNTIF('Test Cases'!B4:B318,"REGRESSION") | C34: =IFERROR(B34/315,0) | D34: =COUNTIFS('Test Cases'!B4:B318,"REGRESSION",'Test Cases'!S4:S318,"Đạt") | E34: =COUNTIFS('Test Cases'!B4:B318,"REGRESSION",'Test Cases'!S4:S318,"Không đạt") | F34: =IFERROR(D34/(D34+E34),0)
A35: RECOVERY | B35: =COUNTIF('Test Cases'!B4:B318,"RECOVERY") | C35: =IFERROR(B35/315,0) | D35: =COUNTIFS('Test Cases'!B4:B318,"RECOVERY",'Test Cases'!S4:S318,"Đạt") | E35: =COUNTIFS('Test Cases'!B4:B318,"RECOVERY",'Test Cases'!S4:S318,"Không đạt") | F35: =IFERROR(D35/(D35+E35),0)
A36: AUDIT | B36: =COUNTIF('Test Cases'!B4:B318,"AUDIT") | C36: =IFERROR(B36/315,0) | D36: =COUNTIFS('Test Cases'!B4:B318,"AUDIT",'Test Cases'!S4:S318,"Đạt") | E36: =COUNTIFS('Test Cases'!B4:B318,"AUDIT",'Test Cases'!S4:S318,"Không đạt") | F36: =IFERROR(D36/(D36+E36),0)
A37: USABILITY | B37: =COUNTIF('Test Cases'!B4:B318,"USABILITY") | C37: =IFERROR(B37/315,0) | D37: =COUNTIFS('Test Cases'!B4:B318,"USABILITY",'Test Cases'!S4:S318,"Đạt") | E37: =COUNTIFS('Test Cases'!B4:B318,"USABILITY",'Test Cases'!S4:S318,"Không đạt") | F37: =IFERROR(D37/(D37+E37),0)
A39: THEO ĐỘ ƯU TIÊN
A40: Priority | B40: Số TC | C40: Tỷ lệ | D40: Pass | E40: Fail | F40: Pass rate
A41: P0 | B41: =COUNTIF('Test Cases'!C4:C318,"P0") | C41: =IFERROR(B41/315,0) | D41: =COUNTIFS('Test Cases'!C4:C318,"P0",'Test Cases'!S4:S318,"Đạt") | E41: =COUNTIFS('Test Cases'!C4:C318,"P0",'Test Cases'!S4:S318,"Không đạt") | F41: =IFERROR(D41/(D41+E41),0)
A42: P1 | B42: =COUNTIF('Test Cases'!C4:C318,"P1") | C42: =IFERROR(B42/315,0) | D42: =COUNTIFS('Test Cases'!C4:C318,"P1",'Test Cases'!S4:S318,"Đạt") | E42: =COUNTIFS('Test Cases'!C4:C318,"P1",'Test Cases'!S4:S318,"Không đạt") | F42: =IFERROR(D42/(D42+E42),0)
A43: P2 | B43: =COUNTIF('Test Cases'!C4:C318,"P2") | C43: =IFERROR(B43/315,0) | D43: =COUNTIFS('Test Cases'!C4:C318,"P2",'Test Cases'!S4:S318,"Đạt") | E43: =COUNTIFS('Test Cases'!C4:C318,"P2",'Test Cases'!S4:S318,"Không đạt") | F43: =IFERROR(D43/(D43+E43),0)
A44: P3 | B44: =COUNTIF('Test Cases'!C4:C318,"P3") | C44: =IFERROR(B44/315,0) | D44: =COUNTIFS('Test Cases'!C4:C318,"P3",'Test Cases'!S4:S318,"Đạt") | E44: =COUNTIFS('Test Cases'!C4:C318,"P3",'Test Cases'!S4:S318,"Không đạt") | F44: =IFERROR(D44/(D44+E44),0)
...

Sheet Test Cases
A1: BỘ TEST CASE UAT: Document Number Engine v0.42
A2: Tổng số TC: 315 | Ngày tạo: 25/05/2026 | Generated by uat-test-writer skill
A3: TC-ID | B3: Loại | C3: Độ ưu tiên | D3: Module | E3: Tiêu đề | F3: Yêu cầu | G3: Kỹ thuật test | H3: Mức độ rủi ro | I3: Điều kiện tiên quyết | J3: Các bước kiểm thử | K3: Dữ liệu kiểm thử | L3: Data fixtures cần | M3: Kết quả mong đợi - UI | N3: Kết quả mong đợi - API | O3: Kết quả mong đợi - Side effects | P3: Severity nếu fail | Q3: Kết quả thực tế | R3: Trạng thái API | S3: Trạng thái E2E | T3: Bug ID | U3: Lần chạy cuối | V3: Lịch sử chạy | W3: Cờ regression | X3: Ghi chú
A4: TC-001 | B4: GREEN | C4: P0 | D4: Draft Number | E4: GREEN: POST /draft INCIDENT — officer nhận preview mã vụ việc | F4: REQ-FUNC-001 | G4: Happy Path | H4: Cao | I4: Đăng nhập officer. Template INCIDENT active. | J4: 1. POST /api/v1/document-numbers/draft 2. Body: {documentType:'INCIDENT'} | K4: user.officer, template.incident.active | L4: user.officer, template.incident.active | M4: 200 OK. {previewNumber:'VV-2026-000XX', isDraft:true}. Counter không tăng. | P4: [API] Đạt như expected. Thời gian: 0ms | Q4: Đạt | T4: 26/05/2026 02:10
A5: TC-002 | B5: GREEN | C5: P0 | D5: Commit Number | E5: GREEN: POST /commit INCIDENT — counter tăng, log ghi isDraft=false | F5: REQ-FUNC-002 | G5: Happy Path | H5: Cao | I5: Officer. Template INCIDENT active. Counter = N. | J5: 1. POST /commit {documentType:'INCIDENT'} 2. Kiểm tra counter | K5: user.officer, template.incident.active, counter.incident.value_50 | L5: user.officer, template.incident.active, counter.incident.value_50 | M5: 200. {number:'VV-2026-NNNXX', logId, changed}. Counter=N+1. Log isDraft=false. | P5: [API] Đạt như expected. Thời gian: 0ms | Q5: Đạt | T5: 26/05/2026 02:10
A6: TC-003 | B6: GREEN | C6: P0 | D6: Commit Number | E6: GREEN: POST /commit PETITION với documentId — log gán documentId | F6: REQ-FUNC-003 | G6: Happy Path | H6: Cao | I6: Officer. Template PETITION active. | J6: 1. POST /commit {documentType:'PETITION', documentId:'some-uuid'} | K6: user.officer, template.petition.active | L6: user.officer, template.petition.active | M6: 200. log.documentId='some-uuid'. isDraft=false. | P6: [API] Đạt như expected. Thời gian: 0ms | Q6: Đạt | T6: 26/05/2026 02:10
A7: TC-004 | B7: GREEN | C7: P1 | D7: Template CRUD | E7: GREEN: GET /templates — admin xem danh sách 6 template seeded | F7: REQ-FUNC-004 | G7: Happy Path | H7: Cao | I7: Admin. 6 template đã seed. | J7: 1. GET /api/v1/document-numbers/templates | K7: user.admin, templates.all_seeded | L7: user.admin, templates.all_seeded | M7: 200. Array >= 6 items. Mỗi item có id, name, documentType, isActive, inputMode. | P7: [API] Đạt như expected. Thời gian: 0ms | Q7: Đạt | T7: 26/05/2026 02:10
A8: TC-005 | B8: GREEN | C8: P0 | D8: Template CRUD | E8: GREEN: POST /templates — admin tạo template mới | F8: REQ-FUNC-005 | G8: Happy Path | H8: Cao | I8: Admin. | J8: 1. POST /templates 2. Body hợp lệ: name, documentType, isActive, separator, inputMode, segments, counterConfig | K8: user.admin | L8: user.admin | M8: 201. Body có id (UUID), name, documentType, isActive=true. | P8: [API] Đạt như expected. Thời gian: 0ms | Q8: Đạt | T8: 26/05/2026 02:10
A9: TC-006 | B9: GREEN | C9: P1 | D9: Template CRUD | E9: GREEN: PUT /templates/:id — admin sửa separator | F9: REQ-FUNC-006 | G9: Happy Path | H9: Cao | I9: Admin. Template INCIDENT tồn tại. | J9: 1. PUT /templates/{id} {separator:'/'} | K9: user.admin, template.incident.active | L9: user.admin, template.incident.active | M9: 200. Template updated. Preview dùng '/' thay '-'. | P9: [API] Đạt như expected. Thời gian: 0ms | Q9: Đạt | T9: 26/05/2026 02:10
A10: TC-007 | B10: GREEN | C10: P1 | D10: Template CRUD | E10: GREEN: DELETE /templates/:id — admin xóa template inactive | F10: REQ-FUNC-007 | G10: Happy Path | H10: Cao | I10: Admin. Template PROPOSAL inactive. | J10: 1. DELETE /templates/{id} | K10: user.admin | L10: user.admin | M10: 200 hoặc 204. Template không còn trong GET /templates. | P10: [API] Đạt như expected. Thời gian: 0ms | Q10: Đạt | T10: 26/05/2026 02:10
A11: TC-008 | B11: GREEN | C11: P1 | D11: Template Preview | E11: GREEN: POST /templates/:id/preview — không tăng counter | F11: REQ-FUNC-008 | G11: Happy Path | H11: Cao | I11: Admin. Counter=42. | J11: 1. POST /templates/{id}/preview 2. Gọi lại lần 2 3. GET /stats | K11: user.admin, template.incident.active, counter.incident.value_50 | L11: user.admin, template.incident.active, counter.incident.value_50 | M11: Cả 2 lần: previewNumber giống nhau. Counter vẫn=42 (không tăng). | P11: [API] Đạt như expected. Thời gian: 0ms | Q11: Đạt | T11: 26/05/2026 02:10
A12: TC-009 | B12: GREEN | C12: P1 | D12: Template Stats | E12: GREEN: GET /templates/:id/stats — xem current, next, periodKey | F12: REQ-FUNC-009 | G12: Happy Path | H12: Cao | I12: Admin. Counter=106. | J12: 1. GET /templates/{id}/stats | K12: user.admin, counter.incident.value_106 | L12: user.admin, counter.incident.value_106 | M12: 200. {currentValue:106, nextValue:107, periodKey:'2026', resetPeriod:'YEARLY'}. | P12: [API] Đạt như expected. Thời gian: 0ms | Q12: Đạt | T12: 26/05/2026 02:10
A13: TC-010 | B13: GREEN | C13: P1 | D13: Reset Counter | E13: GREEN: POST /templates/:id/reset-counter — admin reset về minValue | F13: REQ-FUNC-010 | G13: Happy Path | H13: Cao | I13: Admin. Counter=50. | J13: 1. POST /templates/{id}/reset-counter 2. GET /stats | K13: user.admin, template.incident.active, counter.incident.value_50 | L13: user.admin, template.incident.active, counter.incident.value_50 | M13: 200. nextValue=1. resetAt not null. | P13: [API] Đạt như expected. Thời gian: 0ms | Q13: Đạt | T13: 26/05/2026 02:10
A14: TC-011 | B14: GREEN | C14: P1 | D14: Audit Log | E14: GREEN: GET /logs — admin xem audit log với schema đầy đủ | F14: REQ-FUNC-011 | G14: Happy Path | H14: Cao | I14: Admin. 18 log records. | J14: 1. GET /api/v1/document-numbers/logs | K14: user.admin, logs.mixed_users_18 | L14: user.admin, logs.mixed_users_18 | M14: 200. Items có: id, templateId, generatedNumber, documentType, documentId, userId, isDraft, createdAt. | P14: [API] Đạt như expected. Thời gian: 0ms | Q14: Đạt | T14: 26/05/2026 02:10
A15: TC-012 | B15: GREEN | C15: P1 | D15: Log Update | E15: GREEN: PATCH /logs/:logId — officer gán documentId vào log | F15: REQ-FUNC-012 | G15: Happy Path | H15: Cao | I15: Officer. Log isDraft=false, documentId=null. | J15: 1. PATCH /logs/{logId} {documentId:'real-doc-uuid'} | K15: user.officer, log.officer1.no_doc_id | L15: user.officer, log.officer1.no_doc_id | M15: 200. log.documentId='real-doc-uuid'. | P15: [API] Đạt như expected. Thời gian: 0ms | Q15: Đạt | T15: 26/05/2026 02:10
A16: TC-013 | B16: GREEN | C16: P1 | D16: Settings Page | E16: GREEN: /settings/document-numbers — admin thấy 6 template, preview số tiếp theo | F16: REQ-FUNC-013 | G16: Happy Path | H16: Cao | I16: Admin. | J16: 1. Vào /settings/document-numbers 2. Quan sát bảng | K16: user.admin, templates.all_seeded | L16: user.admin, templates.all_seeded | M16: 6 dòng: Mã vụ việc, Đơn thư, Hồ sơ, Đề xuất, Ủy thác, Vật chứng. Mỗi dòng có preview số tiếp theo và inputMode badge. | P16: [API] Đạt như expected. Thời gian: 0ms | Q16: Đạt | R16: Đạt | T16: 26/05/2026 02:10 | U16: R1:Đạt|R2:Đạt
A17: TC-014 | B17: GREEN | C17: P0 | D17: Settings Page — Create | E17: GREEN: TemplateFormModal 'Thêm mới' — admin tạo template qua UI | F17: REQ-FUNC-014 | G17: Happy Path | H17: Cao | I17: Admin. Trang /settings/document-numbers. | J17: 1. Click [+ Thêm mới] 2. Điền form (tên, loại, segment LITERAL+COUNTER) 3. Click Lưu | K17: user.admin | L17: user.admin | M17: Modal đóng. Danh sách cập nhật. Toast thành công. | P17: [API] Đạt như expected. Thời gian: 0ms | Q17: Đạt | R17: Đạt | T17: 26/05/2026 02:10 | U17: R1:Đạt|R2:Đạt
A18: TC-015 | B18: GREEN | C18: P0 | D18: Settings Page — Edit | E18: GREEN: TemplateFormModal 'Sửa' — pre-fill dữ liệu, sửa, lưu | F18: REQ-FUNC-015 | G18: Happy Path | H18: Cao | I18: Admin. | J18: 1. Click [Sửa] trên dòng INCIDENT 2. Modal pre-fill đúng dữ liệu 3. Sửa separator từ '-' sang '/' 4. Lưu | K18: user.admin, template.incident.active | L18: user.admin, template.incident.active | M18: Modal pre-fill đúng. Sau lưu, separator cập nhật. Preview dùng /. | P18: [API] Đạt như expected. Thời gian: 0ms | Q18: Đạt | R18: Đạt | T18: 26/05/2026 02:10 | U18: R1:Đạt|R2:Đạt
A19: TC-016 | B19: GREEN | C19: P0 | D19: Integration — Incident | E19: GREEN: Integration Incident — code tự sinh VV-YYYY-NNNNN | F19: REQ-FUNC-016 | G19: Happy Path | H19: Cao | I19: Officer. incidents.service.ts dùng commitWithTx(). | J19: 1. POST /api/v1/incidents {tieuDe:'Test', ...} | K19: user.officer, template.incident.active | L19: user.officer, template.incident.active | M19: 201. incident.code='VV-2026-NNNXX'. Log documentId=incident.id. | P19: [API] Đạt như expected. Thời gian: 0ms | Q19: Đạt | R19: Đạt | T19: 26/05/2026 02:10 | U19: R1:Đạt|R2:Đạt
A20: TC-017 | B20: GREEN | C20: P0 | D20: Integration — Petition | E20: GREEN: Integration Petition — stt tự sinh, không cần nhập tay | F20: REQ-FUNC-017 | G20: Happy Path | H20: Cao | I20: Officer. Template PETITION active. | J20: 1. Mở form tạo đơn thư 2. Không nhập stt (readonly) 3. Submit | K20: user.officer, template.petition.active | L20: user.officer, template.petition.active | M20: Petition tạo OK. stt='DT-2026-NNNXX'. | P20: [API] Đạt như expected. Thời gian: 0ms | Q20: Đạt | R20: Đạt | T20: 26/05/2026 02:10 | U20: R1:Đạt|R2:Đạt
A21: TC-018 | B21: GREEN | C21: P0 | D21: Integration — Case List | E21: GREEN: Danh sách hồ sơ — cột Mã vụ án hiển thị HS-YYYY-NNN không phải CUID | F21: REQ-FUNC-018 | G21: Happy Path | H21: Cao | I21: Officer. Hồ sơ có caseCode='HS-2026-001'. | J21: 1. Vào /cases 2. Xem cột Mã vụ án | K21: user.officer, template.case.active | L21: user.officer, template.case.active | M21: Hiển thị 'HS-2026-001', không phải CUID. | P21: [API] Đạt như expected. Thời gian: 0ms | Q21: Đạt | R21: Đạt | T21: 26/05/2026 02:10 | U21: R1:Đạt|R2:Đạt
A22: TC-019 | B22: GREEN | C22: P0 | D22: Concurrency — Basic | E22: GREEN: 2 commit đồng thời INCIDENT — 2 số unique, không deadlock | F22: REQ-FUNC-019 | G22: Happy Path | H22: Cao | I22: 2 officer gửi /commit cùng lúc. | J22: 1. Gửi 2 POST /commit {documentType:'INCIDENT'} song song | K22: user.officer, template.incident.active, counter.incident.value_50 | L22: user.officer, template.incident.active, counter.incident.value_50 | M22: 2 số khác nhau (N và N+1). Counter=ban_đầu+2. Không deadlock. | P22: [API] Đạt như expected. Thời gian: 0ms | Q22: Đạt | R22: Đạt | T22: 26/05/2026 02:10 | U22: R1:Đạt|R2:Đạt
A23: TC-020 | B23: GREEN | C23: P0 | D23: Counter — Cold Start | E23: GREEN: Cold-start counter — commit đầu tiên trong kỳ mới tạo counter row | F23: REQ-FUNC-020 | G23: Happy Path | H23: Cao | I23: Template YEARLY. Không có counter row cho 2026. | J23: 1. POST /commit lần đầu | K23: user.officer, template.incident.active, counter.incident.value_0 | L23: user.officer, template.incident.active, counter.incident.value_0 | M23: Counter row tạo mới periodKey='2026', currentValue=1. Number=prefix-2026-00001. | P23: [API] Đạt như expected. Thời gian: 0ms | Q23: Đạt | R23: Đạt | T23: 26/05/2026 02:10 | U23: R1:Đạt|R2:Đạt
A24: TC-021 | B24: RED | C24: P0 | D24: Auth — Unauthorized | E24: RED: POST /draft không có token → 401 | F24: REQ-FUNC-021 | G24: EP / BVA | H24: Cao | I24: Không có Authorization header. | J24: 1. POST /draft {documentType:'INCIDENT'} không có token | K24: template.incident.active | L24: template.incident.active | M24: 401 Unauthorized. Body có message. | P24: [API] Đạt như expected. Thời gian: 0ms | Q24: Đạt | R24: Đạt | T24: 26/05/2026 02:10 | U24: R1:Đạt|R2:Đạt
A25: TC-022 | B25: RED | C25: P0 | D25: Auth — Unauthorized | E25: RED: POST /commit không có token → 401 | F25: REQ-FUNC-022 | G25: EP / BVA | H25: Cao | I25: Không có Authorization header. | J25: 1. POST /commit {documentType:'INCIDENT'} không có token | K25: template.incident.active | L25: template.incident.active | M25: 401 Unauthorized. | P25: [API] Đạt như expected. Thời gian: 0ms | Q25: Đạt | R25: Đạt | T25: 26/05/2026 02:10 | U25: R1:Đạt|R2:Đạt
A26: TC-023 | B26: RED | C26: P0 | D26: Auth — Unauthorized | E26: RED: GET /templates không có token → 401 | F26: REQ-FUNC-023 | G26: EP / BVA | H26: Cao | I26: Không có Authorization header. | J26: 1. GET /templates không có token | M26: 401 Unauthorized. | P26: [API] Đạt như expected. Thời gian: 0ms | Q26: Đạt | R26: Đạt | S26: BUG-001 | T26: 26/05/2026 02:10 | U26: R1:Không đạt|R2:Đạt
A27: TC-024 | B27: RED | C27: P0 | D27: Auth — Forbidden | E27: RED: POST /templates với role OFFICER → 403 | F27: REQ-FUNC-024 | G27: EP / BVA | H27: Cao | I27: Đăng nhập officer (không phải admin). | J27: 1. POST /templates {name:'X', ...} | K27: user.officer | L27: user.officer | M27: 403 Forbidden. Officer không được tạo template. | P27: [API] Đạt như expected. Thời gian: 0ms | Q27: Đạt | R27: Đạt | T27: 26/05/2026 02:10 | U27: R1:Đạt|R2:Đạt
A28: TC-025 | B28: RED | C28: P0 | D28: Auth — Forbidden | E28: RED: POST /templates/:id/reset-counter với role OFFICER → 403 | F28: REQ-FUNC-025 | G28: EP / BVA | H28: Cao | I28: Đăng nhập officer. | J28: 1. POST /templates/{id}/reset-counter | K28: user.officer, template.incident.active | L28: user.officer, template.incident.active | M28: 403 Forbidden. Chỉ ADMIN được reset. | P28: [API] Đạt như expected. Thời gian: 0ms | Q28: Đạt | T28: 26/05/2026 02:10
A29: TC-026 | B29: RED | C29: P0 | D29: Draft — No Template | E29: RED: POST /draft documentType không có template active → 404 | F29: REQ-FUNC-026 | G29: EP / BVA | H29: Cao | I29: Không có template active cho EVIDENCE. | J29: 1. POST /draft {documentType:'EVIDENCE'} | K29: user.officer | L29: user.officer | M29: 404. message='No active template for documentType: EVIDENCE' | P29: [API] Đạt như expected. Thời gian: 0ms | Q29: Đạt | T29: 26/05/2026 02:10
A30: TC-027 | B30: RED | C30: P0 | D30: Commit Validation | E30: RED: POST /commit documentType=null → 400 | F30: REQ-FUNC-027 | G30: EP / BVA | H30: Cao | I30: Đăng nhập officer. | J30: 1. POST /commit {documentType:null} | K30: user.officer | L30: user.officer | M30: 400 Bad Request. Validation error: documentType required. | P30: [API] Đạt như expected. Thời gian: 0ms | Q30: Đạt | R30: Đạt | T30: 26/05/2026 02:10 | U30: R1:Đạt|R2:Đạt
A31: TC-028 | B31: RED | C31: P1 | D31: Commit Validation | E31: RED: POST /commit body rỗng {} → 400 | F31: REQ-FUNC-028 | G31: EP / BVA | H31: Cao | I31: Officer. | J31: 1. POST /commit {} | K31: user.officer | L31: user.officer | M31: 400. documentType is required. | P31: [API] Đạt như expected. Thời gian: 0ms | Q31: Đạt | R31: Không đạt | S31: BUG-002 | T31: 26/05/2026 02:10 | U31: R1:Đạt|R2:Không đạt | V31: ⚠️ REGRESSION
A32: TC-029 | B32: RED | C32: P1 | D32: Template Validation | E32: RED: POST /templates thiếu name → 400 | F32: REQ-FUNC-029 | G32: EP / BVA | H32: Cao | I32: Admin. | J32: 1. POST /templates {documentType:'PROPOSAL', isActive:true, segments:[], counterConfig:{}} | K32: user.admin | L32: user.admin | M32: 400. name is required. | P32: [API] Đạt như expected. Thời gian: 0ms | Q32: Đạt | R32: Đạt | T32: 26/05/2026 02:10 | U32: R1:Đạt|R2:Đạt
A33: TC-030 | B33: RED | C33: P1 | D33: Template Validation | E33: RED: POST /templates thiếu documentType → 400 | F33: REQ-FUNC-030 | G33: EP / BVA | H33: Cao | I33: Admin. | J33: 1. POST /templates {name:'X', isActive:true, segments:[], counterConfig:{}} | K33: user.admin | L33: user.admin | M33: 400. documentType is required. | P33: [API] Đạt như expected. Thời gian: 0ms | Q33: Đạt | R33: Đạt | T33: 26/05/2026 02:10 | U33: R1:Đạt|R2:Đạt
A34: TC-031 | B34: RED | C34: P1 | D34: Template CRUD — RED | E34: RED: GET /templates/:id không tồn tại → 404 | F34: REQ-FUNC-031 | G34: EP / BVA | H34: Cao | I34: Admin. | J34: 1. GET /templates/00000000-0000-0000-0000-000000000000/stats | K34: user.admin | L34: user.admin | M34: 404. message='Template not found' | P34: [API] Đạt như expected. Thời gian: 0ms | Q34: Đạt | R34: Đạt | T34: 26/05/2026 02:10 | U34: R1:Đạt|R2:Đạt
A35: TC-032 | B35: RED | C35: P1 | D35: Template CRUD — RED | E35: RED: DELETE /templates/:id đang active → 400 hoặc 409 | F35: REQ-FUNC-032 | G35: EP / BVA | H35: Cao | I35: Admin. Template INCIDENT isActive=true. | J35: 1. DELETE /templates/{id} của template đang active | K35: user.admin, template.incident.active | L35: user.admin, template.incident.active | M35: 400 hoặc 409. Không cho xóa template đang active. Phải deactivate trước. | P35: [API] Đạt như expected. Thời gian: 0ms | Q35: Đạt | R35: Đạt | T35: 26/05/2026 02:10 | U35: R1:Đạt|R2:Đạt
A36: TC-033 | B36: RED | C36: P1 | D36: Log Update — RED | E36: RED: PATCH /logs không tồn tại logId → 404 | F36: REQ-FUNC-033 | G36: EP / BVA | H36: Cao | I36: Officer. | J36: 1. PATCH /logs/00000000-0000-0000-0000-000000000000 {documentId:'uuid'} | K36: user.officer | L36: user.officer | M36: 404. Log not found. | P36: [API] Đạt như expected. Thời gian: 0ms | Q36: Đạt | R36: Đạt | T36: 26/05/2026 02:10 | U36: R1:Đạt|R2:Đạt
A37: TC-034 | B37: RED | C37: P1 | D37: Template Validation — RED | E37: RED: PUT /templates/:id với admin — segments=[] → 400 | F37: REQ-FUNC-034 | G37: EP / BVA | H37: Cao | I37: Admin. Template tồn tại. | J37: 1. PUT /templates/{id} {segments:[]} | K37: user.admin, template.incident.active | L37: user.admin, template.incident.active | M37: 400. segments không được rỗng (phải có ít nhất 1 segment). | P37: [API] Đạt như expected. Thời gian: 0ms | Q37: Đạt | R37: Đạt | T37: 26/05/2026 02:10 | U37: R1:Đạt|R2:Đạt
A38: TC-035 | B38: RED | C38: P0 | D38: Auth — Token Expired | E38: RED: POST /draft với JWT expired → 401 | F38: REQ-FUNC-035 | G38: EP / BVA | H38: Cao | I38: Token hết hạn (exp < now). | J38: 1. POST /draft {documentType:'INCIDENT'} với expired token | K38: user.expired_token, template.incident.active | L38: user.expired_token, template.incident.active | M38: 401. TokenExpiredError. Không trả draft number. | P38: [API] Đạt như expected. Thời gian: 0ms | Q38: Đạt | R38: Đạt | T38: 26/05/2026 02:10 | U38: R1:Đạt|R2:Đạt
A39: TC-036 | B39: GREEN | C39: P0 | D39: Formula Engine | E39: Formula YYYY — năm hiện tại đúng trong mã sinh | F39: REQ-FUNC-036 | G39: Happy Path | H39: Cao | I39: Template với FORMULA source=NOW pattern=YYYY, counter=0 | J39: 1. POST /draft {documentType:"INCIDENT"} 2. Kiểm tra previewNumber chứa năm hiện tại | K39: template.incident.active | L39: template.incident.active | M39: previewNumber chứa "2026" (năm UTC hiện tại). VD: "VV-2026-00107" | P39: [API] Không đạt - xem HTML report | Q39: Không đạt | S39: BUG-115 | T39: 26/05/2026 02:10
A40: TC-037 | B40: GREEN | C40: P1 | D40: Formula Engine | E40: Formula YY — 2 chữ số năm trong mã | F40: REQ-FUNC-037 | G40: Happy Path | H40: Cao | I40: Template với FORMULA pattern=YY | J40: 1. POST /draft với template dùng pattern YY | K40: template.yy_pattern | L40: template.yy_pattern | M40: Mã số chứa 2 chữ số năm, VD: "26" | P40: [API] Đạt như expected. Thời gian: 0ms | Q40: Đạt | T40: 26/05/2026 02:10
...

Sheet Test Data
A1: 1. TÀI KHOẢN KIỂM THỬ
A2: ID | B2: Email | C2: Mật khẩu | D2: Vai trò | E2: Trạng thái | F2: Mục đích | G2: Ghi chú
A3: user.admin | D3: ACTIVE | E3: Active | F3: Admin user (admin@pc02.local) với role ADMIN
A4: user.officer | D4: ACTIVE | E4: Active | F4: Officer user (officer1@pc02.local) với role OFFICER
A5: user.officer_with_workid | D5: ACTIVE | E5: Active | F5: Officer có workId='A001' (dùng để test Formula ctx:Login.workId)
A6: user.no_workid | D6: ACTIVE | E6: Active | F6: Officer không có workId (workId=null)
A9: 2. BOUNDARY VALUES (BVA)
A10: Field | B10: Giá trị | C10: Loại | D10: Kỳ vọng | E10: Ghi chú
A11: template.name | B11: A | C11: min | D11: 201 Created
A12: template.name | B12: AAAAAAAAAAAAAAAAAAAAAAAAAAAAAAAAAAAAAAAAAAAAAAAAAAAAAAAAAAAAAAAAAAAAAAAAAAAAAAAAAAAAAAAAAAAAAAAAAAAAAAAAAAAAAAAAAAAAAAAAAAAAAAAAAAAAAAAAAAAAAAAAAAAAAAAAAAAAAAAAAAAAAAAAAAAAAAAAAAAAAAAAAAAAAAAAAAAAAAAA | C12: max | D12: 201 Created | E12: 200 chars
A13: template.name | B13: AAAAAAAAAAAAAAAAAAAAAAAAAAAAAAAAAAAAAAAAAAAAAAAAAAAAAAAAAAAAAAAAAAAAAAAAAAAAAAAAAAAAAAAAAAAAAAAAAAAAAAAAAAAAAAAAAAAAAAAAAAAAAAAAAAAAAAAAAAAAAAAAAAAAAAAAAAAAAAAAAAAAAAAAAAAAAAAAAAAAAAAAAAAAAAAAAAAAAAAAA | C13: max+1 | D13: 400 name too long
A14: counterConfig.padding | B14: 0 | C14: min-1 | D14: 400 validation error
A15: counterConfig.padding | B15: 1 | C15: min | D15: 201 Created
A16: counterConfig.padding | B16: 10 | C16: max | D16: 201 Created
A17: counterConfig.padding | B17: 11 | C17: max+1 | D17: 400 padding too large
A18: counterConfig.minValue | B18: 0 | C18: min-1 | D18: 400 minValue >= 1
A19: counterConfig.minValue | B19: 1 | C19: min | D19: 201 Created
A20: counterConfig.maxValue | B20: 2147483647 | C20: INT_MAX | D20: 201 Created | E20: postgres int max
A21: pageSize | B21: 0 | C21: min-1 | D21: 400 pageSize >= 1
A22: pageSize | B22: 1 | C22: min | D22: 200 OK
A23: pageSize | B23: 100 | C23: max | D23: 200 OK
A24: pageSize | B24: 1000 | C24: max+1 | D24: 400 or capped at 100
A27: 3. SECURITY PAYLOADS (OWASP)
A28: Field/Endpoint | B28: Payload | C28: Loại tấn công | D28: Kỳ vọng | E28: OWASP Reference
A29: POST /templates body.name | B29: ' OR 1=1 -- | C29: SQL Injection | D29: 400 validation error | E29: A03:2021
A30: POST /templates body.name | B30: <script>alert(1)</script> | C30: XSS | D30: 400 or escaped | E30: A03:2021
A31: Authorization header | B31: Bearer invalid.token.here | C31: Invalid JWT | D31: 401 Unauthorized | E31: A07:2021
A32: Authorization header | B32: header.eyJhbGciOiJub25lIn0.payload. | C32: JWT alg:none | D32: 401 Unauthorized | E32: A07:2021
A33: GET /logs?templateId | B33: 00000000-0000-0000-0000-000000000000 | C33: IDOR | D33: 200 empty (not 403) | E33: A01:2021
A34: GET /templates?page | B34: 1; DROP TABLE templates; -- | C34: SQL Injection pagination | D34: 400 invalid page | E34: A03:2021
A35: POST /templates body.segments[].value | B35: VV[NULL]INJECT (null byte) | C35: Null byte injection | D35: 400 or stripped | E35: A03:2021
A36: POST /templates body.name | B36: AAAAAAAAAAAAAAAAAAAAAAAAAAAAAAAAAAAAAAAAAAAAAAAAAAAAAAAAAAAAAAAAAAAAAAAAAAAAAAAAAAAAAAAAAAAAAAAAAAAAAAAAAAAAAAAAAAAAAAAAAAAAAAAAAAAAAAAAAAAAAAAAAAAAAAAAAAAAAAAAAAAAAAAAAAAAAAAAAAAAAAAAAAAAAAAAAAAAAAAAAAAAAAAAAAAAAAAAAAAAAAAAAAAAAAAAAAAAAAAAAAAAAAAAAAAAAAAAAAAAAAAAAAAAAAAAAAAAAAAAAAAAAAAAAAAAAAAAAAAAAAAAAAAAAAAAAAAAAAAAAAAAAAAAAAAAAAAAAAAAAAAAAAAAAAAAAAAAAAAAAAAAAAAAAAAAAAAAAAAAAAAAAAAAAAAAAAAAAAAAAAAAAAAAAAAAAAAAAAAAAAAAAAAAAAAAAAAAAAAAAAAAAAAAAAAAAAAAAAAAAAAAAAAAAAAAAAAAAAAAAAAAAAAAAAAAAAAAAAAAAAAAAAAAAAAAAAAAAAAAAAAAAAAAAAAAAAAAAAAAAAAAAAAAAAAAAAAAAAAAAAAAAAAAAAAAAAAAAAAAAAAAAAAAAAAAAAAAAAAAAAAAAAAAAAAAAAAAAAAAAAAAAAAAAAAAAAAAAAAAAAAAAAAAAAAAAAAAAAAAAAAAAAAAAAAAAAAAAAAAAAAAAAAAAAAAAAAAAAAAAAAAAAAAAAAAAAAAAAAAAAAAAAAAAAAAAAAAAAAAAAAAAAAAAAAAAAAAAAAAAAAAAAAAAAAAAAAAAAAAAAAAAAAAAAAAAAAAAAAAAAAAAAAAAAAAAAAAAAAAAAAAAAAAAAAAAAAAAAAAAAAAAAAAAAAAAAAAAAAAAAAAAAAAAAAAAAAAAAAAAAAAAAAAAAAAAAAAAAAAAAAAAAAAAAAAAAAAAAAAAAAAAAAAAAAAAAAAAAAAAAAAAAAAAAAAAAAAAAAAAAAAAAAAAAAAAAAAAAAAAAAAAAAAAAAAAAAAAAAAAAAAAAAAAAAAAAAAAAAAAAAAAAAAAAAAAAAAAAAAAAAAAAAAAAAAAAAAAAAAAAAAAAAAAAAAAAAAAAAAAAAAAAAAAAAAAAAAAAAAAAAAAAAAAAAAAAAAAAAAAAAAAAAAAAAAAAAAAAAAAAAAAAAAAAAAAAAAAAAAAAAAAAAAAAAAAAAAAAAAAAAAAAAAAAAAAAAAAAAAAAAAAAAAAAAAAAAAAAAAAAAAAAAAAAAAAAAAAAAAAAAAAAAAAAAAAAAAAAAAAAAAAAAAAAAAAAAAAAAAAAAAAAAAAAAAAAAAAAAAAAAAAAAAAAAAAAAAAAAAAAAAAAAAAAAAAAAAAAAAAAAAAAAAAAAAAAAAAAAAAAAAAAAAAAAAAAAAAAAAAAAAAAAAAAAAAAAAAAAAAAAAAAAAAAAAAAAAAAAAAAAAAAAAAAAAAAAAAAAAAAAAAAAAAAAAAAAAAAAAAAAAAAAAAAAAAAAAAAAAAAAAAAAAAAAAAAAAAAAAAAAAAAAAAAAAAAAAAAAAAAAAAAAAAAAAAAAAAAAAAAAAAAAAAAAAAAAAAAAAAAAAAAAAAAAAAAAAAAAAAAAAAAAAAAAAAAAAAAAAAAAAAAAAAAAAAAAAAAAAAAAAAAAAAAAAAAAAAAAAAAAAAAAAAAAAAAAAAAAAAAAAAAAAAAAAAAAAAAAAAAAAAAAAAAAAAAAAAAAAAAAAAAAAAAAAAAAAAAAAAAAAAAAAAAAAAAAAAAAAAAAAAAAAAAAAAAAAAAAAAAAAAAAAAAAAAAAAAAAAAAAAAAAAAAAAAAAAAAAAAAAAAAAAAAAAAAAAAAAAAAAAAAAAAAAAAAAAAAAAAAAAAAAAAAAAAAAAAAAAAAAAAAAAAAAAAAAAAAAAAAAAAAAAAAAAAAAAAAAAAAAAAAAAAAAAAAAAAAAAAAAAAAAAAAAAAAAAAAAAAAAAAAAAAAAAAAAAAAAAAAAAAAAAAAAAAAAAAAAAAAAAAAAAAAAAAAAAAAAAAAAAAAAAAAAAAAAAAAAAAAAAAAAAAAAAAAAAAAAAAAAAAAAAAAAAAAAAAAAAAAAAAAAAAAAAAAAAAAAAAAAAAAAAAAAAAAAAAAAAAAAAAAAAAAAAAAAAAAAAAAAAAAAAAAAAAAAAAAAAAAAAAAAAAAAAAAAAAAAAAAAAAAAAAAAAAAAAAAAAAAAAAAAAAAAAAAAAAAAAAAAAAAAAAAAAAAAAAAAAAAAAAAAAAAAAAAAAAAAAAAAAAAAAAAAAAAAAAAAAAAAAAAAAAAAAAAAAAAAAAAAAAAAAAAAAAAAAAAAAAAAAAAAAAAAAAAAAAAAAAAAAAAAAAAAAAAAAAAAAAAAAAAAAAAAAAAAAAAAAAAAAAAAAAAAAAAAAAAAAAAAAAAAAAAAAAAAAAAAAAAAAAAAAAAAAAAAAAAAAAAAAAAAAAAAAAAAAAAAAAAAAAAAAAAAAAAAAAAAAAAAAAAAAAAAAAAAAAAAAAAAAAAAAAAAAAAAAAAAAAAAAAAAAAAAAAAAAAAAAAAAAAAAAAAAAAAAAAAAAAAAAAAAAAAAAAAAAAAAAAAAAAAAAAAAAAAAAAAAAAAAAAAAAAAAAAAAAAAAAAAAAAAAAAAAAAAAAAAAAAAAAAAAAAAAAAAAAAAAAAAAAAAAAAAAAAAAAAAAAAAAAAAAAAAAAAAAAAAAAAAAAAAAAAAAAAAAAAAAAAAAAAAAAAAAAAAAAAAAAAAAAAAAAAAAAAAAAAAAAAAAAAAAAAAAAAAAAAAAAAAAAAAAAAAAAAAAAAAAAAAAAAAAAAAAAAAAAAAAAAAAAAAAAAAAAAAAAAAAAAAAAAAAAAAAAAAAAAAAAAAAAAAAAAAAAAAAAAAAAAAAAAAAAAAAAAAAAAAAAAAAAAAAAAAAAAAAAAAAAAAAAAAAAAAAAAAAAAAAAAAAAAAAAAAAAAAAAAAAAAAAAAAAAAAAAAAAAAAAAAAAAAAAAAAAAAAAAAAAAAAAAAAAAAAAAAAAAAAAAAAAAAAAAAAAAAAAAAAAAAAAAAAAAAAAAAAAAAAAAAAAAAAAAAAAAAAAAAAAAAAAAAAAAAAAAAAAAAAAAAAAAAAAAAAAAAAAAAAAAAAAAAAAAAAAAAAAAAAAAAAAAAAAAAAAAAAAAAAAAAAAAAAAAAAAAAAAAAAAAAAAAAAAAAAAAAAAAAAAAAAAAAAAAAAAAAAAAAAAAAAAAAAAAAAAAAAAAAAAAAAAAAAAAAAAAAAAAAAAAAAAAAAAAAAAAAAAAAAAAAAAAAAAAAAAAAAAAAAAAAAAAAAAAAAAAAAAAAAAAAAAAAAAAAAAAAAAAAAAAAAAAAAAAAAAAAAAAAAAAAAAAAAAAAAAAAAAAAAAAAAAAAAAAAAAAAAAAAAAAAAAAAAAAAAAAAAAAAAAAAAAAAAAAAAAAAAAAAAAAAAAAAAAAAAAAAAAAAAAAAAAAAAAAAAAAAAAAAAAAAAAAAAAAAAAAAAAAAAAAAAAAAAAAAAAAAAAAAAAAAAAAAAAAAAAAAAAAAAAAAAAAAAAAAAAAAAAAAAAAAAAAAAAAAAAAAAAAAAAAAAAAAAAAAAAAAAAAAAAAAAAAAAAAAAAAAAAAAAAAAAAAAAAAAAAAAAAAAAAAAAAAAAAAAAAAAAAAAAAAAAAAAAAAAAAAAAAAAAAAAAAAAAAAAAAAAAAAAAAAAAAAAAAAAAAAAAAAAAAAAAAAAAAAAAAAAAAAAAAAAAAAAAAAAAAAAAAAAAAAAAAAAAAAAAAAAAAAAAAAAAAAAAAAAAAAAAAAAAAAAAAAAAAAAAAAAAAAAAAAAAAAAAAAAAAAAAAAAAAAAAAAAAAAAAAAAAAAAAAAAAAAAAAAAAAAAAAAAAAAAAAAAAAAAAAAAAAAAAAAAAAAAAAAAAAAAAAAAAAAAAAAAAAAAAAAAAAAAAAAAAAAAAAAAAAAAAAAAAAAAAAAAAAAAAAAAAAAAAAAAAAAAAAAAAAAAAAAAAAAAAAAAAAAAAAAAAAAAAAAAAAAAAAAAAAAAAAAAAAAAAAAAAAAAAAAAAAAAAAAAAAAAAAAAAAAAAAAAAAAAAAAAAAAAAAAAAAAAAAAAAAAAAAAAAAAAAAAAAAAAAAAAAAAAAAAAAAAAAAAAAAAAAAAAAAAAAAAAAAAAAAAAAAAAAAAAAAAAAAAAAAAAAAAAAAAAAAAAAAAAAAAAAAAAAAAAAAAAAAAAAAAAAAAAAAAAAAAAAAAAAAAAAAAAAAAAAAAAAAAAAAAAAAAAAAAAAAAAAAAAAAAAAAAAAAAAAAAAAAAAAAAAAAAAAAAAAAAAAAAAAAAAAAAAAAAAAAAAAAAAAAAAAAAAAAAAAAAAAAAAAAAAAAAAAAAAAAAAAAAAAAAAAAAAAAAAAAAAAAAAAAAAAAAAAAAAAAAAAAAAAAAAAAAAAAAAAAAAAAAAAAAAAAAAAAAAAAAAAAAAAAAAAAAAAAAAAAAAAAAAAAAAAAAAAAAAAAAAAAAAAAAAAAAAAAAAAAAAAAAAAAAAAAAAAAAAAAAAAAAAAAAAAAAAAAAAAAAAAAAAAAAAAAAAAAAAAAAAAAAAAAAAAAAAAAAAAAAAAAAAAAAAAAAAAAAAAAAAAAAAAAAAAAAAAAAAAAAAAAAAAAAAAAAAAAAAAAAAAAAAAAAAAAAAAAAAAAAAAAAAAAAAAAAAAAAAAAAAAAAAAAAAAAAAAAAAAAAAAAAAAAAAAAAAAAAAAAAAAAAAAAAAAAAAAAAAAAAAAAAAAAAAAAAAAAAAAAAAAAAAAAAAAAAAAAAAAAAAAAAAAAAAAAAAAAAAAAAAAAAAAAAAAAAAAAAAAAAAAAAAAAAAAAAAAAAAAAAAAAAAAAAAAAAAAAAAAAAAAAAAAAAAAAAAAAAAAAAAAAAAAAAAAAAAAAAAAAAAAAAAAAAAAAAAAAAAAAAAAAAAAAAAAAAAAAAAAAAAAAAAAAAAAAAAAAAAAAAAAAAAAAAAAAAAAAAAAAAAAAAAAAAAAAAAAAAAAAAAAAAAAAAAAAAAAAAAAAAAAAAAAAAAAAAAAAAAAAAAAAAAAAAAAAAAAAAAAAAAAAAAAAAAAAAAAAAAAAAAAAAAAAAAAAAAAAAAAAAAAAAAAAAAAAAAAAAAAAAAAAAAAAAAAAAAAAAAAAAAAAAAAAAAAAAAAAAAAAAAAAAAAAAAAAAAAAAAAAAAAAAAAAAAAAAAAAAAAAAAAAAAAAAAAAAAAAAAAAAAAAAAAAAAAAAAAAAAAAAAAAAAAAAAAAAAAAAAAAAAAAAAAAAAAAAAAAAAAAAAAAAAAAAAAAAAAAAAAAAAAAAAAAAAAAAAAAAAAAAAAAAAAAAAAAAAAAAAAAAAAAAAAAAAAAAAAAAAAAAAAAAAAAAAAAAAAAAAAAAAAAAAAAAAAAAAAAAAAAAAAAAAAAAAAAAAAAAAAAAAAAAAAAAAAAAAAAAAAAAAAAAAAAAAAAAAAAAAAAAAAAAAAAAAAAAAAAAAAAAAAAAAAAAAAAAAAAAAAAAAAAAAAAAAAAAAAAAAAAAAAAAAAAAAAAAAAAAAAAAAAAAAAAAAAAAAAAAAAAAAAAAAAAAAAAAAAAAAAAAAAAAAAAAAAAAAAAAAAAAAAAAAAAAAAAAAAAAAAAAAAAAAAAAAAAAAAAAAAAAAAAAAAAAAAAAAAAAAAAAAAAAAAAAAAAAAAAAAAAAAAAAAAAAAAAAAAAAAAAAAAAAAAAAAAAAAAAAAAAAAAAAAAAAAAAAAAAAAAAAAAAAAAAAAAAAAAAAAAAAAAAAAAAAAAAAAAAAAAAAAAAAAAAAAAAAAAAAAAAAAAAAAAAAAAAAAAAAAAAAAAAAAAAAAAAAAAAAAAAAAAAAAAAAAAAAAAAAAAAAAAAAAAAAAAAAAAAAAAAAAAAAAAAAAAAAAAAAAAAAAAAAAAAAAAAAAAAAAAAAAAAAAAAAAAAAAAAAAAAAAAAAAAAAAAAAAAAAAAAAAAAAAAAAAAAAAAAAAAAAAAAAAAAAAAAAAAAAAAAAAAAAAAAAAAAAAAAAAAAAAAAAAAAAAAAAAAAAAAAAAAAAAAAAAAAAAAAAAAAAAAAAAAAAAAAAAAAAAAAAAAAAAAAAAAAAAAAAAAAAAAAAAAAAAAAAAAAAAAAAAAAAAAAAAAAAAAAAAAAAAAAAAAAAAAAAAAAAAAAAAAAAAAAAAAAAAAAAAAAAAAAAAAAAAAAAAAAAAAAAAAAAAAAAAAAAAAAAAAAAAAAAAAAAAAAAAAAAAAAAAAAAAAAAAAAAAAAAAAAAAAAAAAAAAAAAAAAAAAAAAAAAAAAAAAAAAAAAAAAAAAAAAAAAAAAAAAAAAAAAAAAAAAAAAAAAAAAAAAAAAAAAAAAAAAAAAAAAAAAAAAAAAAAAAAAAAAAAAAAAAAAAAAAAAAAAAAAAAAAAAAAAAAAAAAAAAAAAAAAAAAAAAAAAAAAAAAAAAAAAAAAAAAAAAAAAAAAAAAAAAAAAAAAAAAAAAAAAAAAAAAAAAAAAAAAAAAAAAAAAAAAAAAAAAAAAAAAAAAAAAAAAAAAAAAAAAAAAAAAAAAAAAAAAAAAAAAAAAAAAAAAAAAAAAAAAAAAAAAAAAAAAAAAAAAAAAAAAAAAAAAAAAAAAAAAAAAAAAAAAAAAAAAAAAAAAAAAAAAAAAAAAAAAAAAAAAAAAAAAAAAAAAAAAAAAAAAAAAAAAAAAAAAAAAAAAAAAAAAAAAAAAAAAAAAAAAAAAAAAAAAAAAAAAAAAAAAAAAAAAAAAAAAAAAAAAAAAAAAAAAAAAAAAAAAAAAAAAAAAAAAAAAAAAAAAAAAAAAAAAAAAAAAAAAAAAAAAAAAAAAAAAAAAAAAAAAAAAAAAAAAAAAAAAAAAAAAAAAAAAAAAAAAAAAAAAAAAAAAAAAAAAAAAAAAAAAAAAAAAAAAAAAAAAAAAAAAAAAAAAAAAAAAAAAAAAAAAAAAAAAAAAAAAAAAAAAAAAAAAAAAAAAAAAAAAAAAAAAAAAAAAAAAAAAAAAAAAAAAAAAAAAAAAAAAAAAAAAAAAAAAAAAAAAAAAAAAAAAAAAAAAAAAAAAAAAAAAAAAAAAAAAAAAAAAAAAAAAAAAAAAAAAAAAAAAAAAAAAAAAAAAAAAAAAAAAAAAAAAAAAAAAAAAAAAAAAAAAAAAAAAAAAAAAAAAAAAAAAAAAAAAAAAAAAAAAAAAAAAAAAAAAAAAAAAAAAAAAAAAAAAAAAAAAAAAAAAAAAAAAAAAAAAAAAAAAAAAAAAAAAAAAAAAAAAAAAAAAAAAAAAAAAAAAAAAAAAAAAAAAAAAAAAAAAAAAAAAAAAAAAAAAAAAAAAAAAAAAAAAAAAAAAAAAAAAAAAAAAAAAAAAAAAAAAAAAAAAAAAAAAAAAAAAAAAAAAAAAAAAAAAAAAAAAAAAAAAAAAAAAAAAAAAAAAAAAAAAAAAAAAAAAAAAAAAAAAAAAAAAAAAAAAAAAAAAAAAAAAAAAAAAAAAAAAAAAAAAAAAAAAAAAAAAAAAAAAAAAAAAAAAAAAAAAAAAAAAAAAAAAAAAAAAAAAAAAAAAAAAAAAAAAAAAAAAAAAAAAAAAAAAAAAAAAAAAAAAAAAAAAAAAAAAAAAAAAAAAAAAAAAAAAAAAAAAAAAAAAAAAAAAAAAAAAAAAAAAAAAAAAAAAAAAAAAAAAAAAAAAAAAAAAAAAAAAAAAAAAAAAAAAAAAAAAAAAAAAAAAAAAAAAAAAAAAAAAAAAAAAAAAAAAAAAAAAAAAAAAAAAAAAAAAAAAAAAAAAAAAAAAAAAAAAAAAAAAAAAAAAAAAAAAAAAAAAAAAAAAAAAAAAAAAAAAAAAAAAAAAAAAAAAAAAAAAAAAAAAAAAAAAAAAAAAAAAAAAAAAAAAAAAAAAAAAAAAAAAAAAAAAAAAAAAAAAAAAAAAAAAAAAAAAAAAAAAAAAAAAAAAAAAAAAAAAAAAAAAAAAAAAAAAAAAAAAAAAAAAAAAAAAAAAAAAAAAAAAAAAAAAAAAAAAAAAAAAAAAAAAAAAAAAAAAAAAAAAAAAAAAAAAAAAAAAAAAAAAAAAAAAAAAAAAAAAAAAAAAAAAAAAAAAAAAAAAAAAAAAAAAAAAAAAAAAAAAAAAAAAAAAAAAAAAAAAAAAAAAAAAAAAAAAAAAAAAAAAAAAAAAAAAAAAAAAAAAAAAAAAAAAAAAAAAAAAAAAAAAAAAAAAAAAAAAAAAAAAAAAAAAAAAAAAAAAAAAAAAAAAAAAAAAAAAAAAAAAAAAAAAAAAAAAAAAAAAAAAAAAAAAAAAAAAAAAAAAAAAAAAAAAAAAAAAAAAAAAAAAAAAAAAAAAAAAAAAAAAAAAAAAAAAAAAAAAAAAAAAAAAAAAAAAAAAAAAAAAAAAAAAAAAAAAAAAAAAAAAAAAAAAAAAAAAAAAAAAAAAAAAAAAAAAAAAAAAAAAAAAAAAAAAAAAAAAAAAAAAAAAAAAAAAAAAAAAAAAAAAAAAAAAAAAAAAAAAAAAAAAAAAAAAAAAAAAAAAAAAAAAAAAAAAAAAAAAAAAAAAAAAAAAAAAAAAAAAAAAAAAAAAAAAAAAAAAAAAAAAAAAAAAAAAAAAAAAAAAAAAAAAAAAAAAAAAAAAAAAAAAAAAAAAAAAAAAAAAAAAAAAAAAAAAAAAAAAAAAAAAAAAAAAAAAAAAAAAAAAAAAAAAAAAAAAAAAAAAAAAAAAAAAAAAAAAAAAAAAAAAAAAAAAAAAAAAAAAAAAAAAAAAAAAAAAAAAAAAAAAAAAAAAAAAAAAAAAAAAAAAAAAAAAAAAAAAAAAAAAAAAAAAAAAAAAAAAAAAAAAAAAAAAAAAAAAAAAAAAAAAAAAAAAAAAAAAAAAAAAAAAAAAAAAAAAAAAAAAAAAAAAAAAAAAAAAAAAAAAAAAAAAAAAAAAAAAAAAAAAAAAAAAAAAAAAAAAAAAAAAAAAAAAAAAAAAAAAAAAAAAAAAAAAAAAAAAAAAAAAAAAAAAAAAAAAAAAAAAAAAAAAAAAAAAAAAAAAAAAAAAAAAAAAAAAAAAAAAAAAAAAAAAAAAAAAAAAAAAAAAAAAAAAAAAAAAAAAAAAAAAAAAAAAAAAAAAAAAAAAAAAAAAAAAAAAAAAAAAAAAAAAAAAAAAAAAAAAAAAAAAAAAAAAAAAAAAAAAAAAAAAAAAAAAAAAAAAAAAAAAAAAAAAAAAAAAAAAAAAAAAAAAAAAAAAAAAAAAAAAAAAAAAAAAAAAAAAAAAAAAAAAAAAAAAAAAAAAAAAAAAAAAAAAAAAAAAAAAAAAAAAAAAAAAAAAAAAAAAAAAAAAAAAAAAAAAAAAAAAAAAAAAAAAAAAAAAAAAAAAAAAAAAAAAAAAAAAAAAAAAAAAAAAAAAAAAAAAAAAAAAAAAAAAAAAAAAAAAAAAAAAAAAAAAAAAAAAAAAAAAAAAAAAAAAAAAAAAAAAAAAAAAAAAAAAAAAAAAAAAAAAAAAAAAAAAAAAAAAAAAAAAAAAAAAAAAAAAAAAAAAAAAAAAAAAAAAAAAAAAAAAAAAAAAAAAAAAAAAAAAAAAAAAAAAAAAAAAAAAAAAAAAAAAAAAAAAAAAAAAAAAAAAAAAAAAAAAAAAAAAAAAAAAAAAAAAAAAAAAAAAAAAAAAAAAAAAAAAAAAAAAAAAAAAAAAAAAAAAAAAAAAAAAAAAAAAAAAAAAAAAAAAAAAAAAAAAAAAAAAAAAAAAAAAAAAAAAAAAAAAAAAAAAAAAAAAAAAAAAAAAAAAAAAAAAAAAAAAAAAAAAAAAAAAAAAAAAAAAAAAAAAAAAAAAAAAAAAAAAAAAAAAAAAAAAAAAAAAAAAAAAAAAAAAAAAAAAAAAAAAAAAAAAAAAAAAAAAAAAAAAAAAAAAAAAAAAAAAAAAAAAAAAAAAAAAAAAAAAAAAAAAAAAAAAAAAAAAAAAAAAAAAAAAAAAAAAAAAAAAAAAAAAAAAAAAAAAAAAAAAAAAAAAAAAAAAAAAAAAAAAAAAAAAAAAAAAAAAAAAAAAAAAAAAAAAAAAAAAAAAAAAAAAAAAAAA | C36: Long payload DoS | D36: 400 name too long | E36: A05:2021

Sheet Data Matrix
A1: 🗂️ DATA MATURITY MATRIX — Fixtures runner seed tự động trước mỗi test
A2: Mỗi fixture có ID format <entity>.<state>.<lifecycle>.<shape>. Runner đọc setup_recipe → tự seed data trước test, KHÔNG cần human chạy SQL. Cleanup tự động sau test.
A3: Fixture ID | B3: Entity | C3: State | D3: Lifecycle | E3: Shape | F3: Mô tả | G3: Setup type | H3: Setup recipe | I3: Cleanup recipe | J3: Outputs | K3: TC sử dụng
A4: template.incident.active | B4: DocumentNumberTemplate | C4: active | E4: single | F4: Template INCIDENT active, segments=[LITERAL:VV, FORMULA:YYYY, COUNTER], padding=5, minValue=1, maxValue=99999, resetPeriod=YEARLY | H4: {"method": "seed", "command": "cd backend && node dist/prisma/seed-document-numbers.js", "note": "Template seeded tự động khi deploy. Verify: GET /api/v1/document-numbers/templates | jq '.[] | select(.documentType==\"INCIDENT\")'", "sql_verify": "SELECT id FROM document_number_templates WHERE document_type='INCIDENT' AND is_active=true LIMIT 1"} | I4: {"note": "No cleanup needed — seed is idempotent"} | J4: {"template_id": "$.id", "counter_config": "$.counterConfig"} | K4: TC-001, TC-002, TC-006, TC-008, TC-010, TC-015, TC-016, TC-019, TC-020, TC-021, TC-022, TC-025, TC-032, TC-034, TC-035, TC-036, TC-043, TC-048, TC-050, TC-051, TC-053, TC-058, TC-060, TC-071, TC-074, TC-075, TC-078, TC-079, TC-082, TC-083, TC-084, TC-090, TC-092, TC-093, TC-096, TC-097, TC-098, TC-100, TC-101, TC-106, TC-107, TC-116, TC-119, TC-120, TC-122, TC-125, TC-128, TC-129, TC-134, TC-135, TC-136, TC-151, TC-153, TC-154, TC-183, TC-184, TC-185, TC-188, TC-204, TC-205, TC-211, TC-212, TC-220, TC-221, TC-222, TC-229, TC-239, TC-242, TC-248, TC-249, TC-252, TC-253, TC-260, TC-263, TC-267, TC-268, TC-276, TC-279, TC-281, TC-286, TC-294, TC-295, TC-296, TC-298, TC-299, TC-300, TC-302, TC-304, TC-306, TC-307, TC-316
A5: template.case.active | B5: DocumentNumberTemplate | C5: active | E5: single | F5: Template CASE active, segments=[LITERAL:HS, FORMULA:YYYY, COUNTER], padding=3, resetPeriod=YEARLY | H5: {"method": "seed", "command": "cd backend && node dist/prisma/seed-document-numbers.js", "sql_verify": "SELECT id FROM document_number_templates WHERE document_type='CASE' AND is_active=true LIMIT 1"} | I5: {"note": "No cleanup needed"} | J5: {"template_id": "$.id"} | K5: TC-018, TC-059, TC-103, TC-123, TC-128, TC-132, TC-310
A6: template.petition.active | B6: DocumentNumberTemplate | C6: active | E6: single | F6: Template PETITION active, segments=[LITERAL:DT, FORMULA:YYYY, COUNTER], padding=5, resetPeriod=YEARLY | H6: {"method": "seed", "sql_verify": "SELECT id FROM document_number_templates WHERE document_type='PETITION' AND is_active=true LIMIT 1"} | I6: {"note": "No cleanup needed"} | J6: {"template_id": "$.id"} | K6: TC-003, TC-017, TC-052, TC-102, TC-124, TC-130
A7: template.proposal.active | B7: DocumentNumberTemplate | C7: active | E7: single | F7: Template PROPOSAL active, segments=[LITERAL:DX, FORMULA:YYYY, COUNTER], padding=5 | H7: {"method": "seed", "sql_verify": "SELECT id FROM document_number_templates WHERE document_type='PROPOSAL' AND is_active=true LIMIT 1"} | I7: {"note": "No cleanup needed"} | J7: {"template_id": "$.id"} | K7: TC-126
A8: template.delegation.active | B8: DocumentNumberTemplate | C8: active | E8: single | F8: Template DELEGATION active, segments=[LITERAL:UT, FORMULA:YYYY, COUNTER], separator='/', padding=4 | H8: {"method": "seed", "sql_verify": "SELECT id FROM document_number_templates WHERE document_type='DELEGATION' AND is_active=true LIMIT 1"} | I8: {"note": "No cleanup needed"} | J8: {"template_id": "$.id"} | K8: TC-127, TC-272
A9: template.evidence.override | B9: DocumentNumberTemplate | C9: active | E9: single | F9: Template EVIDENCE inputMode=AUTO_WITH_OVERRIDE, active | H9: {"method": "seed", "sql_verify": "SELECT id FROM document_number_templates WHERE document_type='EVIDENCE' AND input_mode='AUTO_WITH_OVERRIDE' AND is_active=true LIMIT 1"} | I9: {"note": "No cleanup needed"} | J9: {"template_id": "$.id"} | K9: TC-072, TC-108, TC-282
A10: template.monthly.active | B10: DocumentNumberTemplate | C10: active | E10: single | F10: Template với resetPeriod=MONTHLY (cần tạo thủ công qua API) | H10: {"method": "api", "endpoint": "POST /api/v1/document-numbers/templates", "body": {"name": "TEST-MONTHLY-{{random}}", "documentType": "PROPOSAL", "separator": "-", "inputMode": "AUTO", "isActive": true, "segments": [{"type": "LITERAL", "value": "TST"}, {"type": "COUNTER"}], "counterConfig": {"resetPeriod": "MONTHLY", "minValue": 1, "maxValue": 9999, "padding": 4}}, "auth": "admin_token"} | I10: {"method": "api", "endpoint": "DELETE /api/v1/document-numbers/templates/{{template_id}}"} | J10: {"template_id": "$.id"} | K10: TC-044, TC-186
A11: template.weekly.active | B11: DocumentNumberTemplate | C11: active | E11: single | F11: Template với resetPeriod=WEEKLY | H11: {"method": "api", "endpoint": "POST /api/v1/document-numbers/templates", "body": {"name": "TEST-WEEKLY-{{random}}", "documentType": "PROPOSAL", "separator": "-", "inputMode": "AUTO", "isActive": true, "segments": [{"type": "LITERAL", "value": "WK"}, {"type": "COUNTER"}], "counterConfig": {"resetPeriod": "WEEKLY", "minValue": 1, "maxValue": 9999, "padding": 4}}, "auth": "admin_token"} | I11: {"method": "api", "endpoint": "DELETE /api/v1/document-numbers/templates/{{template_id}}"} | J11: {"template_id": "$.id"} | K11: TC-045, TC-290
A12: template.never.active | B12: DocumentNumberTemplate | C12: active | E12: single | F12: Template với resetPeriod=NEVER | H12: {"method": "api", "endpoint": "POST /api/v1/document-numbers/templates", "body": {"name": "TEST-NEVER-{{random}}", "documentType": "DELEGATION", "separator": "-", "inputMode": "AUTO", "isActive": true, "segments": [{"type": "LITERAL", "value": "NV"}, {"type": "COUNTER"}], "counterConfig": {"resetPeriod": "NEVER", "minValue": 1, "maxValue": 999999, "padding": 5}}, "auth": "admin_token"} | I12: {"method": "api", "endpoint": "DELETE /api/v1/document-numbers/templates/{{template_id}}"} | J12: {"template_id": "$.id"} | K12: TC-046, TC-187
A13: template.maxnumber.active | B13: DocumentNumberTemplate | C13: active | E13: single | F13: Template với resetPeriod=MAX_NUMBER | H13: {"method": "api", "endpoint": "POST /api/v1/document-numbers/templates", "body": {"name": "TEST-MAXNUM-{{random}}", "documentType": "EVIDENCE", "separator": "-", "inputMode": "AUTO", "isActive": false, "segments": [{"type": "LITERAL", "value": "MX"}, {"type": "COUNTER"}], "counterConfig": {"resetPeriod": "MAX_NUMBER", "minValue": 1, "maxValue": 10, "padding": 2}}, "auth": "admin_token"} | I13: {"method": "api", "endpoint": "DELETE /api/v1/document-numbers/templates/{{template_id}}"} | J13: {"template_id": "$.id"} | K13: TC-047
A14: template.maxnumber.at_max | B14: DocumentNumberTemplate | C14: active | E14: single | F14: Template resetPeriod=MAX_NUMBER với counter đang ở maxValue (10/10) | H14: {"method": "sql", "steps": ["1. Tạo template maxnumber.active", "2. UPDATE document_number_counters SET current_value=10 WHERE template_id='{{template_id}}' AND period_key='global'"]} | I14: {"method": "api", "endpoint": "DELETE /api/v1/document-numbers/templates/{{template_id}}"} | J14: {"template_id": "$.id"} | K14: TC-301
A15: template.no_counter | B15: DocumentNumberTemplate | C15: active | E15: single | F15: Template PROPOSAL active nhưng chưa có counter row (period mới chưa từng commit) | H15: {"method": "api+sql", "steps": ["1. Tạo template mới qua POST /templates", "2. DELETE FROM document_number_counters WHERE template_id='{{template_id}}'"]} | I15: {"method": "api", "endpoint": "DELETE /api/v1/document-numbers/templates/{{template_id}}"} | J15: {"template_id": "$.id"} | K15: TC-049
... A23: counter.incident.value_106 | B23: DocumentNumberCounter | C23: production_baseline | E23: single | F23: Counter INCIDENT = 106 (production baseline sau seed) | H23: {"method": "sql", "sql": "UPDATE document_number_counters SET current_value=106 WHERE template_id=(SELECT id FROM document_number_templates WHERE document_type='INCIDENT' AND is_active=true) AND period_key='2026'"} | I23: {"note": "This is production baseline, no cleanup needed"} | J23: {"current_value": 106} | K23: TC-009, TC-053, TC-082, TC-093, TC-125, TC-135, TC-154, TC-249, TC-296, TC-316
A24: counter.incident.exhausted | B24: DocumentNumberCounter | C24: exhausted | E24: single | F24: Counter INCIDENT đã đạt maxValue (99999) — không thể commit thêm trong kỳ YEARLY | H24: {"method": "sql", "sql": "UPDATE document_number_counters SET current_value=99999 WHERE template_id=(SELECT id FROM document_number_templates WHERE document_type='INCIDENT' AND is_active=true) AND period_key='2026'"} | I24: {"sql": "UPDATE ... SET current_value=106 (restore production baseline)"} | J24: {"current_value": 99999}
A25: counter.incident.year_2026 | B25: DocumentNumberCounter | C25: near_max | E25: single | F25: Counter INCIDENT year_2026 = 99 (gần maxValue, test year boundary) | H25: {"method": "sql", "sql": "INSERT INTO document_number_counters (id, template_id, period_key, current_value, updated_at) VALUES (gen_random_uuid(), '{{template_incident_id}}', '2026', 99, NOW()) ON CONFLICT (template_id, period_key) DO UPDATE SET current_value=99"} | I25: {"sql": "DELETE FROM document_number_counters WHERE template_id='{{template_incident_id}}' AND period_key='2026'"} | J25: {"current_value": 99, "period_key": "2026"} | K25: TC-048
A26: counter.case.value_0 | B26: DocumentNumberCounter | C26: zero | E26: single | F26: Counter CASE = 0 | H26: {"method": "sql", "sql": "UPDATE document_number_counters SET current_value=0 WHERE template_id=(SELECT id FROM document_number_templates WHERE document_type='CASE' AND is_active=true) AND period_key='2026'"} | I26: {"note": "Restore after test"} | J26: {"current_value": 0} | K26: TC-059, TC-123
A27: counter.petition.value_0 | B27: DocumentNumberCounter | C27: zero | E27: single | F27: Counter PETITION = 0 | H27: {"method": "sql", "sql": "UPDATE document_number_counters SET current_value=0 WHERE template_id=(SELECT id FROM document_number_templates WHERE document_type='PETITION' AND is_active=true) AND period_key='2026'"} | I27: {"note": "Restore after test"} | J27: {"current_value": 0} | K27: TC-052, TC-124
A28: counter.proposal.value_0 | B28: DocumentNumberCounter | C28: zero | E28: single | F28: Counter PROPOSAL = 0 | H28: {"method": "sql", "sql": "UPDATE document_number_counters SET current_value=0 WHERE template_id=(SELECT id FROM document_number_templates WHERE document_type='PROPOSAL' AND is_active=true) AND period_key='2026'"} | I28: {"note": "Restore after test"} | J28: {"current_value": 0} | K28: TC-126
A29: counter.delegation.value_0 | B29: DocumentNumberCounter | C29: zero | E29: single | F29: Counter DELEGATION = 0 | H29: {"method": "sql", "sql": "UPDATE document_number_counters SET current_value=0 WHERE template_id=(SELECT id FROM document_number_templates WHERE document_type='DELEGATION' AND is_active=true) AND period_key='global'"} | I29: {"note": "Restore after test"} | J29: {"current_value": 0} | K29: TC-127, TC-272
A30: user.admin | B30: User | C30: active | E30: single | F30: Admin user (admin@pc02.local) với role ADMIN | H30: {"method": "existing", "credentials": {"email": "admin@pc02.local", "password": "{{env.ADMIN_PASSWORD}}"}, "note": "Seeded tự động. GET /api/v1/auth/login để lấy token"} | I30: {"note": "Không xóa — account hệ thống"} | J30: {"user_id": "$.id", "token": "$.accessToken"} | K30: TC-004, TC-005, TC-006, TC-007, TC-008, TC-009, TC-010, TC-011, TC-013, TC-014, TC-015, TC-029, TC-030, TC-031, TC-032, TC-034, TC-055, TC-062, TC-063, TC-064, TC-065, TC-066, TC-067, TC-068, TC-069, TC-070, TC-076, TC-077, TC-078, TC-079, TC-080, TC-081, TC-082, TC-083, TC-084, TC-086, TC-087, TC-088, TC-089, TC-090, TC-091, TC-092, TC-093, TC-094, TC-095, TC-096, TC-109, TC-110, TC-111, TC-112, TC-113, TC-114, TC-115, TC-117, TC-118, TC-121, TC-133, TC-137, TC-138, TC-139, TC-140, TC-141, TC-142, TC-143, TC-144, TC-145, TC-146, TC-147, TC-148, TC-149, TC-152, TC-154, TC-155, TC-156, TC-157, TC-158, TC-159, TC-160, TC-161, TC-162, TC-163, TC-164, TC-165, TC-166, TC-167, TC-168, TC-169, TC-170, TC-175, TC-176, TC-188, TC-189, TC-190, TC-191, TC-192, TC-196, TC-197, TC-198, TC-200, TC-201, TC-202, TC-204, TC-213, TC-215, TC-216, TC-217, TC-218, TC-219, TC-223, TC-224, TC-225, TC-226, TC-227, TC-228, TC-230, TC-231, TC-232, TC-233, TC-234, TC-235, TC-236, TC-238, TC-239, TC-245, TC-246, TC-247, TC-248, TC-251, TC-252, TC-253, TC-255, TC-256, TC-257, TC-259, TC-260, TC-261, TC-264, TC-265, TC-266, TC-268, TC-269, TC-270, TC-273, TC-277, TC-278, TC-279, TC-281, TC-283, TC-284, TC-285, TC-287, TC-289, TC-291, TC-292, TC-296, TC-297, TC-298, TC-299, TC-301, TC-302, TC-304, TC-305, TC-306, TC-308, TC-312, TC-317, TC-318, TC-319, TC-320
