Workbook

Sheet TỔNG
A1: THỐNG KÊ HÌNH SỰ LIÊN NGÀNH Kỳ thống kê tháng …. năm 2026
A3: Tiêu chí | B3: Mã | C3: Số
B4: dòng | C4: liệu
A5: I. TIẾP NHẬN, GIẢI QUYẾT TỐ GIÁC, TIN BÁO VỀ TỘI PHẠM VÀ KIẾN NGHỊ KHỞI TỐ
A6: Số tố giác, tin báo về tội phạm, kiến nghị khởi tố mới nhận | B6: 1 | C6: =SUM('Đội 3:Cơ sở 2'!C6) -> 222
A7: Tổng số tố giác, tin báo về tội phạm, kiến nghị khởi tố phải giải quyết | B7: 2 | C7: =SUM('Đội 3:Cơ sở 2'!C7) -> 515
A8: Số tố giác, tin báo về tội phạm, kiến nghị khởi tố đã quyết định khởi tố vụ án hình sự | B8: 3 | C8: =SUM('Đội 3:Cơ sở 2'!C8) -> 172
A9: Số tố giác, tin báo về tội phạm, kiến nghị khởi tố quyết định không khởi tố vụ án hình sự | B9: 4 | C9: =SUM('Đội 3:Cơ sở 2'!C9) -> 15
A10: Số tố giác, tin báo về tội phạm, kiến nghị khởi tố tạm đình chỉ việc giải quyết trong kỳ thống kê | B10: 5 | C10: =SUM('Đội 3:Cơ sở 2'!C10) -> 30
A11: Tổng số tố giác, tin báo về tội phạm, kiến nghị khởi tố tạm đình chỉ giải quyết tính đến cuối kỳ thống kê | B11: 6 | C11: =SUM('Đội 3:Cơ sở 2'!C11) -> 3934
A12: Số tố giác, tin báo về tội phạm, kiến nghị khởi tố cuối kỳ chưa giải quyết xong | B12: 7 | C12: =SUM('Đội 3:Cơ sở 2'!C12) -> 372
A13: Trong đó: Số tố giác, tin báo về tội phạm, kiến nghị khởi tố đã quá hạn | B13: 8 | C13: =SUM('Đội 3:Cơ sở 2'!C13) -> 0
A14: Số quyết định VKS hủy bỏ các lệnh, quyết định không có căn cứ và trái pháp luật của CQĐT, cơ quan được giao nhiệm vụ tiến hành một số hoạt động điều tra | B14: 9 | C14: =SUM('Đội 3:Cơ sở 2'!C14) -> 0
A15: Số bản kiến nghị của VKS ban hành kiến nghị CQĐT, cơ quan được giao nhiệm vụ tiến hành một số hoạt động điều tra được chấp nhận | B15: 10 | C15: =SUM('Đội 3:Cơ sở 2'!C15) -> 0
A16: II. KHỞI TỐ, ĐIỀU TRA VÀ KIỂM SÁT ĐIỀU TRA CÁC VỤ ÁN HÌNH SỰ
A17: Số vụ án mới khởi tố | B17: 11 | C17: =SUM('Đội 3:Cơ sở 2'!C17) -> 172
A18: Số bị can mới khởi tố | B18: 12 | C18: =SUM('Đội 3:Cơ sở 2'!C18) -> 210
A19: Tổng số vụ án thụ lý điều tra | B19: 13 | C19: =SUM('Đội 3:Cơ sở 2'!C19) -> 2356
A20: Tổng số bị can thụ lý điều tra | B20: 14 | C20: =SUM('Đội 3:Cơ sở 2'!C20) -> 2135
A21: Số vụ án đề nghị truy tố | B21: 15 | C21: =SUM('Đội 3:Cơ sở 2'!C21) -> 147
A22: Số bị can đề nghị truy tố | B22: 16 | C22: =SUM('Đội 3:Cơ sở 2'!C22) -> 374
A23: Số vụ án CQĐT đình chỉ điều tra | B23: 17 | C23: =SUM('Đội 3:Cơ sở 2'!C23) -> 497
A24: Số bị can CQĐT đình chỉ điều tra | B24: 18 | C24: =SUM('Đội 3:Cơ sở 2'!C24) -> 6
A25: Trong đó: - Số bị can đình chỉ điều tra do không có sự việc phạm tội (theo K1 Đ157 BLTTHS) - (không tính trường hợp đình chỉ do bị can bị tâm thần). | B25: 19 | C25: =SUM('Đội 3:Cơ sở 2'!C25) -> 0
A26: - Số bị can đình chỉ điều tra do hành vi không cấu thành tội phạm (theo K2 Đ157 BLTTHS) - (không tính trường hợp đình chỉ do bị can bị tâm thần). | B26: 20 | C26: =SUM('Đội 3:Cơ sở 2'!C26) -> 0
A27: - Số bị can đình chỉ vì hết thời hạn điều tra mà không chứng minh được bị can đã thực hiện tội phạm (theo điểm b K1 Đ230 BLTTHS) | B27: 21 | C27: =SUM('Đội 3:Cơ sở 2'!C27) -> 0
A28: - Số bị can đình chỉ do được miễn trách nhiệm hình sự theo K1 Đ29 BLHS | B28: 22 | C28: =SUM('Đội 3:Cơ sở 2'!C28) -> 0
... A37: Số bản kiến nghị của VKS ban hành kiến nghị CQĐT, cơ quan được giao nhiệm vụ tiến hành một số hoạt động điều tra được chấp nhận | B37: 31 | C37: =SUM('Đội 3:Cơ sở 2'!C37) -> 0
A38: III. QUYẾT ĐỊNH VIỆC TRUY TỐ
A39: Số vụ án mới thụ lý | B39: 32 | C39: =SUM('Đội 3:Cơ sở 2'!C39) -> #REF!
A40: Số bị can mới thụ lý | B40: 33 | C40: =SUM('Đội 3:Cơ sở 2'!C40) -> #REF!
A41: Tổng số vụ án VKS thụ lý giải quyết | B41: 34 | C41: =SUM('Đội 3:Cơ sở 2'!C41) -> #REF!
A42: Tổng số bị can VKS thụ lý giải quyết | B42: 35 | C42: =SUM('Đội 3:Cơ sở 2'!C42) -> #REF!
A43: Số vụ án truy tố | B43: 36 | C43: =SUM('Đội 3:Cơ sở 2'!C43) -> #REF!
A44: Số bị can truy tố | B44: 37 | C44: =SUM('Đội 3:Cơ sở 2'!C44) -> #REF!
A45: Số vụ án VKS quyết định không truy tố và ra quyết định đình chỉ | B45: 38 | C45: =SUM('Đội 3:Cơ sở 2'!C45) -> #REF!
A46: Trong đó: Số vụ án Toà án trả hồ sơ cho VKS để điều tra bổ sung nhưng sau đó đình chỉ | B46: 39 | C46: =SUM('Đội 3:Cơ sở 2'!C46) -> #REF!
A47: Số bị can VKS quyết định không truy tố và ra quyết định đình chỉ vụ án đối với bị can | B47: 40 | C47: =SUM('Đội 3:Cơ sở 2'!C47) -> #REF!
A48: Trong đó: - Số bị can đình chỉ điều tra do không có sự việc phạm tội (theo K1 Đ157 BLTTHS) | B48: 41 | C48: =SUM('Đội 3:Cơ sở 2'!C48) -> #REF!
A49: - Số bị can đình chỉ điều tra do hành vi không cấu thành tội phạm (theo K2 Đ157 BLTTHS) | B49: 42 | C49: =SUM('Đội 3:Cơ sở 2'!C49) -> #REF!
...

Sheet Đội 3
A1: THỐNG KÊ HÌNH SỰ LIÊN NGÀNH Kỳ thống kê tháng …. năm 2026
A3: Tiêu chí | B3: Mã | C3: Số
B4: dòng | C4: liệu
A5: I. TIẾP NHẬN, GIẢI QUYẾT TỐ GIÁC, TIN BÁO VỀ TỘI PHẠM VÀ KIẾN NGHỊ KHỞI TỐ
A6: Số tố giác, tin báo về tội phạm, kiến nghị khởi tố mới nhận | B6: 1 | C6: 5
A7: Tổng số tố giác, tin báo về tội phạm, kiến nghị khởi tố phải giải quyết | B7: 2 | C7: 5
A8: Số tố giác, tin báo về tội phạm, kiến nghị khởi tố đã quyết định khởi tố vụ án hình sự | B8: 3 | C8: 5
A9: Số tố giác, tin báo về tội phạm, kiến nghị khởi tố quyết định không khởi tố vụ án hình sự | B9: 4
A10: Số tố giác, tin báo về tội phạm, kiến nghị khởi tố tạm đình chỉ việc giải quyết trong kỳ thống kê | B10: 5
A11: Tổng số tố giác, tin báo về tội phạm, kiến nghị khởi tố tạm đình chỉ giải quyết tính đến cuối kỳ thống kê | B11: 6
A12: Số tố giác, tin báo về tội phạm, kiến nghị khởi tố cuối kỳ chưa giải quyết xong | B12: 7
A13: Trong đó: Số tố giác, tin báo về tội phạm, kiến nghị khởi tố đã quá hạn | B13: 8 | C13: 0
A14: Số quyết định VKS hủy bỏ các lệnh, quyết định không có căn cứ và trái pháp luật của CQĐT, cơ quan được giao nhiệm vụ tiến hành một số hoạt động điều tra | B14: 9
A15: Số bản kiến nghị của VKS ban hành kiến nghị CQĐT, cơ quan được giao nhiệm vụ tiến hành một số hoạt động điều tra được chấp nhận | B15: 10
A16: II. KHỞI TỐ, ĐIỀU TRA VÀ KIỂM SÁT ĐIỀU TRA CÁC VỤ ÁN HÌNH SỰ
A17: Số vụ án mới khởi tố | B17: 11 | C17: 5
A18: Số bị can mới khởi tố | B18: 12 | C18: 14
A19: Tổng số vụ án thụ lý điều tra | B19: 13 | C19: 73
A20: Tổng số bị can thụ lý điều tra | B20: 14 | C20: 151
A21: Số vụ án đề nghị truy tố | B21: 15 | C21: 6
A22: Số bị can đề nghị truy tố | B22: 16 | C22: 9
A23: Số vụ án CQĐT đình chỉ điều tra | B23: 17
A24: Số bị can CQĐT đình chỉ điều tra | B24: 18
A25: Trong đó: - Số bị can đình chỉ điều tra do không có sự việc phạm tội (theo K1 Đ157 BLTTHS) - (không tính trường hợp đình chỉ do bị can bị tâm thần). | B25: 19
A26: - Số bị can đình chỉ điều tra do hành vi không cấu thành tội phạm (theo K2 Đ157 BLTTHS) - (không tính trường hợp đình chỉ do bị can bị tâm thần). | B26: 20
A27: - Số bị can đình chỉ vì hết thời hạn điều tra mà không chứng minh được bị can đã thực hiện tội phạm (theo điểm b K1 Đ230 BLTTHS) | B27: 21
A28: - Số bị can đình chỉ do được miễn trách nhiệm hình sự theo K1 Đ29 BLHS | B28: 22
A29: - Số bị can đình chỉ do được miễn trách nhiệm hình sự theo K2 Đ29 BLHS | B29: 23
A30: - Số bị can đình chỉ điều tra do được miễn trách nhiệm hình sự theo K3 Đ29 BLHS | B30: 24
A31: Tổng số vụ án CQĐT ra quyết định tạm đình chỉ điều tra còn lại tính đến cuối kỳ thống kê | B31: 25
A32: Tổng số bị can CQĐT ra quyết định tạm đình chỉ điều tra còn lại tính đến cuối kỳ thống kê | B32: 26
A33: Số vụ án còn lại chưa kết thúc điều tra | B33: 27 | C33: 67
A34: Trong đó:Số vụ án chưa kết thúc điều tra đã quá thời hạn luật định | B34: 28
A35: Số bị can còn lại chưa kết thúc điều tra | B35: 29 | C35: 142
A36: Số quyết định VKS hủy bỏ các lệnh, quyết định không có căn cứ và trái pháp luật của CQĐT, cơ quan được giao nhiệm vụ tiến hành một số hoạt động điều tra | B36: 30
A37: Số bản kiến nghị của VKS ban hành kiến nghị CQĐT, cơ quan được giao nhiệm vụ tiến hành một số hoạt động điều tra được chấp nhận | B37: 31
A38: III. QUYẾT ĐỊNH VIỆC TRUY TỐ
A39: Số vụ án mới thụ lý | B39: 32
A40: Số bị can mới thụ lý | B40: 33
A41: Tổng số vụ án VKS thụ lý giải quyết | B41: 34
...

Sheet Đội 4
A1: THỐNG KÊ HÌNH SỰ LIÊN NGÀNH Kỳ thống kê tháng …. năm 2026
A3: Tiêu chí | B3: Mã | C3: Số
B4: dòng | C4: liệu
A5: I. TIẾP NHẬN, GIẢI QUYẾT TỐ GIÁC, TIN BÁO VỀ TỘI PHẠM VÀ KIẾN NGHỊ KHỞI TỐ
A6: Số tố giác, tin báo về tội phạm, kiến nghị khởi tố mới nhận | B6: 1 | C6: 6
A7: Tổng số tố giác, tin báo về tội phạm, kiến nghị khởi tố phải giải quyết | B7: 2 | C7: 81
A8: Số tố giác, tin báo về tội phạm, kiến nghị khởi tố đã quyết định khởi tố vụ án hình sự | B8: 3 | C8: 10
A9: Số tố giác, tin báo về tội phạm, kiến nghị khởi tố quyết định không khởi tố vụ án hình sự | B9: 4 | C9: 1
A10: Số tố giác, tin báo về tội phạm, kiến nghị khởi tố tạm đình chỉ việc giải quyết trong kỳ thống kê | B10: 5 | C10: 8
A11: Tổng số tố giác, tin báo về tội phạm, kiến nghị khởi tố tạm đình chỉ giải quyết tính đến cuối kỳ thống kê | B11: 6 | C11: 1219
A12: Số tố giác, tin báo về tội phạm, kiến nghị khởi tố cuối kỳ chưa giải quyết xong | B12: 7 | C12: 70
A13: Trong đó: Số tố giác, tin báo về tội phạm, kiến nghị khởi tố đã quá hạn | B13: 8 | C13: 0
A14: Số quyết định VKS hủy bỏ các lệnh, quyết định không có căn cứ và trái pháp luật của CQĐT, cơ quan được giao nhiệm vụ tiến hành một số hoạt động điều tra | B14: 9 | C14: 0
A15: Số bản kiến nghị của VKS ban hành kiến nghị CQĐT, cơ quan được giao nhiệm vụ tiến hành một số hoạt động điều tra được chấp nhận | B15: 10 | C15: 0
A16: II. KHỞI TỐ, ĐIỀU TRA VÀ KIỂM SÁT ĐIỀU TRA CÁC VỤ ÁN HÌNH SỰ
A17: Số vụ án mới khởi tố | B17: 11 | C17: 10
A18: Số bị can mới khởi tố | B18: 12 | C18: 9
A19: Tổng số vụ án thụ lý điều tra | B19: 13 | C19: 547
A20: Tổng số bị can thụ lý điều tra | B20: 14 | C20: 211
A21: Số vụ án đề nghị truy tố | B21: 15 | C21: 5
A22: Số bị can đề nghị truy tố | B22: 16 | C22: 10
A23: Số vụ án CQĐT đình chỉ điều tra | B23: 17 | C23: 0
A24: Số bị can CQĐT đình chỉ điều tra | B24: 18 | C24: 0
A25: Trong đó: - Số bị can đình chỉ điều tra do không có sự việc phạm tội (theo K1 Đ157 BLTTHS) - (không tính trường hợp đình chỉ do bị can bị tâm thần). | B25: 19
A26: - Số bị can đình chỉ điều tra do hành vi không cấu thành tội phạm (theo K2 Đ157 BLTTHS) - (không tính trường hợp đình chỉ do bị can bị tâm thần). | B26: 20
A27: - Số bị can đình chỉ vì hết thời hạn điều tra mà không chứng minh được bị can đã thực hiện tội phạm (theo điểm b K1 Đ230 BLTTHS) | B27: 21
A28: - Số bị can đình chỉ do được miễn trách nhiệm hình sự theo K1 Đ29 BLHS | B28: 22
A29: - Số bị can đình chỉ do được miễn trách nhiệm hình sự theo K2 Đ29 BLHS | B29: 23
A30: - Số bị can đình chỉ điều tra do được miễn trách nhiệm hình sự theo K3 Đ29 BLHS | B30: 24
A31: Tổng số vụ án CQĐT ra quyết định tạm đình chỉ điều tra còn lại tính đến cuối kỳ thống kê | B31: 25 | C31: 1053
A32: Tổng số bị can CQĐT ra quyết định tạm đình chỉ điều tra còn lại tính đến cuối kỳ thống kê | B32: 26 | C32: 154
A33: Số vụ án còn lại chưa kết thúc điều tra | B33: 27 | C33: 490
A34: Trong đó:Số vụ án chưa kết thúc điều tra đã quá thời hạn luật định | B34: 28 | C34: 0
A35: Số bị can còn lại chưa kết thúc điều tra | B35: 29 | C35: 200
A36: Số quyết định VKS hủy bỏ các lệnh, quyết định không có căn cứ và trái pháp luật của CQĐT, cơ quan được giao nhiệm vụ tiến hành một số hoạt động điều tra | B36: 30 | C36: 0
A37: Số bản kiến nghị của VKS ban hành kiến nghị CQĐT, cơ quan được giao nhiệm vụ tiến hành một số hoạt động điều tra được chấp nhận | B37: 31 | C37: 0
A38: III. QUYẾT ĐỊNH VIỆC TRUY TỐ
A39: Số vụ án mới thụ lý | B39: 32
A40: Số bị can mới thụ lý | B40: 33
A41: Tổng số vụ án VKS thụ lý giải quyết | B41: 34
...

Sheet Đội 5
A1: THỐNG KÊ HÌNH SỰ LIÊN NGÀNH Kỳ thống kê tháng …. năm 2026
A3: Tiêu chí | B3: Mã | C3: Số
B4: dòng | C4: liệu
A5: I. TIẾP NHẬN, GIẢI QUYẾT TỐ GIÁC, TIN BÁO VỀ TỘI PHẠM VÀ KIẾN NGHỊ KHỞI TỐ
A6: Số tố giác, tin báo về tội phạm, kiến nghị khởi tố mới nhận | B6: 1 | C6: 2
A7: Tổng số tố giác, tin báo về tội phạm, kiến nghị khởi tố phải giải quyết | B7: 2 | C7: 2
A8: Số tố giác, tin báo về tội phạm, kiến nghị khởi tố đã quyết định khởi tố vụ án hình sự | B8: 3 | C8: 2
A9: Số tố giác, tin báo về tội phạm, kiến nghị khởi tố quyết định không khởi tố vụ án hình sự | B9: 4 | C9: 0
A10: Số tố giác, tin báo về tội phạm, kiến nghị khởi tố tạm đình chỉ việc giải quyết trong kỳ thống kê | B10: 5 | C10: 0
A11: Tổng số tố giác, tin báo về tội phạm, kiến nghị khởi tố tạm đình chỉ giải quyết tính đến cuối kỳ thống kê | B11: 6 | C11: 0
A12: Số tố giác, tin báo về tội phạm, kiến nghị khởi tố cuối kỳ chưa giải quyết xong | B12: 7 | C12: 0
A13: Trong đó: Số tố giác, tin báo về tội phạm, kiến nghị khởi tố đã quá hạn | B13: 8 | C13: 0
A14: Số quyết định VKS hủy bỏ các lệnh, quyết định không có căn cứ và trái pháp luật của CQĐT, cơ quan được giao nhiệm vụ tiến hành một số hoạt động điều tra | B14: 9 | C14: 0
A15: Số bản kiến nghị của VKS ban hành kiến nghị CQĐT, cơ quan được giao nhiệm vụ tiến hành một số hoạt động điều tra được chấp nhận | B15: 10 | C15: 0
A16: II. KHỞI TỐ, ĐIỀU TRA VÀ KIỂM SÁT ĐIỀU TRA CÁC VỤ ÁN HÌNH SỰ
A17: Số vụ án mới khởi tố | B17: 11 | C17: 3
A18: Số bị can mới khởi tố | B18: 12 | C18: 7
A19: Tổng số vụ án thụ lý điều tra | B19: 13 | C19: 27
A20: Tổng số bị can thụ lý điều tra | B20: 14 | C20: 181
A21: Số vụ án đề nghị truy tố | B21: 15 | C21: 0
A22: Số bị can đề nghị truy tố | B22: 16 | C22: 0
A23: Số vụ án CQĐT đình chỉ điều tra | B23: 17 | C23: 0
A24: Số bị can CQĐT đình chỉ điều tra | B24: 18 | C24: 0
A25: Trong đó: - Số bị can đình chỉ điều tra do không có sự việc phạm tội (theo K1 Đ157 BLTTHS) - (không tính trường hợp đình chỉ do bị can bị tâm thần). | B25: 19 | C25: 0
A26: - Số bị can đình chỉ điều tra do hành vi không cấu thành tội phạm (theo K2 Đ157 BLTTHS) - (không tính trường hợp đình chỉ do bị can bị tâm thần). | B26: 20 | C26: 0
A27: - Số bị can đình chỉ vì hết thời hạn điều tra mà không chứng minh được bị can đã thực hiện tội phạm (theo điểm b K1 Đ230 BLTTHS) | B27: 21 | C27: 0
A28: - Số bị can đình chỉ do được miễn trách nhiệm hình sự theo K1 Đ29 BLHS | B28: 22 | C28: 0
... A37: Số bản kiến nghị của VKS ban hành kiến nghị CQĐT, cơ quan được giao nhiệm vụ tiến hành một số hoạt động điều tra được chấp nhận | B37: 31 | C37: 0
A38: III. QUYẾT ĐỊNH VIỆC TRUY TỐ
A39: Số vụ án mới thụ lý | B39: 32
A40: Số bị can mới thụ lý | B40: 33
A41: Tổng số vụ án VKS thụ lý giải quyết | B41: 34
A42: Tổng số bị can VKS thụ lý giải quyết | B42: 35
A43: Số vụ án truy tố | B43: 36
A44: Số bị can truy tố | B44: 37
A45: Số vụ án VKS quyết định không truy tố và ra quyết định đình chỉ | B45: 38
A46: Trong đó: Số vụ án Toà án trả hồ sơ cho VKS để điều tra bổ sung nhưng sau đó đình chỉ | B46: 39
A47: Số bị can VKS quyết định không truy tố và ra quyết định đình chỉ vụ án đối với bị can | B47: 40
A48: Trong đó: - Số bị can đình chỉ điều tra do không có sự việc phạm tội (theo K1 Đ157 BLTTHS) | B48: 41
A49: - Số bị can đình chỉ điều tra do hành vi không cấu thành tội phạm (theo K2 Đ157 BLTTHS) | B49: 42
...

Sheet Đội 6
A1: THỐNG KÊ HÌNH SỰ LIÊN NGÀNH Kỳ thống kê tháng …. năm 2026
A3: Tiêu chí | B3: Mã | C3: Số
B4: dòng | C4: liệu
A5: I. TIẾP NHẬN, GIẢI QUYẾT TỐ GIÁC, TIN BÁO VỀ TỘI PHẠM VÀ KIẾN NGHỊ KHỞI TỐ
A6: Số tố giác, tin báo về tội phạm, kiến nghị khởi tố mới nhận | B6: 1 | C6: 3
A7: Tổng số tố giác, tin báo về tội phạm, kiến nghị khởi tố phải giải quyết | B7: 2 | C7: 4
A8: Số tố giác, tin báo về tội phạm, kiến nghị khởi tố đã quyết định khởi tố vụ án hình sự | B8: 3 | C8: 0
A9: Số tố giác, tin báo về tội phạm, kiến nghị khởi tố quyết định không khởi tố vụ án hình sự | B9: 4 | C9: 0
A10: Số tố giác, tin báo về tội phạm, kiến nghị khởi tố tạm đình chỉ việc giải quyết trong kỳ thống kê | B10: 5 | C10: 0
A11: Tổng số tố giác, tin báo về tội phạm, kiến nghị khởi tố tạm đình chỉ giải quyết tính đến cuối kỳ thống kê | B11: 6 | C11: 10
A12: Số tố giác, tin báo về tội phạm, kiến nghị khởi tố cuối kỳ chưa giải quyết xong | B12: 7 | C12: 4
A13: Trong đó: Số tố giác, tin báo về tội phạm, kiến nghị khởi tố đã quá hạn | B13: 8 | C13: 0
A14: Số quyết định VKS hủy bỏ các lệnh, quyết định không có căn cứ và trái pháp luật của CQĐT, cơ quan được giao nhiệm vụ tiến hành một số hoạt động điều tra | B14: 9 | C14: 0
A15: Số bản kiến nghị của VKS ban hành kiến nghị CQĐT, cơ quan được giao nhiệm vụ tiến hành một số hoạt động điều tra được chấp nhận | B15: 10 | C15: 0
A16: II. KHỞI TỐ, ĐIỀU TRA VÀ KIỂM SÁT ĐIỀU TRA CÁC VỤ ÁN HÌNH SỰ
A17: Số vụ án mới khởi tố | B17: 11 | C17: 5
A18: Số bị can mới khởi tố | B18: 12 | C18: 15
A19: Tổng số vụ án thụ lý điều tra | B19: 13 | C19: 22
A20: Tổng số bị can thụ lý điều tra | B20: 14 | C20: 135
A21: Số vụ án đề nghị truy tố | B21: 15
A22: Số bị can đề nghị truy tố | B22: 16
A23: Số vụ án CQĐT đình chỉ điều tra | B23: 17 | C23: 0
A24: Số bị can CQĐT đình chỉ điều tra | B24: 18 | C24: 0
A25: Trong đó: - Số bị can đình chỉ điều tra do không có sự việc phạm tội (theo K1 Đ157 BLTTHS) - (không tính trường hợp đình chỉ do bị can bị tâm thần). | B25: 19 | C25: 0
A26: - Số bị can đình chỉ điều tra do hành vi không cấu thành tội phạm (theo K2 Đ157 BLTTHS) - (không tính trường hợp đình chỉ do bị can bị tâm thần). | B26: 20 | C26: 0
A27: - Số bị can đình chỉ vì hết thời hạn điều tra mà không chứng minh được bị can đã thực hiện tội phạm (theo điểm b K1 Đ230 BLTTHS) | B27: 21 | C27: 0
A28: - Số bị can đình chỉ do được miễn trách nhiệm hình sự theo K1 Đ29 BLHS | B28: 22 | C28: 0
A29: - Số bị can đình chỉ do được miễn trách nhiệm hình sự theo K2 Đ29 BLHS | B29: 23 | C29: 0
A30: - Số bị can đình chỉ điều tra do được miễn trách nhiệm hình sự theo K3 Đ29 BLHS | B30: 24 | C30: 0
A31: Tổng số vụ án CQĐT ra quyết định tạm đình chỉ điều tra còn lại tính đến cuối kỳ thống kê | B31: 25 | C31: 12
A32: Tổng số bị can CQĐT ra quyết định tạm đình chỉ điều tra còn lại tính đến cuối kỳ thống kê | B32: 26 | C32: 2
A33: Số vụ án còn lại chưa kết thúc điều tra | B33: 27 | C33: 21
A34: Trong đó:Số vụ án chưa kết thúc điều tra đã quá thời hạn luật định | B34: 28 | C34: 0
... A37: Số bản kiến nghị của VKS ban hành kiến nghị CQĐT, cơ quan được giao nhiệm vụ tiến hành một số hoạt động điều tra được chấp nhận | B37: 31 | C37: 0
A38: III. QUYẾT ĐỊNH VIỆC TRUY TỐ
A39: Số vụ án mới thụ lý | B39: 32
A40: Số bị can mới thụ lý | B40: 33
A41: Tổng số vụ án VKS thụ lý giải quyết | B41: 34
A42: Tổng số bị can VKS thụ lý giải quyết | B42: 35
A43: Số vụ án truy tố | B43: 36
...

Sheet Tổ 1
A1: THỐNG KÊ HÌNH SỰ LIÊN NGÀNH Kỳ thống kê tháng …. năm 2026
A3: Tiêu chí | B3: Mã | C3: Số
B4: dòng | C4: liệu
A5: I. TIẾP NHẬN, GIẢI QUYẾT TỐ GIÁC, TIN BÁO VỀ TỘI PHẠM VÀ KIẾN NGHỊ KHỞI TỐ
A6: Số tố giác, tin báo về tội phạm, kiến nghị khởi tố mới nhận | B6: 1 | C6: 2
A7: Tổng số tố giác, tin báo về tội phạm, kiến nghị khởi tố phải giải quyết | B7: 2 | C7: =C8+C9+C10+C12 -> 23
A8: Số tố giác, tin báo về tội phạm, kiến nghị khởi tố đã quyết định khởi tố vụ án hình sự | B8: 3 | C8: 6
A9: Số tố giác, tin báo về tội phạm, kiến nghị khởi tố quyết định không khởi tố vụ án hình sự | B9: 4 | C9: 0
A10: Số tố giác, tin báo về tội phạm, kiến nghị khởi tố tạm đình chỉ việc giải quyết trong kỳ thống kê | B10: 5 | C10: 0
A11: Tổng số tố giác, tin báo về tội phạm, kiến nghị khởi tố tạm đình chỉ giải quyết tính đến cuối kỳ thống kê | B11: 6 | C11: 356
A12: Số tố giác, tin báo về tội phạm, kiến nghị khởi tố cuối kỳ chưa giải quyết xong | B12: 7 | C12: 17
A13: Trong đó: Số tố giác, tin báo về tội phạm, kiến nghị khởi tố đã quá hạn | B13: 8 | C13: 0
A14: Số quyết định VKS hủy bỏ các lệnh, quyết định không có căn cứ và trái pháp luật của CQĐT, cơ quan được giao nhiệm vụ tiến hành một số hoạt động điều tra | B14: 9 | C14: 0
A15: Số bản kiến nghị của VKS ban hành kiến nghị CQĐT, cơ quan được giao nhiệm vụ tiến hành một số hoạt động điều tra được chấp nhận | B15: 10 | C15: 0
A16: II. KHỞI TỐ, ĐIỀU TRA VÀ KIỂM SÁT ĐIỀU TRA CÁC VỤ ÁN HÌNH SỰ
A17: Số vụ án mới khởi tố | B17: 11 | C17: 6
A18: Số bị can mới khởi tố | B18: 12 | C18: 0
A19: Tổng số vụ án thụ lý điều tra | B19: 13 | C19: 202
A20: Tổng số bị can thụ lý điều tra | B20: 14 | C20: 60
A21: Số vụ án đề nghị truy tố | B21: 15 | C21: 2
A22: Số bị can đề nghị truy tố | B22: 16 | C22: 3
A23: Số vụ án CQĐT đình chỉ điều tra | B23: 17 | C23: 0
A24: Số bị can CQĐT đình chỉ điều tra | B24: 18 | C24: 0
A25: Trong đó: - Số bị can đình chỉ điều tra do không có sự việc phạm tội (theo K1 Đ157 BLTTHS) - (không tính trường hợp đình chỉ do bị can bị tâm thần). | B25: 19 | C25: 0
A26: - Số bị can đình chỉ điều tra do hành vi không cấu thành tội phạm (theo K2 Đ157 BLTTHS) - (không tính trường hợp đình chỉ do bị can bị tâm thần). | B26: 20 | C26: 0
A27: - Số bị can đình chỉ vì hết thời hạn điều tra mà không chứng minh được bị can đã thực hiện tội phạm (theo điểm b K1 Đ230 BLTTHS) | B27: 21 | C27: 0
A28: - Số bị can đình chỉ do được miễn trách nhiệm hình sự theo K1 Đ29 BLHS | B28: 22 | C28: 0
... A37: Số bản kiến nghị của VKS ban hành kiến nghị CQĐT, cơ quan được giao nhiệm vụ tiến hành một số hoạt động điều tra được chấp nhận | B37: 31 | C37: 0
A38: III. QUYẾT ĐỊNH VIỆC TRUY TỐ
A39: Số vụ án mới thụ lý | B39: 32
A40: Số bị can mới thụ lý | B40: 33
A41: Tổng số vụ án VKS thụ lý giải quyết | B41: 34
A42: Tổng số bị can VKS thụ lý giải quyết | B42: 35
A43: Số vụ án truy tố | B43: 36
A44: Số bị can truy tố | B44: 37
A45: Số vụ án VKS quyết định không truy tố và ra quyết định đình chỉ | B45: 38
A46: Trong đó: Số vụ án Toà án trả hồ sơ cho VKS để điều tra bổ sung nhưng sau đó đình chỉ | B46: 39
A47: Số bị can VKS quyết định không truy tố và ra quyết định đình chỉ vụ án đối với bị can | B47: 40
A48: Trong đó: - Số bị can đình chỉ điều tra do không có sự việc phạm tội (theo K1 Đ157 BLTTHS) | B48: 41
A49: - Số bị can đình chỉ điều tra do hành vi không cấu thành tội phạm (theo K2 Đ157 BLTTHS) | B49: 42
...

Sheet Tổ 2
A1: THỐNG KÊ HÌNH SỰ LIÊN NGÀNH Kỳ thống kê tháng …. năm 2026
A3: Tiêu chí | B3: Mã | C3: Số
B4: dòng | C4: liệu
A5: I. TIẾP NHẬN, GIẢI QUYẾT TỐ GIÁC, TIN BÁO VỀ TỘI PHẠM VÀ KIẾN NGHỊ KHỞI TỐ
A6: Số tố giác, tin báo về tội phạm, kiến nghị khởi tố mới nhận | B6: 1 | C6: 64
A7: Tổng số tố giác, tin báo về tội phạm, kiến nghị khởi tố phải giải quyết | B7: 2 | C7: 39
A8: Số tố giác, tin báo về tội phạm, kiến nghị khởi tố đã quyết định khởi tố vụ án hình sự | B8: 3 | C8: 29
A9: Số tố giác, tin báo về tội phạm, kiến nghị khởi tố quyết định không khởi tố vụ án hình sự | B9: 4 | C9: 5
A10: Số tố giác, tin báo về tội phạm, kiến nghị khởi tố tạm đình chỉ việc giải quyết trong kỳ thống kê | B10: 5 | C10: 5
A11: Tổng số tố giác, tin báo về tội phạm, kiến nghị khởi tố tạm đình chỉ giải quyết tính đến cuối kỳ thống kê | B11: 6 | C11: 638
A12: Số tố giác, tin báo về tội phạm, kiến nghị khởi tố cuối kỳ chưa giải quyết xong | B12: 7 | C12: 25
A13: Trong đó: Số tố giác, tin báo về tội phạm, kiến nghị khởi tố đã quá hạn | B13: 8
A14: Số quyết định VKS hủy bỏ các lệnh, quyết định không có căn cứ và trái pháp luật của CQĐT, cơ quan được giao nhiệm vụ tiến hành một số hoạt động điều tra | B14: 9
A15: Số bản kiến nghị của VKS ban hành kiến nghị CQĐT, cơ quan được giao nhiệm vụ tiến hành một số hoạt động điều tra được chấp nhận | B15: 10
A16: II. KHỞI TỐ, ĐIỀU TRA VÀ KIỂM SÁT ĐIỀU TRA CÁC VỤ ÁN HÌNH SỰ
A17: Số vụ án mới khởi tố | B17: 11 | C17: 29
A18: Số bị can mới khởi tố | B18: 12 | C18: 29
A19: Tổng số vụ án thụ lý điều tra | B19: 13
A20: Tổng số bị can thụ lý điều tra | B20: 14
A21: Số vụ án đề nghị truy tố | B21: 15 | C21: 30
A22: Số bị can đề nghị truy tố | B22: 16 | C22: 69
A23: Số vụ án CQĐT đình chỉ điều tra | B23: 17 | C23: 2
A24: Số bị can CQĐT đình chỉ điều tra | B24: 18 | C24: 5
A25: Trong đó: - Số bị can đình chỉ điều tra do không có sự việc phạm tội (theo K1 Đ157 BLTTHS) - (không tính trường hợp đình chỉ do bị can bị tâm thần). | B25: 19
A26: - Số bị can đình chỉ điều tra do hành vi không cấu thành tội phạm (theo K2 Đ157 BLTTHS) - (không tính trường hợp đình chỉ do bị can bị tâm thần). | B26: 20
A27: - Số bị can đình chỉ vì hết thời hạn điều tra mà không chứng minh được bị can đã thực hiện tội phạm (theo điểm b K1 Đ230 BLTTHS) | B27: 21
A28: - Số bị can đình chỉ do được miễn trách nhiệm hình sự theo K1 Đ29 BLHS | B28: 22
A29: - Số bị can đình chỉ do được miễn trách nhiệm hình sự theo K2 Đ29 BLHS | B29: 23
A30: - Số bị can đình chỉ điều tra do được miễn trách nhiệm hình sự theo K3 Đ29 BLHS | B30: 24
A31: Tổng số vụ án CQĐT ra quyết định tạm đình chỉ điều tra còn lại tính đến cuối kỳ thống kê | B31: 25 | C31: 1306
A32: Tổng số bị can CQĐT ra quyết định tạm đình chỉ điều tra còn lại tính đến cuối kỳ thống kê | B32: 26 | C32: 45
A33: Số vụ án còn lại chưa kết thúc điều tra | B33: 27 | C33: 124
A34: Trong đó:Số vụ án chưa kết thúc điều tra đã quá thời hạn luật định | B34: 28
A35: Số bị can còn lại chưa kết thúc điều tra | B35: 29 | C35: 228
A36: Số quyết định VKS hủy bỏ các lệnh, quyết định không có căn cứ và trái pháp luật của CQĐT, cơ quan được giao nhiệm vụ tiến hành một số hoạt động điều tra | B36: 30
A37: Số bản kiến nghị của VKS ban hành kiến nghị CQĐT, cơ quan được giao nhiệm vụ tiến hành một số hoạt động điều tra được chấp nhận | B37: 31
A38: III. QUYẾT ĐỊNH VIỆC TRUY TỐ
A39: Số vụ án mới thụ lý | B39: 32
A40: Số bị can mới thụ lý | B40: 33
A41: Tổng số vụ án VKS thụ lý giải quyết | B41: 34
...

Sheet Tổ 3
A1: THỐNG KÊ HÌNH SỰ LIÊN NGÀNH Kỳ thống kê tháng …. năm 2026
A3: Tiêu chí | B3: Mã | C3: Số
B4: dòng | C4: liệu
A5: I. TIẾP NHẬN, GIẢI QUYẾT TỐ GIÁC, TIN BÁO VỀ TỘI PHẠM VÀ KIẾN NGHỊ KHỞI TỐ
A6: Số tố giác, tin báo về tội phạm, kiến nghị khởi tố mới nhận | B6: 1 | C6: 7
A7: Tổng số tố giác, tin báo về tội phạm, kiến nghị khởi tố phải giải quyết | B7: 2 | C7: 19
A8: Số tố giác, tin báo về tội phạm, kiến nghị khởi tố đã quyết định khởi tố vụ án hình sự | B8: 3 | C8: 7
A9: Số tố giác, tin báo về tội phạm, kiến nghị khởi tố quyết định không khởi tố vụ án hình sự | B9: 4
A10: Số tố giác, tin báo về tội phạm, kiến nghị khởi tố tạm đình chỉ việc giải quyết trong kỳ thống kê | B10: 5
A11: Tổng số tố giác, tin báo về tội phạm, kiến nghị khởi tố tạm đình chỉ giải quyết tính đến cuối kỳ thống kê | B11: 6 | C11: 241
A12: Số tố giác, tin báo về tội phạm, kiến nghị khởi tố cuối kỳ chưa giải quyết xong | B12: 7 | C12: 12
A13: Trong đó: Số tố giác, tin báo về tội phạm, kiến nghị khởi tố đã quá hạn | B13: 8
A14: Số quyết định VKS hủy bỏ các lệnh, quyết định không có căn cứ và trái pháp luật của CQĐT, cơ quan được giao nhiệm vụ tiến hành một số hoạt động điều tra | B14: 9
A15: Số bản kiến nghị của VKS ban hành kiến nghị CQĐT, cơ quan được giao nhiệm vụ tiến hành một số hoạt động điều tra được chấp nhận | B15: 10
A16: II. KHỞI TỐ, ĐIỀU TRA VÀ KIỂM SÁT ĐIỀU TRA CÁC VỤ ÁN HÌNH SỰ
A17: Số vụ án mới khởi tố | B17: 11 | C17: 7
A18: Số bị can mới khởi tố | B18: 12 | C18: 1
A19: Tổng số vụ án thụ lý điều tra | B19: 13 | C19: 87
A20: Tổng số bị can thụ lý điều tra | B20: 14 | C20: 99
A21: Số vụ án đề nghị truy tố | B21: 15 | C21: 5
A22: Số bị can đề nghị truy tố | B22: 16 | C22: 8
A23: Số vụ án CQĐT đình chỉ điều tra | B23: 17
A24: Số bị can CQĐT đình chỉ điều tra | B24: 18
A25: Trong đó: - Số bị can đình chỉ điều tra do không có sự việc phạm tội (theo K1 Đ157 BLTTHS) - (không tính trường hợp đình chỉ do bị can bị tâm thần). | B25: 19
A26: - Số bị can đình chỉ điều tra do hành vi không cấu thành tội phạm (theo K2 Đ157 BLTTHS) - (không tính trường hợp đình chỉ do bị can bị tâm thần). | B26: 20
A27: - Số bị can đình chỉ vì hết thời hạn điều tra mà không chứng minh được bị can đã thực hiện tội phạm (theo điểm b K1 Đ230 BLTTHS) | B27: 21
A28: - Số bị can đình chỉ do được miễn trách nhiệm hình sự theo K1 Đ29 BLHS | B28: 22
A29: - Số bị can đình chỉ do được miễn trách nhiệm hình sự theo K2 Đ29 BLHS | B29: 23
A30: - Số bị can đình chỉ điều tra do được miễn trách nhiệm hình sự theo K3 Đ29 BLHS | B30: 24
A31: Tổng số vụ án CQĐT ra quyết định tạm đình chỉ điều tra còn lại tính đến cuối kỳ thống kê | B31: 25 | C31: 1114
A32: Tổng số bị can CQĐT ra quyết định tạm đình chỉ điều tra còn lại tính đến cuối kỳ thống kê | B32: 26 | C32: 63
A33: Số vụ án còn lại chưa kết thúc điều tra | B33: 27 | C33: 82
A34: Trong đó:Số vụ án chưa kết thúc điều tra đã quá thời hạn luật định | B34: 28
A35: Số bị can còn lại chưa kết thúc điều tra | B35: 29 | C35: 92
A36: Số quyết định VKS hủy bỏ các lệnh, quyết định không có căn cứ và trái pháp luật của CQĐT, cơ quan được giao nhiệm vụ tiến hành một số hoạt động điều tra | B36: 30
A37: Số bản kiến nghị của VKS ban hành kiến nghị CQĐT, cơ quan được giao nhiệm vụ tiến hành một số hoạt động điều tra được chấp nhận | B37: 31
A38: III. QUYẾT ĐỊNH VIỆC TRUY TỐ
A39: Số vụ án mới thụ lý | B39: 32
A40: Số bị can mới thụ lý | B40: 33
A41: Tổng số vụ án VKS thụ lý giải quyết | B41: 34
...

Sheet Tổ 4
A1: THỐNG KÊ HÌNH SỰ LIÊN NGÀNH Kỳ thống kê tháng …. năm 2026
A3: Tiêu chí | B3: Mã | C3: Số
B4: dòng | C4: liệu
A5: I. TIẾP NHẬN, GIẢI QUYẾT TỐ GIÁC, TIN BÁO VỀ TỘI PHẠM VÀ KIẾN NGHỊ KHỞI TỐ
A6: Số tố giác, tin báo về tội phạm, kiến nghị khởi tố mới nhận | B6: 1 | C6: 13
A7: Tổng số tố giác, tin báo về tội phạm, kiến nghị khởi tố phải giải quyết | B7: 2 | C7: 13
A8: Số tố giác, tin báo về tội phạm, kiến nghị khởi tố đã quyết định khởi tố vụ án hình sự | B8: 3 | C8: 2
A9: Số tố giác, tin báo về tội phạm, kiến nghị khởi tố quyết định không khởi tố vụ án hình sự | B9: 4 | C9: 1
A10: Số tố giác, tin báo về tội phạm, kiến nghị khởi tố tạm đình chỉ việc giải quyết trong kỳ thống kê | B10: 5 | C10: 0
A11: Tổng số tố giác, tin báo về tội phạm, kiến nghị khởi tố tạm đình chỉ giải quyết tính đến cuối kỳ thống kê | B11: 6 | C11: 315
A12: Số tố giác, tin báo về tội phạm, kiến nghị khởi tố cuối kỳ chưa giải quyết xong | B12: 7 | C12: 24
A13: Trong đó: Số tố giác, tin báo về tội phạm, kiến nghị khởi tố đã quá hạn | B13: 8 | C13: 0
A14: Số quyết định VKS hủy bỏ các lệnh, quyết định không có căn cứ và trái pháp luật của CQĐT, cơ quan được giao nhiệm vụ tiến hành một số hoạt động điều tra | B14: 9 | C14: 0
A15: Số bản kiến nghị của VKS ban hành kiến nghị CQĐT, cơ quan được giao nhiệm vụ tiến hành một số hoạt động điều tra được chấp nhận | B15: 10 | C15: 0
A16: II. KHỞI TỐ, ĐIỀU TRA VÀ KIỂM SÁT ĐIỀU TRA CÁC VỤ ÁN HÌNH SỰ
A17: Số vụ án mới khởi tố | B17: 11 | C17: 7
A18: Số bị can mới khởi tố | B18: 12 | C18: 3
A19: Tổng số vụ án thụ lý điều tra | B19: 13 | C19: 116
A20: Tổng số bị can thụ lý điều tra | B20: 14 | C20: 93
A21: Số vụ án đề nghị truy tố | B21: 15 | C21: 21
A22: Số bị can đề nghị truy tố | B22: 16 | C22: 62
A23: Số vụ án CQĐT đình chỉ điều tra | B23: 17 | C23: 493
A24: Số bị can CQĐT đình chỉ điều tra | B24: 18 | C24: 0
A25: Trong đó: - Số bị can đình chỉ điều tra do không có sự việc phạm tội (theo K1 Đ157 BLTTHS) - (không tính trường hợp đình chỉ do bị can bị tâm thần). | B25: 19 | C25: 0
A26: - Số bị can đình chỉ điều tra do hành vi không cấu thành tội phạm (theo K2 Đ157 BLTTHS) - (không tính trường hợp đình chỉ do bị can bị tâm thần). | B26: 20 | C26: 0
A27: - Số bị can đình chỉ vì hết thời hạn điều tra mà không chứng minh được bị can đã thực hiện tội phạm (theo điểm b K1 Đ230 BLTTHS) | B27: 21 | C27: 0
A28: - Số bị can đình chỉ do được miễn trách nhiệm hình sự theo K1 Đ29 BLHS | B28: 22 | C28: 0
... A37: Số bản kiến nghị của VKS ban hành kiến nghị CQĐT, cơ quan được giao nhiệm vụ tiến hành một số hoạt động điều tra được chấp nhận | B37: 31 | C37: 0
A38: III. QUYẾT ĐỊNH VIỆC TRUY TỐ
A39: Số vụ án mới thụ lý | B39: 32
A40: Số bị can mới thụ lý | B40: 33
A41: Tổng số vụ án VKS thụ lý giải quyết | B41: 34
A42: Tổng số bị can VKS thụ lý giải quyết | B42: 35
A43: Số vụ án truy tố | B43: 36
A44: Số bị can truy tố | B44: 37
A45: Số vụ án VKS quyết định không truy tố và ra quyết định đình chỉ | B45: 38
A46: Trong đó: Số vụ án Toà án trả hồ sơ cho VKS để điều tra bổ sung nhưng sau đó đình chỉ | B46: 39
A47: Số bị can VKS quyết định không truy tố và ra quyết định đình chỉ vụ án đối với bị can | B47: 40
A48: Trong đó: - Số bị can đình chỉ điều tra do không có sự việc phạm tội (theo K1 Đ157 BLTTHS) | B48: 41
A49: - Số bị can đình chỉ điều tra do hành vi không cấu thành tội phạm (theo K2 Đ157 BLTTHS) | B49: 42
...

Sheet Tổ 5
A1: THỐNG KÊ HÌNH SỰ LIÊN NGÀNH Kỳ thống kê tháng …. năm 2026
A3: Tiêu chí | B3: Mã | C3: Số
B4: dòng | C4: liệu
A5: I. TIẾP NHẬN, GIẢI QUYẾT TỐ GIÁC, TIN BÁO VỀ TỘI PHẠM VÀ KIẾN NGHỊ KHỞI TỐ
A6: Số tố giác, tin báo về tội phạm, kiến nghị khởi tố mới nhận | B6: 1 | C6: 7
A7: Tổng số tố giác, tin báo về tội phạm, kiến nghị khởi tố phải giải quyết | B7: 2 | C7: 26
A8: Số tố giác, tin báo về tội phạm, kiến nghị khởi tố đã quyết định khởi tố vụ án hình sự | B8: 3 | C8: 10
A9: Số tố giác, tin báo về tội phạm, kiến nghị khởi tố quyết định không khởi tố vụ án hình sự | B9: 4 | C9: 1
A10: Số tố giác, tin báo về tội phạm, kiến nghị khởi tố tạm đình chỉ việc giải quyết trong kỳ thống kê | B10: 5 | C10: 4
A11: Tổng số tố giác, tin báo về tội phạm, kiến nghị khởi tố tạm đình chỉ giải quyết tính đến cuối kỳ thống kê | B11: 6 | C11: 66
A12: Số tố giác, tin báo về tội phạm, kiến nghị khởi tố cuối kỳ chưa giải quyết xong | B12: 7 | C12: 11
A13: Trong đó: Số tố giác, tin báo về tội phạm, kiến nghị khởi tố đã quá hạn | B13: 8 | C13: 0
A14: Số quyết định VKS hủy bỏ các lệnh, quyết định không có căn cứ và trái pháp luật của CQĐT, cơ quan được giao nhiệm vụ tiến hành một số hoạt động điều tra | B14: 9 | C14: 0
A15: Số bản kiến nghị của VKS ban hành kiến nghị CQĐT, cơ quan được giao nhiệm vụ tiến hành một số hoạt động điều tra được chấp nhận | B15: 10 | C15: 0
A16: II. KHỞI TỐ, ĐIỀU TRA VÀ KIỂM SÁT ĐIỀU TRA CÁC VỤ ÁN HÌNH SỰ
A17: Số vụ án mới khởi tố | B17: 11 | C17: 4
A18: Số bị can mới khởi tố | B18: 12 | C18: 7
A19: Tổng số vụ án thụ lý điều tra | B19: 13 | C19: 88
A20: Tổng số bị can thụ lý điều tra | B20: 14 | C20: 159
A21: Số vụ án đề nghị truy tố | B21: 15 | C21: 6
A22: Số bị can đề nghị truy tố | B22: 16 | C22: 9
A23: Số vụ án CQĐT đình chỉ điều tra | B23: 17 | C23: 0
A24: Số bị can CQĐT đình chỉ điều tra | B24: 18 | C24: 0
A25: Trong đó: - Số bị can đình chỉ điều tra do không có sự việc phạm tội (theo K1 Đ157 BLTTHS) - (không tính trường hợp đình chỉ do bị can bị tâm thần). | B25: 19 | C25: 0
A26: - Số bị can đình chỉ điều tra do hành vi không cấu thành tội phạm (theo K2 Đ157 BLTTHS) - (không tính trường hợp đình chỉ do bị can bị tâm thần). | B26: 20 | C26: 0
A27: - Số bị can đình chỉ vì hết thời hạn điều tra mà không chứng minh được bị can đã thực hiện tội phạm (theo điểm b K1 Đ230 BLTTHS) | B27: 21 | C27: 0
A28: - Số bị can đình chỉ do được miễn trách nhiệm hình sự theo K1 Đ29 BLHS | B28: 22 | C28: 0
... A37: Số bản kiến nghị của VKS ban hành kiến nghị CQĐT, cơ quan được giao nhiệm vụ tiến hành một số hoạt động điều tra được chấp nhận | B37: 31 | C37: 0
A38: III. QUYẾT ĐỊNH VIỆC TRUY TỐ
A39: Số vụ án mới thụ lý | B39: 32
A40: Số bị can mới thụ lý | B40: 33
A41: Tổng số vụ án VKS thụ lý giải quyết | B41: 34
A42: Tổng số bị can VKS thụ lý giải quyết | B42: 35
A43: Số vụ án truy tố | B43: 36
A44: Số bị can truy tố | B44: 37
A45: Số vụ án VKS quyết định không truy tố và ra quyết định đình chỉ | B45: 38
A46: Trong đó: Số vụ án Toà án trả hồ sơ cho VKS để điều tra bổ sung nhưng sau đó đình chỉ | B46: 39
A47: Số bị can VKS quyết định không truy tố và ra quyết định đình chỉ vụ án đối với bị can | B47: 40
A48: Trong đó: - Số bị can đình chỉ điều tra do không có sự việc phạm tội (theo K1 Đ157 BLTTHS) | B48: 41
A49: - Số bị can đình chỉ điều tra do hành vi không cấu thành tội phạm (theo K2 Đ157 BLTTHS) | B49: 42
...

Sheet Tổ 6
A1: THỐNG KÊ HÌNH SỰ LIÊN NGÀNH Kỳ thống kê tháng …. năm 2026
A3: Tiêu chí | B3: Mã | C3: Số
B4: dòng | C4: liệu
A5: I. TIẾP NHẬN, GIẢI QUYẾT TỐ GIÁC, TIN BÁO VỀ TỘI PHẠM VÀ KIẾN NGHỊ KHỞI TỐ
A6: Số tố giác, tin báo về tội phạm, kiến nghị khởi tố mới nhận | B6: 1 | C6: 9
A7: Tổng số tố giác, tin báo về tội phạm, kiến nghị khởi tố phải giải quyết | B7: 2 | C7: 23
A8: Số tố giác, tin báo về tội phạm, kiến nghị khởi tố đã quyết định khởi tố vụ án hình sự | B8: 3 | C8: 1
A9: Số tố giác, tin báo về tội phạm, kiến nghị khởi tố quyết định không khởi tố vụ án hình sự | B9: 4 | C9: 0
A10: Số tố giác, tin báo về tội phạm, kiến nghị khởi tố tạm đình chỉ việc giải quyết trong kỳ thống kê | B10: 5 | C10: 2
A11: Tổng số tố giác, tin báo về tội phạm, kiến nghị khởi tố tạm đình chỉ giải quyết tính đến cuối kỳ thống kê | B11: 6 | C11: 97
A12: Số tố giác, tin báo về tội phạm, kiến nghị khởi tố cuối kỳ chưa giải quyết xong | B12: 7 | C12: 20
A13: Trong đó: Số tố giác, tin báo về tội phạm, kiến nghị khởi tố đã quá hạn | B13: 8 | C13: 0
A14: Số quyết định VKS hủy bỏ các lệnh, quyết định không có căn cứ và trái pháp luật của CQĐT, cơ quan được giao nhiệm vụ tiến hành một số hoạt động điều tra | B14: 9 | C14: 0
A15: Số bản kiến nghị của VKS ban hành kiến nghị CQĐT, cơ quan được giao nhiệm vụ tiến hành một số hoạt động điều tra được chấp nhận | B15: 10 | C15: 0
A16: II. KHỞI TỐ, ĐIỀU TRA VÀ KIỂM SÁT ĐIỀU TRA CÁC VỤ ÁN HÌNH SỰ
A17: Số vụ án mới khởi tố | B17: 11 | C17: 6
A18: Số bị can mới khởi tố | B18: 12 | C18: 23
A19: Tổng số vụ án thụ lý điều tra | B19: 13 | C19: 92
A20: Tổng số bị can thụ lý điều tra | B20: 14 | C20: 126
A21: Số vụ án đề nghị truy tố | B21: 15 | C21: 1
A22: Số bị can đề nghị truy tố | B22: 16 | C22: 3
A23: Số vụ án CQĐT đình chỉ điều tra | B23: 17 | C23: 0
A24: Số bị can CQĐT đình chỉ điều tra | B24: 18 | C24: 0
A25: Trong đó: - Số bị can đình chỉ điều tra do không có sự việc phạm tội (theo K1 Đ157 BLTTHS) - (không tính trường hợp đình chỉ do bị can bị tâm thần). | B25: 19 | C25: 0
A26: - Số bị can đình chỉ điều tra do hành vi không cấu thành tội phạm (theo K2 Đ157 BLTTHS) - (không tính trường hợp đình chỉ do bị can bị tâm thần). | B26: 20 | C26: 0
A27: - Số bị can đình chỉ vì hết thời hạn điều tra mà không chứng minh được bị can đã thực hiện tội phạm (theo điểm b K1 Đ230 BLTTHS) | B27: 21 | C27: 0
A28: - Số bị can đình chỉ do được miễn trách nhiệm hình sự theo K1 Đ29 BLHS | B28: 22 | C28: 0
... A37: Số bản kiến nghị của VKS ban hành kiến nghị CQĐT, cơ quan được giao nhiệm vụ tiến hành một số hoạt động điều tra được chấp nhận | B37: 31 | C37: 0
A38: III. QUYẾT ĐỊNH VIỆC TRUY TỐ
A39: Số vụ án mới thụ lý | B39: 32
A40: Số bị can mới thụ lý | B40: 33
A41: Tổng số vụ án VKS thụ lý giải quyết | B41: 34
A42: Tổng số bị can VKS thụ lý giải quyết | B42: 35
A43: Số vụ án truy tố | B43: 36
A44: Số bị can truy tố | B44: 37
A45: Số vụ án VKS quyết định không truy tố và ra quyết định đình chỉ | B45: 38
A46: Trong đó: Số vụ án Toà án trả hồ sơ cho VKS để điều tra bổ sung nhưng sau đó đình chỉ | B46: 39
A47: Số bị can VKS quyết định không truy tố và ra quyết định đình chỉ vụ án đối với bị can | B47: 40
A48: Trong đó: - Số bị can đình chỉ điều tra do không có sự việc phạm tội (theo K1 Đ157 BLTTHS) | B48: 41
A49: - Số bị can đình chỉ điều tra do hành vi không cấu thành tội phạm (theo K2 Đ157 BLTTHS) | B49: 42
...

Sheet Tổ 7
A1: THỐNG KÊ HÌNH SỰ LIÊN NGÀNH Kỳ thống kê tháng …. năm 2026
A3: Tiêu chí | B3: Mã | C3: Số
B4: dòng | C4: liệu
A5: I. TIẾP NHẬN, GIẢI QUYẾT TỐ GIÁC, TIN BÁO VỀ TỘI PHẠM VÀ KIẾN NGHỊ KHỞI TỐ
A6: Số tố giác, tin báo về tội phạm, kiến nghị khởi tố mới nhận | B6: 1 | C6: 14
A7: Tổng số tố giác, tin báo về tội phạm, kiến nghị khởi tố phải giải quyết | B7: 2 | C7: 60
A8: Số tố giác, tin báo về tội phạm, kiến nghị khởi tố đã quyết định khởi tố vụ án hình sự | B8: 3 | C8: 22
A9: Số tố giác, tin báo về tội phạm, kiến nghị khởi tố quyết định không khởi tố vụ án hình sự | B9: 4 | C9: 3
A10: Số tố giác, tin báo về tội phạm, kiến nghị khởi tố tạm đình chỉ việc giải quyết trong kỳ thống kê | B10: 5 | C10: 2
A11: Tổng số tố giác, tin báo về tội phạm, kiến nghị khởi tố tạm đình chỉ giải quyết tính đến cuối kỳ thống kê | B11: 6 | C11: 27
A12: Số tố giác, tin báo về tội phạm, kiến nghị khởi tố cuối kỳ chưa giải quyết xong | B12: 7 | C12: 33
A13: Trong đó: Số tố giác, tin báo về tội phạm, kiến nghị khởi tố đã quá hạn | B13: 8 | C13: 0
A14: Số quyết định VKS hủy bỏ các lệnh, quyết định không có căn cứ và trái pháp luật của CQĐT, cơ quan được giao nhiệm vụ tiến hành một số hoạt động điều tra | B14: 9 | C14: 0
A15: Số bản kiến nghị của VKS ban hành kiến nghị CQĐT, cơ quan được giao nhiệm vụ tiến hành một số hoạt động điều tra được chấp nhận | B15: 10 | C15: 0
A16: II. KHỞI TỐ, ĐIỀU TRA VÀ KIỂM SÁT ĐIỀU TRA CÁC VỤ ÁN HÌNH SỰ
A17: Số vụ án mới khởi tố | B17: 11 | C17: 20
A18: Số bị can mới khởi tố | B18: 12 | C18: 4
A19: Tổng số vụ án thụ lý điều tra | B19: 13 | C19: 244
A20: Tổng số bị can thụ lý điều tra | B20: 14 | C20: 61
A21: Số vụ án đề nghị truy tố | B21: 15 | C21: 4
A22: Số bị can đề nghị truy tố | B22: 16 | C22: 4
A23: Số vụ án CQĐT đình chỉ điều tra | B23: 17
A24: Số bị can CQĐT đình chỉ điều tra | B24: 18
A25: Trong đó: - Số bị can đình chỉ điều tra do không có sự việc phạm tội (theo K1 Đ157 BLTTHS) - (không tính trường hợp đình chỉ do bị can bị tâm thần). | B25: 19
A26: - Số bị can đình chỉ điều tra do hành vi không cấu thành tội phạm (theo K2 Đ157 BLTTHS) - (không tính trường hợp đình chỉ do bị can bị tâm thần). | B26: 20
A27: - Số bị can đình chỉ vì hết thời hạn điều tra mà không chứng minh được bị can đã thực hiện tội phạm (theo điểm b K1 Đ230 BLTTHS) | B27: 21
A28: - Số bị can đình chỉ do được miễn trách nhiệm hình sự theo K1 Đ29 BLHS | B28: 22
A29: - Số bị can đình chỉ do được miễn trách nhiệm hình sự theo K2 Đ29 BLHS | B29: 23
A30: - Số bị can đình chỉ điều tra do được miễn trách nhiệm hình sự theo K3 Đ29 BLHS | B30: 24
A31: Tổng số vụ án CQĐT ra quyết định tạm đình chỉ điều tra còn lại tính đến cuối kỳ thống kê | B31: 25 | C31: 1042
A32: Tổng số bị can CQĐT ra quyết định tạm đình chỉ điều tra còn lại tính đến cuối kỳ thống kê | B32: 26 | C32: 15
A33: Số vụ án còn lại chưa kết thúc điều tra | B33: 27 | C33: 215
A34: Trong đó:Số vụ án chưa kết thúc điều tra đã quá thời hạn luật định | B34: 28 | C34: 0
A35: Số bị can còn lại chưa kết thúc điều tra | B35: 29 | C35: 57
A36: Số quyết định VKS hủy bỏ các lệnh, quyết định không có căn cứ và trái pháp luật của CQĐT, cơ quan được giao nhiệm vụ tiến hành một số hoạt động điều tra | B36: 30 | C36: 0
A37: Số bản kiến nghị của VKS ban hành kiến nghị CQĐT, cơ quan được giao nhiệm vụ tiến hành một số hoạt động điều tra được chấp nhận | B37: 31 | C37: 0
A38: III. QUYẾT ĐỊNH VIỆC TRUY TỐ
A39: Số vụ án mới thụ lý | B39: 32
A40: Số bị can mới thụ lý | B40: 33
A41: Tổng số vụ án VKS thụ lý giải quyết | B41: 34
...

Sheet Tổ 8
A1: THỐNG KÊ HÌNH SỰ LIÊN NGÀNH Kỳ thống kê tháng …. năm 2026
A3: Tiêu chí | B3: Mã | C3: Số
B4: dòng | C4: liệu
A5: I. TIẾP NHẬN, GIẢI QUYẾT TỐ GIÁC, TIN BÁO VỀ TỘI PHẠM VÀ KIẾN NGHỊ KHỞI TỐ
A6: Số tố giác, tin báo về tội phạm, kiến nghị khởi tố mới nhận | B6: 1 | C6: 6
A7: Tổng số tố giác, tin báo về tội phạm, kiến nghị khởi tố phải giải quyết | B7: 2 | C7: 6
A8: Số tố giác, tin báo về tội phạm, kiến nghị khởi tố đã quyết định khởi tố vụ án hình sự | B8: 3 | C8: 6
A9: Số tố giác, tin báo về tội phạm, kiến nghị khởi tố quyết định không khởi tố vụ án hình sự | B9: 4 | C9: 0
A10: Số tố giác, tin báo về tội phạm, kiến nghị khởi tố tạm đình chỉ việc giải quyết trong kỳ thống kê | B10: 5 | C10: 0
A11: Tổng số tố giác, tin báo về tội phạm, kiến nghị khởi tố tạm đình chỉ giải quyết tính đến cuối kỳ thống kê | B11: 6 | C11: 0
A12: Số tố giác, tin báo về tội phạm, kiến nghị khởi tố cuối kỳ chưa giải quyết xong | B12: 7 | C12: 4
A13: Trong đó: Số tố giác, tin báo về tội phạm, kiến nghị khởi tố đã quá hạn | B13: 8 | C13: 0
A14: Số quyết định VKS hủy bỏ các lệnh, quyết định không có căn cứ và trái pháp luật của CQĐT, cơ quan được giao nhiệm vụ tiến hành một số hoạt động điều tra | B14: 9 | C14: 0
A15: Số bản kiến nghị của VKS ban hành kiến nghị CQĐT, cơ quan được giao nhiệm vụ tiến hành một số hoạt động điều tra được chấp nhận | B15: 10 | C15: 0
A16: II. KHỞI TỐ, ĐIỀU TRA VÀ KIỂM SÁT ĐIỀU TRA CÁC VỤ ÁN HÌNH SỰ
A17: Số vụ án mới khởi tố | B17: 11 | C17: 6
A18: Số bị can mới khởi tố | B18: 12 | C18: 4
A19: Tổng số vụ án thụ lý điều tra | B19: 13 | C19: 78
A20: Tổng số bị can thụ lý điều tra | B20: 14 | C20: 95
A21: Số vụ án đề nghị truy tố | B21: 15 | C21: 3
A22: Số bị can đề nghị truy tố | B22: 16 | C22: 14
A23: Số vụ án CQĐT đình chỉ điều tra | B23: 17 | C23: 0
A24: Số bị can CQĐT đình chỉ điều tra | B24: 18 | C24: 0
A25: Trong đó: - Số bị can đình chỉ điều tra do không có sự việc phạm tội (theo K1 Đ157 BLTTHS) - (không tính trường hợp đình chỉ do bị can bị tâm thần). | B25: 19 | C25: 0
A26: - Số bị can đình chỉ điều tra do hành vi không cấu thành tội phạm (theo K2 Đ157 BLTTHS) - (không tính trường hợp đình chỉ do bị can bị tâm thần). | B26: 20 | C26: 0
A27: - Số bị can đình chỉ vì hết thời hạn điều tra mà không chứng minh được bị can đã thực hiện tội phạm (theo điểm b K1 Đ230 BLTTHS) | B27: 21 | C27: 0
A28: - Số bị can đình chỉ do được miễn trách nhiệm hình sự theo K1 Đ29 BLHS | B28: 22 | C28: 0
... A37: Số bản kiến nghị của VKS ban hành kiến nghị CQĐT, cơ quan được giao nhiệm vụ tiến hành một số hoạt động điều tra được chấp nhận | B37: 31 | C37: 0
A38: III. QUYẾT ĐỊNH VIỆC TRUY TỐ
A39: Số vụ án mới thụ lý | B39: 32
A40: Số bị can mới thụ lý | B40: 33
A41: Tổng số vụ án VKS thụ lý giải quyết | B41: 34
A42: Tổng số bị can VKS thụ lý giải quyết | B42: 35
A43: Số vụ án truy tố | B43: 36
A44: Số bị can truy tố | B44: 37
A45: Số vụ án VKS quyết định không truy tố và ra quyết định đình chỉ | B45: 38
A46: Trong đó: Số vụ án Toà án trả hồ sơ cho VKS để điều tra bổ sung nhưng sau đó đình chỉ | B46: 39
A47: Số bị can VKS quyết định không truy tố và ra quyết định đình chỉ vụ án đối với bị can | B47: 40
A48: Trong đó: - Số bị can đình chỉ điều tra do không có sự việc phạm tội (theo K1 Đ157 BLTTHS) | B48: 41
A49: - Số bị can đình chỉ điều tra do hành vi không cấu thành tội phạm (theo K2 Đ157 BLTTHS) | B49: 42
...

Sheet Tổ 9
A1: THỐNG KÊ HÌNH SỰ LIÊN NGÀNH Kỳ thống kê tháng …. năm 2026
A3: Tiêu chí | B3: Mã | C3: Số
B4: dòng | C4: liệu
A5: I. TIẾP NHẬN, GIẢI QUYẾT TỐ GIÁC, TIN BÁO VỀ TỘI PHẠM VÀ KIẾN NGHỊ KHỞI TỐ
A6: Số tố giác, tin báo về tội phạm, kiến nghị khởi tố mới nhận | B6: 1 | C6: 10
A7: Tổng số tố giác, tin báo về tội phạm, kiến nghị khởi tố phải giải quyết | B7: 2 | C7: 59
A8: Số tố giác, tin báo về tội phạm, kiến nghị khởi tố đã quyết định khởi tố vụ án hình sự | B8: 3 | C8: 7
A9: Số tố giác, tin báo về tội phạm, kiến nghị khởi tố quyết định không khởi tố vụ án hình sự | B9: 4 | C9: 1
A10: Số tố giác, tin báo về tội phạm, kiến nghị khởi tố tạm đình chỉ việc giải quyết trong kỳ thống kê | B10: 5 | C10: 5
A11: Tổng số tố giác, tin báo về tội phạm, kiến nghị khởi tố tạm đình chỉ giải quyết tính đến cuối kỳ thống kê | B11: 6 | C11: 54
A12: Số tố giác, tin báo về tội phạm, kiến nghị khởi tố cuối kỳ chưa giải quyết xong | B12: 7 | C12: 46
A13: Trong đó: Số tố giác, tin báo về tội phạm, kiến nghị khởi tố đã quá hạn | B13: 8 | C13: 0
A14: Số quyết định VKS hủy bỏ các lệnh, quyết định không có căn cứ và trái pháp luật của CQĐT, cơ quan được giao nhiệm vụ tiến hành một số hoạt động điều tra | B14: 9 | C14: 0
A15: Số bản kiến nghị của VKS ban hành kiến nghị CQĐT, cơ quan được giao nhiệm vụ tiến hành một số hoạt động điều tra được chấp nhận | B15: 10 | C15: 0
A16: II. KHỞI TỐ, ĐIỀU TRA VÀ KIỂM SÁT ĐIỀU TRA CÁC VỤ ÁN HÌNH SỰ
A17: Số vụ án mới khởi tố | B17: 11 | C17: 12
A18: Số bị can mới khởi tố | B18: 12 | C18: 25
A19: Tổng số vụ án thụ lý điều tra | B19: 13 | C19: 203
A20: Tổng số bị can thụ lý điều tra | B20: 14 | C20: 140
A21: Số vụ án đề nghị truy tố | B21: 15 | C21: 3
A22: Số bị can đề nghị truy tố | B22: 16 | C22: 13
A23: Số vụ án CQĐT đình chỉ điều tra | B23: 17
A24: Số bị can CQĐT đình chỉ điều tra | B24: 18
A25: Trong đó: - Số bị can đình chỉ điều tra do không có sự việc phạm tội (theo K1 Đ157 BLTTHS) - (không tính trường hợp đình chỉ do bị can bị tâm thần). | B25: 19
A26: - Số bị can đình chỉ điều tra do hành vi không cấu thành tội phạm (theo K2 Đ157 BLTTHS) - (không tính trường hợp đình chỉ do bị can bị tâm thần). | B26: 20
A27: - Số bị can đình chỉ vì hết thời hạn điều tra mà không chứng minh được bị can đã thực hiện tội phạm (theo điểm b K1 Đ230 BLTTHS) | B27: 21
A28: - Số bị can đình chỉ do được miễn trách nhiệm hình sự theo K1 Đ29 BLHS | B28: 22
A29: - Số bị can đình chỉ do được miễn trách nhiệm hình sự theo K2 Đ29 BLHS | B29: 23
A30: - Số bị can đình chỉ điều tra do được miễn trách nhiệm hình sự theo K3 Đ29 BLHS | B30: 24
A31: Tổng số vụ án CQĐT ra quyết định tạm đình chỉ điều tra còn lại tính đến cuối kỳ thống kê | B31: 25
A32: Tổng số bị can CQĐT ra quyết định tạm đình chỉ điều tra còn lại tính đến cuối kỳ thống kê | B32: 26
A33: Số vụ án còn lại chưa kết thúc điều tra | B33: 27
A34: Trong đó:Số vụ án chưa kết thúc điều tra đã quá thời hạn luật định | B34: 28
... A37: Số bản kiến nghị của VKS ban hành kiến nghị CQĐT, cơ quan được giao nhiệm vụ tiến hành một số hoạt động điều tra được chấp nhận | B37: 31
A38: III. QUYẾT ĐỊNH VIỆC TRUY TỐ
A39: Số vụ án mới thụ lý | B39: 32
A40: Số bị can mới thụ lý | B40: 33
A41: Tổng số vụ án VKS thụ lý giải quyết | B41: 34
A42: Tổng số bị can VKS thụ lý giải quyết | B42: 35
A43: Số vụ án truy tố | B43: 36
...

Sheet Tổ 10
A1: THỐNG KÊ HÌNH SỰ LIÊN NGÀNH Kỳ thống kê tháng …. năm 2026
A3: Tiêu chí | B3: Mã | C3: Số
B4: dòng | C4: liệu
A5: I. TIẾP NHẬN, GIẢI QUYẾT TỐ GIÁC, TIN BÁO VỀ TỘI PHẠM VÀ KIẾN NGHỊ KHỞI TỐ
A6: Số tố giác, tin báo về tội phạm, kiến nghị khởi tố mới nhận | B6: 1 | C6: 14
A7: Tổng số tố giác, tin báo về tội phạm, kiến nghị khởi tố phải giải quyết | B7: 2 | C7: 37
A8: Số tố giác, tin báo về tội phạm, kiến nghị khởi tố đã quyết định khởi tố vụ án hình sự | B8: 3 | C8: 5
A9: Số tố giác, tin báo về tội phạm, kiến nghị khởi tố quyết định không khởi tố vụ án hình sự | B9: 4 | C9: 0
A10: Số tố giác, tin báo về tội phạm, kiến nghị khởi tố tạm đình chỉ việc giải quyết trong kỳ thống kê | B10: 5 | C10: 0
A11: Tổng số tố giác, tin báo về tội phạm, kiến nghị khởi tố tạm đình chỉ giải quyết tính đến cuối kỳ thống kê | B11: 6 | C11: 341
A12: Số tố giác, tin báo về tội phạm, kiến nghị khởi tố cuối kỳ chưa giải quyết xong | B12: 7 | C12: 32
A13: Trong đó: Số tố giác, tin báo về tội phạm, kiến nghị khởi tố đã quá hạn | B13: 8 | C13: 0
A14: Số quyết định VKS hủy bỏ các lệnh, quyết định không có căn cứ và trái pháp luật của CQĐT, cơ quan được giao nhiệm vụ tiến hành một số hoạt động điều tra | B14: 9 | C14: 0
A15: Số bản kiến nghị của VKS ban hành kiến nghị CQĐT, cơ quan được giao nhiệm vụ tiến hành một số hoạt động điều tra được chấp nhận | B15: 10 | C15: 0
A16: II. KHỞI TỐ, ĐIỀU TRA VÀ KIỂM SÁT ĐIỀU TRA CÁC VỤ ÁN HÌNH SỰ
A17: Số vụ án mới khởi tố | B17: 11 | C17: 5
A18: Số bị can mới khởi tố | B18: 12 | C18: 14
A19: Tổng số vụ án thụ lý điều tra | B19: 13 | C19: 86
A20: Tổng số bị can thụ lý điều tra | B20: 14 | C20: 94
A21: Số vụ án đề nghị truy tố | B21: 15 | C21: 8
A22: Số bị can đề nghị truy tố | B22: 16 | C22: 19
A23: Số vụ án CQĐT đình chỉ điều tra | B23: 17 | C23: 0
A24: Số bị can CQĐT đình chỉ điều tra | B24: 18 | C24: 0
A25: Trong đó: - Số bị can đình chỉ điều tra do không có sự việc phạm tội (theo K1 Đ157 BLTTHS) - (không tính trường hợp đình chỉ do bị can bị tâm thần). | B25: 19
A26: - Số bị can đình chỉ điều tra do hành vi không cấu thành tội phạm (theo K2 Đ157 BLTTHS) - (không tính trường hợp đình chỉ do bị can bị tâm thần). | B26: 20
A27: - Số bị can đình chỉ vì hết thời hạn điều tra mà không chứng minh được bị can đã thực hiện tội phạm (theo điểm b K1 Đ230 BLTTHS) | B27: 21
A28: - Số bị can đình chỉ do được miễn trách nhiệm hình sự theo K1 Đ29 BLHS | B28: 22
A29: - Số bị can đình chỉ do được miễn trách nhiệm hình sự theo K2 Đ29 BLHS | B29: 23
A30: - Số bị can đình chỉ điều tra do được miễn trách nhiệm hình sự theo K3 Đ29 BLHS | B30: 24
A31: Tổng số vụ án CQĐT ra quyết định tạm đình chỉ điều tra còn lại tính đến cuối kỳ thống kê | B31: 25 | C31: 1105
A32: Tổng số bị can CQĐT ra quyết định tạm đình chỉ điều tra còn lại tính đến cuối kỳ thống kê | B32: 26 | C32: 86
A33: Số vụ án còn lại chưa kết thúc điều tra | B33: 27 | C33: 73
A34: Trong đó:Số vụ án chưa kết thúc điều tra đã quá thời hạn luật định | B34: 28 | C34: 0
A35: Số bị can còn lại chưa kết thúc điều tra | B35: 29 | C35: 73
A36: Số quyết định VKS hủy bỏ các lệnh, quyết định không có căn cứ và trái pháp luật của CQĐT, cơ quan được giao nhiệm vụ tiến hành một số hoạt động điều tra | B36: 30 | C36: 0
A37: Số bản kiến nghị của VKS ban hành kiến nghị CQĐT, cơ quan được giao nhiệm vụ tiến hành một số hoạt động điều tra được chấp nhận | B37: 31 | C37: 0
A38: III. QUYẾT ĐỊNH VIỆC TRUY TỐ
A39: Số vụ án mới thụ lý | B39: 32 | C39: =SUM(#REF!) -> #REF!
A40: Số bị can mới thụ lý | B40: 33 | C40: =SUM(#REF!) -> #REF!
A41: Tổng số vụ án VKS thụ lý giải quyết | B41: 34 | C41: =SUM(#REF!) -> #REF!
...

Sheet Cơ sở 1
A1: THỐNG KÊ HÌNH SỰ LIÊN NGÀNH Kỳ thống kê tháng …. năm 2026
A3: Tiêu chí | B3: Mã | C3: Số
B4: dòng | C4: liệu
A5: I. TIẾP NHẬN, GIẢI QUYẾT TỐ GIÁC, TIN BÁO VỀ TỘI PHẠM VÀ KIẾN NGHỊ KHỞI TỐ
A6: Số tố giác, tin báo về tội phạm, kiến nghị khởi tố mới nhận | B6: 1 | C6: 42
A7: Tổng số tố giác, tin báo về tội phạm, kiến nghị khởi tố phải giải quyết | B7: 2 | C7: 98
A8: Số tố giác, tin báo về tội phạm, kiến nghị khởi tố đã quyết định khởi tố vụ án hình sự | B8: 3 | C8: 45
A9: Số tố giác, tin báo về tội phạm, kiến nghị khởi tố quyết định không khởi tố vụ án hình sự | B9: 4 | C9: 2
A10: Số tố giác, tin báo về tội phạm, kiến nghị khởi tố tạm đình chỉ việc giải quyết trong kỳ thống kê | B10: 5 | C10: 3
A11: Tổng số tố giác, tin báo về tội phạm, kiến nghị khởi tố tạm đình chỉ giải quyết tính đến cuối kỳ thống kê | B11: 6 | C11: 384
A12: Số tố giác, tin báo về tội phạm, kiến nghị khởi tố cuối kỳ chưa giải quyết xong | B12: 7 | C12: 53
A13: Trong đó: Số tố giác, tin báo về tội phạm, kiến nghị khởi tố đã quá hạn | B13: 8 | C13: 0
A14: Số quyết định VKS hủy bỏ các lệnh, quyết định không có căn cứ và trái pháp luật của CQĐT, cơ quan được giao nhiệm vụ tiến hành một số hoạt động điều tra | B14: 9
A15: Số bản kiến nghị của VKS ban hành kiến nghị CQĐT, cơ quan được giao nhiệm vụ tiến hành một số hoạt động điều tra được chấp nhận | B15: 10
A16: II. KHỞI TỐ, ĐIỀU TRA VÀ KIỂM SÁT ĐIỀU TRA CÁC VỤ ÁN HÌNH SỰ
A17: Số vụ án mới khởi tố | B17: 11 | C17: 32
A18: Số bị can mới khởi tố | B18: 12 | C18: 30
A19: Tổng số vụ án thụ lý điều tra | B19: 13 | C19: 262
A20: Tổng số bị can thụ lý điều tra | B20: 14 | C20: 360
A21: Số vụ án đề nghị truy tố | B21: 15 | C21: 35
A22: Số bị can đề nghị truy tố | B22: 16 | C22: 109
A23: Số vụ án CQĐT đình chỉ điều tra | B23: 17 | C23: 2
A24: Số bị can CQĐT đình chỉ điều tra | B24: 18 | C24: 1
A25: Trong đó: - Số bị can đình chỉ điều tra do không có sự việc phạm tội (theo K1 Đ157 BLTTHS) - (không tính trường hợp đình chỉ do bị can bị tâm thần). | B25: 19
A26: - Số bị can đình chỉ điều tra do hành vi không cấu thành tội phạm (theo K2 Đ157 BLTTHS) - (không tính trường hợp đình chỉ do bị can bị tâm thần). | B26: 20
A27: - Số bị can đình chỉ vì hết thời hạn điều tra mà không chứng minh được bị can đã thực hiện tội phạm (theo điểm b K1 Đ230 BLTTHS) | B27: 21
A28: - Số bị can đình chỉ do được miễn trách nhiệm hình sự theo K1 Đ29 BLHS | B28: 22
A29: - Số bị can đình chỉ do được miễn trách nhiệm hình sự theo K2 Đ29 BLHS | B29: 23
A30: - Số bị can đình chỉ điều tra do được miễn trách nhiệm hình sự theo K3 Đ29 BLHS | B30: 24
A31: Tổng số vụ án CQĐT ra quyết định tạm đình chỉ điều tra còn lại tính đến cuối kỳ thống kê | B31: 25 | C31: 754
A32: Tổng số bị can CQĐT ra quyết định tạm đình chỉ điều tra còn lại tính đến cuối kỳ thống kê | B32: 26 | C32: 73
A33: Số vụ án còn lại chưa kết thúc điều tra | B33: 27 | C33: 211
A34: Trong đó:Số vụ án chưa kết thúc điều tra đã quá thời hạn luật định | B34: 28 | C34: 0
A35: Số bị can còn lại chưa kết thúc điều tra | B35: 29 | C35: 273
A36: Số quyết định VKS hủy bỏ các lệnh, quyết định không có căn cứ và trái pháp luật của CQĐT, cơ quan được giao nhiệm vụ tiến hành một số hoạt động điều tra | B36: 30
A37: Số bản kiến nghị của VKS ban hành kiến nghị CQĐT, cơ quan được giao nhiệm vụ tiến hành một số hoạt động điều tra được chấp nhận | B37: 31
A38: III. QUYẾT ĐỊNH VIỆC TRUY TỐ
A39: Số vụ án mới thụ lý | B39: 32
A40: Số bị can mới thụ lý | B40: 33
A41: Tổng số vụ án VKS thụ lý giải quyết | B41: 34
...

Sheet Cơ sở 2
A1: THỐNG KÊ HÌNH SỰ LIÊN NGÀNH Kỳ thống kê tháng …. năm 2026
A3: Tiêu chí | B3: Mã | C3: Số
B4: dòng | C4: liệu
A5: I. TIẾP NHẬN, GIẢI QUYẾT TỐ GIÁC, TIN BÁO VỀ TỘI PHẠM VÀ KIẾN NGHỊ KHỞI TỐ
A6: Số tố giác, tin báo về tội phạm, kiến nghị khởi tố mới nhận | B6: 1 | C6: 18
A7: Tổng số tố giác, tin báo về tội phạm, kiến nghị khởi tố phải giải quyết | B7: 2 | C7: 20
A8: Số tố giác, tin báo về tội phạm, kiến nghị khởi tố đã quyết định khởi tố vụ án hình sự | B8: 3 | C8: 15
A9: Số tố giác, tin báo về tội phạm, kiến nghị khởi tố quyết định không khởi tố vụ án hình sự | B9: 4 | C9: 1
A10: Số tố giác, tin báo về tội phạm, kiến nghị khởi tố tạm đình chỉ việc giải quyết trong kỳ thống kê | B10: 5 | C10: 1
A11: Tổng số tố giác, tin báo về tội phạm, kiến nghị khởi tố tạm đình chỉ giải quyết tính đến cuối kỳ thống kê | B11: 6 | C11: 186
A12: Số tố giác, tin báo về tội phạm, kiến nghị khởi tố cuối kỳ chưa giải quyết xong | B12: 7 | C12: 21
A13: Trong đó: Số tố giác, tin báo về tội phạm, kiến nghị khởi tố đã quá hạn | B13: 8 | C13: 0
A14: Số quyết định VKS hủy bỏ các lệnh, quyết định không có căn cứ và trái pháp luật của CQĐT, cơ quan được giao nhiệm vụ tiến hành một số hoạt động điều tra | B14: 9 | C14: 0
A15: Số bản kiến nghị của VKS ban hành kiến nghị CQĐT, cơ quan được giao nhiệm vụ tiến hành một số hoạt động điều tra được chấp nhận | B15: 10 | C15: 0
A16: II. KHỞI TỐ, ĐIỀU TRA VÀ KIỂM SÁT ĐIỀU TRA CÁC VỤ ÁN HÌNH SỰ
A17: Số vụ án mới khởi tố | B17: 11 | C17: 15
A18: Số bị can mới khởi tố | B18: 12 | C18: 25
A19: Tổng số vụ án thụ lý điều tra | B19: 13 | C19: 229
A20: Tổng số bị can thụ lý điều tra | B20: 14 | C20: 170
A21: Số vụ án đề nghị truy tố | B21: 15 | C21: 18
A22: Số bị can đề nghị truy tố | B22: 16 | C22: 42
A23: Số vụ án CQĐT đình chỉ điều tra | B23: 17 | C23: 0
A24: Số bị can CQĐT đình chỉ điều tra | B24: 18 | C24: 0
A25: Trong đó: - Số bị can đình chỉ điều tra do không có sự việc phạm tội (theo K1 Đ157 BLTTHS) - (không tính trường hợp đình chỉ do bị can bị tâm thần). | B25: 19 | C25: 0
A26: - Số bị can đình chỉ điều tra do hành vi không cấu thành tội phạm (theo K2 Đ157 BLTTHS) - (không tính trường hợp đình chỉ do bị can bị tâm thần). | B26: 20 | C26: 0
A27: - Số bị can đình chỉ vì hết thời hạn điều tra mà không chứng minh được bị can đã thực hiện tội phạm (theo điểm b K1 Đ230 BLTTHS) | B27: 21 | C27: 0
A28: - Số bị can đình chỉ do được miễn trách nhiệm hình sự theo K1 Đ29 BLHS | B28: 22 | C28: 0
... A37: Số bản kiến nghị của VKS ban hành kiến nghị CQĐT, cơ quan được giao nhiệm vụ tiến hành một số hoạt động điều tra được chấp nhận | B37: 31 | C37: 0
A38: III. QUYẾT ĐỊNH VIỆC TRUY TỐ
A39: Số vụ án mới thụ lý | B39: 32
A40: Số bị can mới thụ lý | B40: 33
A41: Tổng số vụ án VKS thụ lý giải quyết | B41: 34
A42: Tổng số bị can VKS thụ lý giải quyết | B42: 35
A43: Số vụ án truy tố | B43: 36
A44: Số bị can truy tố | B44: 37
A45: Số vụ án VKS quyết định không truy tố và ra quyết định đình chỉ | B45: 38
A46: Trong đó: Số vụ án Toà án trả hồ sơ cho VKS để điều tra bổ sung nhưng sau đó đình chỉ | B46: 39
A47: Số bị can VKS quyết định không truy tố và ra quyết định đình chỉ vụ án đối với bị can | B47: 40
A48: Trong đó: - Số bị can đình chỉ điều tra do không có sự việc phạm tội (theo K1 Đ157 BLTTHS) | B48: 41
A49: - Số bị can đình chỉ điều tra do hành vi không cấu thành tội phạm (theo K2 Đ157 BLTTHS) | B49: 42
...
