Workbook

Sheet Summary
A1: 📊 DASHBOARD - UAT EXECUTION SUMMARY
A3: TỔNG QUAN
A4: Tổng số TC | B4: 240 | C4: Số test case đã viết
A5: ✅ Đạt (cả 2 layer) | B5: =SUMPRODUCT(('Test Cases'!R4:R243="Đạt")*('Test Cases'!S4:S243="Đạt")) | C5: TC pass cả API VÀ E2E
A6: ❌ Không đạt | B6: =SUMPRODUCT((('Test Cases'!R4:R243="Không đạt")+('Test Cases'!S4:S243="Không đạt"))>0)*1 | C6: TC fail ít nhất 1 layer
A7: API Đạt | B7: =COUNTIF('Test Cases'!R4:R243,"Đạt") | C7: Layer 1 — API smoke
A8: API Không đạt | B8: =COUNTIF('Test Cases'!R4:R243,"Không đạt") | C8: API fail
A9: E2E Đạt | B9: =COUNTIF('Test Cases'!S4:S243,"Đạt") | C9: Layer 2 — UI E2E
A10: E2E Không đạt | B10: =COUNTIF('Test Cases'!S4:S243,"Không đạt") | C10: E2E fail
A11: E2E Bỏ qua | B11: =COUNTIF('Test Cases'!S4:S243,"Bỏ qua") | C11: Skip do API smoke fail
A12: Chưa chạy | B12: =COUNTBLANK('Test Cases'!R4:R243)+COUNTIF('Test Cases'!R4:R243,"Chưa chạy") | C12: Còn lại
A14: Tỷ lệ đạt (cả 2 layer) | B14: =IFERROR(SUMPRODUCT(('Test Cases'!R4:R243="Đạt")*('Test Cases'!S4:S243="Đạt"))/(SUMPRODUCT(('Test Cases'!R4:R243="Đạt")*('Test Cases'!S4:S243="Đạt"))+SUMPRODUCT((('Test Cases'!R4:R243="Không đạt")+('Test Cases'!S4:S243="Không đạt"))>0)),0) | C14: API+E2E đều Đạt / Tổng đã chạy
A15: API pass rate | B15: =IFERROR(COUNTIF('Test Cases'!R4:R243,"Đạt")/(COUNTIF('Test Cases'!R4:R243,"Đạt")+COUNTIF('Test Cases'!R4:R243,"Không đạt")),0) | C15: Layer 1
A16: E2E pass rate | B16: =IFERROR(COUNTIF('Test Cases'!S4:S243,"Đạt")/(COUNTIF('Test Cases'!S4:S243,"Đạt")+COUNTIF('Test Cases'!S4:S243,"Không đạt")),0) | C16: Layer 2 (UI Chromium)
A17: Tỷ lệ hoàn thành | B17: =IFERROR((COUNTIF('Test Cases'!R4:R243,"Đạt")+COUNTIF('Test Cases'!R4:R243,"Không đạt")+COUNTIF('Test Cases'!R4:R243,"Bị chặn"))/240,0) | C17: API đã chạy / Tổng
A19: ĐỘ PHỦ THEO LOẠI
A20: Loại | B20: Số TC | C20: Tỷ lệ | D20: Pass | E20: Fail | F20: Pass rate
A21: GREEN | B21: =COUNTIF('Test Cases'!B4:B243,"GREEN") | C21: =IFERROR(B21/240,0) | D21: =COUNTIFS('Test Cases'!B4:B243,"GREEN",'Test Cases'!S4:S243,"Đạt") | E21: =COUNTIFS('Test Cases'!B4:B243,"GREEN",'Test Cases'!S4:S243,"Không đạt") | F21: =IFERROR(D21/(D21+E21),0)
A22: RED | B22: =COUNTIF('Test Cases'!B4:B243,"RED") | C22: =IFERROR(B22/240,0) | D22: =COUNTIFS('Test Cases'!B4:B243,"RED",'Test Cases'!S4:S243,"Đạt") | E22: =COUNTIFS('Test Cases'!B4:B243,"RED",'Test Cases'!S4:S243,"Không đạt") | F22: =IFERROR(D22/(D22+E22),0)
A23: EDGE | B23: =COUNTIF('Test Cases'!B4:B243,"EDGE") | C23: =IFERROR(B23/240,0) | D23: =COUNTIFS('Test Cases'!B4:B243,"EDGE",'Test Cases'!S4:S243,"Đạt") | E23: =COUNTIFS('Test Cases'!B4:B243,"EDGE",'Test Cases'!S4:S243,"Không đạt") | F23: =IFERROR(D23/(D23+E23),0)
A24: BOUNDARY | B24: =COUNTIF('Test Cases'!B4:B243,"BOUNDARY") | C24: =IFERROR(B24/240,0) | D24: =COUNTIFS('Test Cases'!B4:B243,"BOUNDARY",'Test Cases'!S4:S243,"Đạt") | E24: =COUNTIFS('Test Cases'!B4:B243,"BOUNDARY",'Test Cases'!S4:S243,"Không đạt") | F24: =IFERROR(D24/(D24+E24),0)
A25: EP | B25: =COUNTIF('Test Cases'!B4:B243,"EP") | C25: =IFERROR(B25/240,0) | D25: =COUNTIFS('Test Cases'!B4:B243,"EP",'Test Cases'!S4:S243,"Đạt") | E25: =COUNTIFS('Test Cases'!B4:B243,"EP",'Test Cases'!S4:S243,"Không đạt") | F25: =IFERROR(D25/(D25+E25),0)
A26: STATE | B26: =COUNTIF('Test Cases'!B4:B243,"STATE") | C26: =IFERROR(B26/240,0) | D26: =COUNTIFS('Test Cases'!B4:B243,"STATE",'Test Cases'!S4:S243,"Đạt") | E26: =COUNTIFS('Test Cases'!B4:B243,"STATE",'Test Cases'!S4:S243,"Không đạt") | F26: =IFERROR(D26/(D26+E26),0)
A27: DECISION | B27: =COUNTIF('Test Cases'!B4:B243,"DECISION") | C27: =IFERROR(B27/240,0) | D27: =COUNTIFS('Test Cases'!B4:B243,"DECISION",'Test Cases'!S4:S243,"Đạt") | E27: =COUNTIFS('Test Cases'!B4:B243,"DECISION",'Test Cases'!S4:S243,"Không đạt") | F27: =IFERROR(D27/(D27+E27),0)
A28: SECURITY | B28: =COUNTIF('Test Cases'!B4:B243,"SECURITY") | C28: =IFERROR(B28/240,0) | D28: =COUNTIFS('Test Cases'!B4:B243,"SECURITY",'Test Cases'!S4:S243,"Đạt") | E28: =COUNTIFS('Test Cases'!B4:B243,"SECURITY",'Test Cases'!S4:S243,"Không đạt") | F28: =IFERROR(D28/(D28+E28),0)
A29: DATA | B29: =COUNTIF('Test Cases'!B4:B243,"DATA") | C29: =IFERROR(B29/240,0) | D29: =COUNTIFS('Test Cases'!B4:B243,"DATA",'Test Cases'!S4:S243,"Đạt") | E29: =COUNTIFS('Test Cases'!B4:B243,"DATA",'Test Cases'!S4:S243,"Không đạt") | F29: =IFERROR(D29/(D29+E29),0)
A30: PERFORMANCE | B30: =COUNTIF('Test Cases'!B4:B243,"PERFORMANCE") | C30: =IFERROR(B30/240,0) | D30: =COUNTIFS('Test Cases'!B4:B243,"PERFORMANCE",'Test Cases'!S4:S243,"Đạt") | E30: =COUNTIFS('Test Cases'!B4:B243,"PERFORMANCE",'Test Cases'!S4:S243,"Không đạt") | F30: =IFERROR(D30/(D30+E30),0)
A31: A11Y | B31: =COUNTIF('Test Cases'!B4:B243,"A11Y") | C31: =IFERROR(B31/240,0) | D31: =COUNTIFS('Test Cases'!B4:B243,"A11Y",'Test Cases'!S4:S243,"Đạt") | E31: =COUNTIFS('Test Cases'!B4:B243,"A11Y",'Test Cases'!S4:S243,"Không đạt") | F31: =IFERROR(D31/(D31+E31),0)
A32: COMPAT | B32: =COUNTIF('Test Cases'!B4:B243,"COMPAT") | C32: =IFERROR(B32/240,0) | D32: =COUNTIFS('Test Cases'!B4:B243,"COMPAT",'Test Cases'!S4:S243,"Đạt") | E32: =COUNTIFS('Test Cases'!B4:B243,"COMPAT",'Test Cases'!S4:S243,"Không đạt") | F32: =IFERROR(D32/(D32+E32),0)
A33: INTEGRATION | B33: =COUNTIF('Test Cases'!B4:B243,"INTEGRATION") | C33: =IFERROR(B33/240,0) | D33: =COUNTIFS('Test Cases'!B4:B243,"INTEGRATION",'Test Cases'!S4:S243,"Đạt") | E33: =COUNTIFS('Test Cases'!B4:B243,"INTEGRATION",'Test Cases'!S4:S243,"Không đạt") | F33: =IFERROR(D33/(D33+E33),0)
A34: REGRESSION | B34: =COUNTIF('Test Cases'!B4:B243,"REGRESSION") | C34: =IFERROR(B34/240,0) | D34: =COUNTIFS('Test Cases'!B4:B243,"REGRESSION",'Test Cases'!S4:S243,"Đạt") | E34: =COUNTIFS('Test Cases'!B4:B243,"REGRESSION",'Test Cases'!S4:S243,"Không đạt") | F34: =IFERROR(D34/(D34+E34),0)
A35: RECOVERY | B35: =COUNTIF('Test Cases'!B4:B243,"RECOVERY") | C35: =IFERROR(B35/240,0) | D35: =COUNTIFS('Test Cases'!B4:B243,"RECOVERY",'Test Cases'!S4:S243,"Đạt") | E35: =COUNTIFS('Test Cases'!B4:B243,"RECOVERY",'Test Cases'!S4:S243,"Không đạt") | F35: =IFERROR(D35/(D35+E35),0)
A36: AUDIT | B36: =COUNTIF('Test Cases'!B4:B243,"AUDIT") | C36: =IFERROR(B36/240,0) | D36: =COUNTIFS('Test Cases'!B4:B243,"AUDIT",'Test Cases'!S4:S243,"Đạt") | E36: =COUNTIFS('Test Cases'!B4:B243,"AUDIT",'Test Cases'!S4:S243,"Không đạt") | F36: =IFERROR(D36/(D36+E36),0)
A37: USABILITY | B37: =COUNTIF('Test Cases'!B4:B243,"USABILITY") | C37: =IFERROR(B37/240,0) | D37: =COUNTIFS('Test Cases'!B4:B243,"USABILITY",'Test Cases'!S4:S243,"Đạt") | E37: =COUNTIFS('Test Cases'!B4:B243,"USABILITY",'Test Cases'!S4:S243,"Không đạt") | F37: =IFERROR(D37/(D37+E37),0)
A39: THEO ĐỘ ƯU TIÊN
A40: Priority | B40: Số TC | C40: Tỷ lệ | D40: Pass | E40: Fail | F40: Pass rate
A41: P0 | B41: =COUNTIF('Test Cases'!C4:C243,"P0") | C41: =IFERROR(B41/240,0) | D41: =COUNTIFS('Test Cases'!C4:C243,"P0",'Test Cases'!S4:S243,"Đạt") | E41: =COUNTIFS('Test Cases'!C4:C243,"P0",'Test Cases'!S4:S243,"Không đạt") | F41: =IFERROR(D41/(D41+E41),0)
A42: P1 | B42: =COUNTIF('Test Cases'!C4:C243,"P1") | C42: =IFERROR(B42/240,0) | D42: =COUNTIFS('Test Cases'!C4:C243,"P1",'Test Cases'!S4:S243,"Đạt") | E42: =COUNTIFS('Test Cases'!C4:C243,"P1",'Test Cases'!S4:S243,"Không đạt") | F42: =IFERROR(D42/(D42+E42),0)
A43: P2 | B43: =COUNTIF('Test Cases'!C4:C243,"P2") | C43: =IFERROR(B43/240,0) | D43: =COUNTIFS('Test Cases'!C4:C243,"P2",'Test Cases'!S4:S243,"Đạt") | E43: =COUNTIFS('Test Cases'!C4:C243,"P2",'Test Cases'!S4:S243,"Không đạt") | F43: =IFERROR(D43/(D43+E43),0)
A44: P3 | B44: =COUNTIF('Test Cases'!C4:C243,"P3") | C44: =IFERROR(B44/240,0) | D44: =COUNTIFS('Test Cases'!C4:C243,"P3",'Test Cases'!S4:S243,"Đạt") | E44: =COUNTIFS('Test Cases'!C4:C243,"P3",'Test Cases'!S4:S243,"Không đạt") | F44: =IFERROR(D44/(D44+E44),0)
...

Sheet Test Cases
A1: BỘ TEST CASE UAT: petition_assignment
A2: Tổng số TC: 240 | Ngày tạo: 08/06/2026 | Generated by uat-test-writer skill
A3: TC-ID | B3: Loại | C3: Độ ưu tiên | D3: Module | E3: Tiêu đề | F3: Yêu cầu | G3: Kỹ thuật test | H3: Mức độ rủi ro | I3: Điều kiện tiên quyết | J3: Các bước kiểm thử | K3: Dữ liệu kiểm thử | L3: Data fixtures cần | M3: Kết quả mong đợi - UI | N3: Kết quả mong đợi - API | O3: Kết quả mong đợi - Side effects | P3: Severity nếu fail | Q3: Kết quả thực tế | R3: Trạng thái API | S3: Trạng thái E2E | T3: Bug ID | U3: Lần chạy cuối | V3: Lịch sử chạy | W3: Cờ regression | X3: Ghi chú
A4: TC-001 | B4: GREEN | C4: P0 | D4: GET /assignments | E4: GET /assignments trả về danh sách 2 phân công đúng format | F4: REQ-PA-I | G4: Black-box | H4: Cao | I4: Petition tồn tại với 2 assignment (user-1 LEAD, user-2 SUPPORT) | J4: GET /api/v1/petitions/:id/assignments với JWT hợp lệ | K4: account.officer.primary, petition.with_2_assignments.D7 | L4: petition.with_2_assignments.D7 | M4: Hiển thị 2 row trong danh sách, role đúng | N4: HTTP 200, array 2 phần tử, mỗi phần tử có id, petitionId, userId, role, assignedAt, user{id,username,firstName,lastName} | O4: Không có side effect DB | P4: Critical | X4: Happy path — endpoint cần pass P0
A5: TC-002 | B5: GREEN | C5: P0 | D5: GET /assignments | E5: GET /assignments trả về [] khi chưa có phân công | F5: REQ-PA-I | G5: Black-box | H5: Cao | I5: Petition mới tạo, chưa có assignment | J5: GET /api/v1/petitions/:id/assignments | K5: account.officer.primary, petition.new.D0 | L5: petition.new.D0 | M5: Hiển thị 'Chưa có cán bộ được phân công' | N5: HTTP 200, data = [] | O5: Không side effect | P5: High | X5: Empty state
A6: TC-003 | B6: GREEN | C6: P0 | D6: GET /assignments | E6: GET /assignments — response có đủ fields user.username, assignedBy | F6: REQ-PA-I | G6: Black-box | H6: Cao | I6: Petition có 1 assignment | J6: GET /api/v1/petitions/:id/assignments → kiểm tra JSON response | K6: petition.with_1_assignment.D7 | L6: petition.with_1_assignment.D7 | M6: Tên cán bộ hiển thị đúng (firstName + lastName hoặc username) | N6: HTTP 200, item.user.username ≠ null, item.assignedBy có {id, username} | O6: - | P6: High | X6: username field phải có — fix từ /review adversarial
A7: TC-004 | B7: GREEN | C7: P0 | D7: GET /assignments | E7: GET /assignments — response sắp xếp theo assignedAt tăng dần | F7: REQ-PA-I | G7: Black-box | H7: TB | I7: Petition có 3 assignments tạo lần lượt cách nhau 1 giây | J7: GET /api/v1/petitions/:id/assignments | K7: petition.with_3_assignments.D7 | L7: petition.with_3_assignments.D7 | M7: Cán bộ đầu tiên phân công ở đầu list | N7: HTTP 200, items[0].assignedAt < items[1].assignedAt < items[2].assignedAt | O7: - | P7: Medium | X7: orderBy assignedAt asc
A8: TC-005 | B8: GREEN | C8: P0 | D8: POST /assignments | E8: POST /assignments — thêm phân công với role SUPPORT → 201 | F8: REQ-PA-I | G8: Black-box | H8: Cao | I8: Petition tồn tại, user-3 chưa được assign | J8: POST /api/v1/petitions/:id/assignments body {userId:'user-3', role:'SUPPORT'} | K8: account.officer.primary, petition.new.D0, user.officer2 | L8: petition.new.D0 | M8: user-3 xuất hiện trong danh sách với badge 'Hỗ trợ' | N8: HTTP 201, response.userId='user-3', response.role='SUPPORT', response.user.username present | O8: petition_assignments table: 1 row mới, assignedAt = now() | P8: Critical | X8: Core create flow
A9: TC-006 | B9: GREEN | C9: P0 | D9: POST /assignments | E9: POST /assignments — thêm phân công với role LEAD → 201 | F9: REQ-PA-I | G9: Black-box | H9: Cao | I9: Petition tồn tại, user-3 chưa assigned | J9: POST /api/v1/petitions/:id/assignments body {userId:'user-3', role:'LEAD'} | K9: petition.new.D0, user.officer2 | L9: petition.new.D0 | M9: Badge 'Chủ trì' màu xanh hiện bên cạnh tên | N9: HTTP 201, response.role='LEAD' | O9: 1 row trong petition_assignments với role='LEAD' | P9: Critical | X9: LEAD role flow
A10: TC-007 | B10: GREEN | C10: P0 | D10: POST /assignments | E10: POST /assignments — không gửi role → default SUPPORT | F10: REQ-PA-I | G10: Black-box | H10: TB | I10: Petition tồn tại, user chưa assigned | J10: POST /api/v1/petitions/:id/assignments body {userId:'user-3'} (không có role) | K10: petition.new.D0, user.officer2 | L10: petition.new.D0 | M10: Badge 'Hỗ trợ' hiển thị | N10: HTTP 201, response.role='SUPPORT' | O10: role='SUPPORT' trong DB | P10: High | X10: Controller default: dto.role ?? 'SUPPORT'
A11: TC-008 | B11: GREEN | C11: P0 | D11: DELETE /assignments | E11: DELETE /assignments/:userId — xóa thành công → 200 + {success:true} | F11: REQ-PA-I | G11: Black-box | H11: Cao | I11: Petition có user-1 được assigned | J11: DELETE /api/v1/petitions/:id/assignments/user-1 | K11: petition.with_1_assignment.D7 | L11: petition.with_1_assignment.D7 | M11: user-1 biến mất khỏi danh sách, hiện lại trong dropdown | N11: HTTP 200, response = {success:true} | O11: petition_assignments: row với userId=user-1 bị xóa | P11: Critical | X11: HTTP 200 (không phải 204) theo @HttpCode(HttpStatus.OK)
A12: TC-009 | B12: GREEN | C12: P0 | D12: PATCH /assign | E12: PATCH /assign — auto-gán trưởng đội khi không gửi assignedToId | F12: REQ-PA-I | G12: Black-box | H12: Cao | I12: Team-A có user-leader (isLeader=true) | J12: PATCH /api/v1/petitions/:id/assign body {assignedTeamId:'team-A', expectedUpdatedAt:'...'} | K12: petition.unassigned.D0, team.with_leader | L12: petition.unassigned.D0 | M12: Tên đội trưởng xuất hiện trong field 'Phụ trách' | N12: HTTP 200, petition.assignedToId = leaderId, petition.assignedTeamId = 'team-A' | O12: Petition row cập nhật assignedToId + assignedTeamId | P12: Critical | X12: Nhóm I core feature — auto-assign to leader
A13: TC-010 | B13: GREEN | C13: P1 | D13: PATCH /assign | E13: PATCH /assign — gán với assignedToId hợp lệ trong team | F13: REQ-PA-I | G13: Black-box | H13: Cao | I13: Team-A có user-officer1 là thành viên | J13: PATCH /assign body {assignedTeamId:'team-A', assignedToId:'user-officer1', expectedUpdatedAt} | K13: petition.unassigned.D0, team.with_members | L13: petition.unassigned.D0 | M13: Cán bộ user-officer1 hiển thị trong chi tiết đơn | N13: HTTP 200, petition.assignedToId = 'user-officer1' | O13: assignedToId cập nhật trong DB | P13: High | X13: Explicit assignment
A14: TC-011 | B14: GREEN | C14: P1 | D14: POST /assignments | E14: POST /assignments — response bao gồm user relation đầy đủ | F14: REQ-PA-I | G14: Black-box | H14: TB | I14: user-3 có firstName='Lê', lastName='Văn C', username='levanc' | J14: POST /assignments {userId:'user-3', role:'SUPPORT'} → inspect response | K14: petition.new.D0, user.officer3_with_name | L14: petition.new.D0 | M14: - | N14: HTTP 201, response.user.firstName='Lê', response.user.lastName='Văn C', response.user.username='levanc', response.assignedBy.username present | O14: - | P14: High | X14: user relation + assignedBy relation
A15: TC-012 | B15: GREEN | C15: P1 | D15: UI Phân công | E15: UI — section header và form load khi mở PetitionFormPage edit mode | F15: REQ-PA-I | G15: UI / Use case | H15: TB | I15: Đăng nhập officer, mở petition edit page | J15: 1. Navigate /petitions/:id/edit 2. Cuộn đến section 'Phân công cán bộ' | K15: account.officer.primary, petition.any.D7 | L15: petition.any.D7 | M15: Section 'Phân công cán bộ' hiển thị với form select Cán bộ + Vai trò + nút Thêm | N15: GET /petitions/:id/assignments tự động gọi khi load | O15: - | P15: High | X15: E2E navigation test
... A243: TC-240 | B243: COMPAT | C243: P2 | D243: COMPAT | E243: COMPAT — PWA mode (standalone): section và interactions hoạt động như browser | F243: REQ-PA-COMPAT | G243: PWA / Standalone mode | H243: Thấp | I243: Cài PC02 PWA, mở từ home screen | J243: Mở PetitionFormPage edit trong PWA mode | K243: petition.with_2_assignments.D7 | L243: petition.with_2_assignments.D7 | M243: Section hiển thị đúng, add/remove hoạt động | N243: API calls qua PWA service worker | O243: - | P243: Low | X243: PWA standalone = Chrome trong fullscreen — behavior same

Sheet Test Data
A1: 1. TÀI KHOẢN KIỂM THỬ
A2: ID | B2: Email | C2: Mật khẩu | D2: Vai trò | E2: Trạng thái | F2: Mục đích | G2: Ghi chú
A5: 2. BOUNDARY VALUES (BVA)
A6: Field | B6: Giá trị | C6: Loại | D6: Kỳ vọng | E6: Ghi chú
A9: 3. SECURITY PAYLOADS (OWASP)
A10: Field/Endpoint | B10: Payload | C10: Loại tấn công | D10: Kỳ vọng | E10: OWASP Reference

Sheet Data Matrix
A1: 🗂️ DATA MATURITY MATRIX — Fixtures runner seed tự động trước mỗi test
A2: Mỗi fixture có ID format <entity>.<state>.<lifecycle>.<shape>. Runner đọc setup_recipe → tự seed data trước test, KHÔNG cần human chạy SQL. Cleanup tự động sau test.
A3: Fixture ID | B3: Entity | C3: State | D3: Lifecycle | E3: Shape | F3: Mô tả | G3: Setup type | H3: Setup recipe | I3: Cleanup recipe | J3: Outputs | K3: TC sử dụng
A4: ⚠️ Chưa có fixture nào define | B4: Xem references/data-maturity-matrix.md để biết cách viết

Sheet Bug Tracker
A1: 🐛 BUG TRACKER
A2: Workflow: Open → Fixing → Fixed → Verified → Closed. Mỗi lần TC fail tự động tạo bug record.
A3: Bug ID | B3: TC ID liên kết | C3: Mô tả bug | D3: Severity | E3: Status | F3: Ngày phát hiện | G3: Lần fix gần nhất | H3: Re-test kết quả | I3: Ghi chú

Sheet Regression Log
A1: ⚠️ REGRESSION LOG — Theo dõi lỗi level down (TC từng Đạt nay Không đạt)
A2: Auto-generated bởi runner khi phát hiện TC từng Đạt giờ Không đạt sau khi fix bug khác. Severity tự động ESCALATE +1 level (High→Critical, Medium→High...). BẤT KỲ regression nào còn open đều BLOCK release.
A3: Reg ID | B3: TC ID | C3: Module | D3: Lần phát hiện | E3: Bug gốc gây regression | F3: Status trước retest | G3: Status sau retest | H3: Severity gốc | I3: Severity regression | J3: Mô tả regression | K3: Đã fix? | L3: Ngày verify lại | M3: Ghi chú
